Workbook
Name _1_9: #REF!
Name _2_99: #REF!
Name _9: #REF!
Name _99: #REF!
Name CGRQ: [1]采购!$A$1:$A$2368
Name CGRQ: [1]采购!$A$1:$A$2368
Name CGRQ: [1]采购!$A$1:$A$2368
Name CGRQ: [1]采购!$A$1:$A$2368
Name CGRQ: [1]采购!$A$1:$A$2368
Name CGRQ: [1]采购!$A$1:$A$2368
Name CGRQ: [1]采购!$A$1:$A$2368
Name CGRQ: [1]采购!$A$1:$A$2368
Name CGSL: [1]采购!$B$1:$B$2368
Name CGSL: [1]采购!$B$1:$B$2368
Name CGSL: [1]采购!$B$1:$B$2368
Name CGSL: [1]采购!$B$1:$B$2368
Name CGSL: [1]采购!$B$1:$B$2368
Name CGSL: [1]采购!$B$1:$B$2368
Name CGSL: [1]采购!$B$1:$B$2368
Name CGSL: [1]采购!$B$1:$B$2368
Name month: #REF!
Name 本日付款: #REF!
Name 本月付款: #REF!
Name 采购量: [2]厂内潮玉米日采购量价!#REF!
Name 代号1: #REF!
Name 辅料消耗: #REF!
Name 付款数量: #REF!
Name 含税单价: #REF!
Name 合同号1: #REF!
Name 合同金额: #REF!
Name 合同量: #REF!
Name 签定日期: #REF!
Name 物料表: #REF!

Sheet 果糖
A1: 生产技术部果糖年度生产计划(2025年)
P2: 日 期：2024年9月10日
A3: 项 目 | B3: 单位 | C3: 指标 | D3: 2025年预算
D4: 1月 | E4: 2月 | F4: 3月 | G4: 4月 | H4: 5月 | I4: 6月 | J4: 7月 | K4: 8月 | L4: 9月 | M4: 10月 | N4: 11月 | O4: 12月 | P4: 合计
A5: 一、工时计划
A6: 日历时数 | B6: h | D6: =24*D92 -> 744 | E6: =24*E92 -> 672 | F6: =24*F92 -> 744 | G6: =24*G92 -> 720 | H6: =24*H92 -> 744 | I6: =24*I92 -> 720 | J6: =24*J92 -> 744 | K6: =24*K92 -> 744 | ... O6: =24*O92 -> 744 | P6: =SUM(D6:O6) -> 8760
A7: 计划工时 | B7: h | D7: =D6-D9 -> 650 | E7: =E6-E9 -> 407 | F7: =F6-F9 -> 644 | G7: =G6-G9 -> 540 | H7: =H6-H9 -> 744 | I7: =I6-I9 -> 720 | J7: =J6-J9 -> 744 | K7: =K6-K9 -> 744 | ... O7: =O6-O9 -> 744 | P7: =SUM(D7:O7) -> 7629
A8: 计划工时 | B8: 天 | D8: =D7/24 -> 27.083333 | E8: =E7/24 -> 16.958333 | F8: =F7/24 -> 26.833333 | G8: =G7/24 -> 22.5 | H8: =H7/24 -> 31 | I8: =I7/24 -> 30 | J8: =J7/24 -> 31 | K8: =K7/24 -> 31 | ... P8: =P7/24 -> 317.875
A9: 停车时数 | B9: h | D9: =SUM(D10:D12) -> 94 | E9: =SUM(E10:E12) -> 265 | F9: =SUM(F10:F12) -> 100 | G9: =SUM(G10:G12) -> 180 | H9: =SUM(H10:H12) -> 0 | I9: =SUM(I10:I12) -> 0 | J9: =SUM(J10:J12) -> 0 | K9: =SUM(K10:K12) -> 0 | ... O9: =SUM(O10:O12) -> 0 | P9: =SUM(D9:O9) -> 1131
A10: 计划停车 | B10: h | D10: 94 | E10: 265 | F10: 100 | G10: 180 | H10: 0 | I10: 0 | J10: 0 | K10: 0 | L10: 120 | M10: 186 | N10: 186 | O10: 0 | P10: =SUM(D10:O10) -> 1131 | T10: 108 | U10: 260 | V10: 200 | W10: 360 | X10: 0 | Y10: 0 | Z10: 0 | AA10: 0 | AB10: 240 | AC10: 372 | AD10: 372 | AE10: 0
A11: 非计划停车 | B11: h | P11: =SUM(D11:O11) -> 0 | T11: 80 | U11: 270
A12: 外部原因停车 | B12: h | P12: =SUM(D12:O12) -> 0 | T12: =(T10+T11)/2 -> 94 | U12: =(U10+U11)/2 -> 265 | V12: =(V10+V11)/2 -> 100 | W12: =(W10+W11)/2 -> 180 | X12: =(X10+X11)/2 -> 0 | Y12: =(Y10+Y11)/2 -> 0 | Z12: =(Z10+Z11)/2 -> 0 | AA12: =(AA10+AA11)/2 -> 0 | ... AE12: =(AE10+AE11)/2 -> 0
A13: 二、绝干收率 | D13: 120 | E13: 0 | F13: 120 | G13: 120 | H13: 240 | I13: 120 | J13: 360 | K13: 360 | L13: 90 | M13: 0 | N13: 120 | O13: 150
A14: 果糖 | B14: % | D14: =IF(D35=0,0,1/D35) -> 1.0803818 | E14: =IF(E35=0,0,1/E35) -> 1.0803112 | F14: =IF(F35=0,0,1/F35) -> 1.0802223 | G14: =IF(G35=0,0,1/G35) -> 1.0799701 | H14: =IF(H35=0,0,1/H35) -> 1.0803597 | I14: =IF(I35=0,0,1/I35) -> 1.0803513 | J14: =IF(J35=0,0,1/J35) -> 1.0803308 | K14: =IF(K35=0,0,1/K35) -> 1.0803854 | ... P14: =IF(P35=0,0,1/P35) -> 1.0799136
A15: 三、生产负荷计划 | P15: =SUM(D15:O15) -> 0
A16: 果糖装置 | B16: % | D16: =IF(D7=0,0,(D18+D24)/D7/(333+480)*24) -> 0.87850128 | E16: =IF(E7=0,0,(E18+E24)/E7/(333+480)*24) -> 0.80165372 | F16: =IF(F7=0,0,(F18+F24)/F7/(333+480)*24) -> 0.64518347 | G16: =IF(G7=0,0,(G18+G24)/G7/(333+480)*24) -> 0.55252153 | H16: =IF(H7=0,0,(H18+H24)/H7/(333+480)*24) -> 0.7209856 | I16: =IF(I7=0,0,(I18+I24)/I7/(333+480)*24) -> 0.75086101 | J16: =IF(J7=0,0,(J18+J24)/J7/(333+480)*24) -> 0.73362298 | K16: =IF(K7=0,0,(K18+K24)/K7/(333+480)*24) -> 0.73235329 | ... P16: =IF(P7=0,0,(P18+P24)/P7/(333+480)*24) -> 0.66887904 | Q16: ？？
A17: 四、产品产量 | D17: =D18+D24+D29+D30 -> 20266.236 | E17: =E18+E24+E29+E30 -> 11358.46 | F17: =F18+F24+F29+F30 -> 14531.012 | G17: =G18+G24+G29+G30 -> 11042.722 | H17: =H18+H24+H29+H30 -> 18968.192 | I17: =I18+I24+I29+I30 -> 19211.004 | J17: =J18+J24+J29+J30 -> 19507.636 | K17: =K18+K24+K29+K30 -> 19365.3 | ... O17: =O18+O24+O29+O30 -> 16934.5 | P17: =SUM(D17:O17) -> 182037.06 | Q17: =P17+葡萄糖!P18+麦芽糖!P18 -> 204103.06 | R17: 总销量
A18: 果糖F42(71%) | B18: t | D18: =果糖一线!D18+果糖二线!D18 -> 343.5 | E18: =果糖一线!E18+果糖二线!E18 -> 52.5 | F18: =果糖一线!F18+果糖二线!F18 -> 75 | G18: =果糖一线!G18+果糖二线!G18 -> 107 | H18: =果糖一线!H18+果糖二线!H18 -> 171 | I18: =果糖一线!I18+果糖二线!I18 -> 313.5 | J18: =果糖一线!J18+果糖二线!J18 -> 489.5 | K18: =果糖一线!K18+果糖二线!K18 -> 457.5 | ... O18: =果糖一线!O18+果糖二线!O18 -> 97.5 | P18: =SUM(D18:O18) -> 2860 | Q18: =P18+P24+P29+P30 -> 182037.06 | R18: 果糖产量
A19: 可乐标准 | B19: t | D19: =果糖一线!D19+果糖二线!D19 -> 0 | E19: =果糖一线!E19+果糖二线!E19 -> 0 | F19: =果糖一线!F19+果糖二线!F19 -> 0 | G19: =果糖一线!G19+果糖二线!G19 -> 0 | H19: =果糖一线!H19+果糖二线!H19 -> 0 | I19: =果糖一线!I19+果糖二线!I19 -> 0 | J19: =果糖一线!J19+果糖二线!J19 -> 0 | K19: =果糖一线!K19+果糖二线!K19 -> 0 | ... O19: =果糖一线!O19+果糖二线!O19 -> 0 | P19: =SUM(D19:O19) -> 0
A20: 比重 | B20: % | D20: =IF(D18=0,0,D19/D18) -> 0 | E20: =IF(E18=0,0,E19/E18) -> 0 | F20: =IF(F18=0,0,F19/F18) -> 0 | G20: =IF(G18=0,0,G19/G18) -> 0 | H20: =IF(H18=0,0,H19/H18) -> 0 | I20: =IF(I18=0,0,I19/I18) -> 0 | J20: =IF(J18=0,0,J19/J18) -> 0 | K20: =IF(K18=0,0,K19/K18) -> 0 | ... P20: =IF(P18=0,0,P19/P18) -> 0
A21: 国标 | B21: t | D21: =D18-D19 -> 343.5 | E21: =E18-E19 -> 52.5 | F21: =F18-F19 -> 75 | G21: =G18-G19 -> 107 | H21: =H18-H19 -> 171 | I21: =I18-I19 -> 313.5 | J21: =J18-J19 -> 489.5 | K21: =K18-K19 -> 457.5 | ... O21: =O18-O19 -> 97.5 | P21: =SUM(D21:O21) -> 2860
A22: 比重 | B22: % | D22: =IF(D18=0,0,D21/D18) -> 1 | E22: =IF(E18=0,0,E21/E18) -> 1 | F22: =IF(F18=0,0,F21/F18) -> 1 | G22: =IF(G18=0,0,G21/G18) -> 1 | H22: =IF(H18=0,0,H21/H18) -> 1 | I22: =IF(I18=0,0,I21/I18) -> 1 | J22: =IF(J18=0,0,J21/J18) -> 1 | K22: =IF(K18=0,0,K21/K18) -> 1 | ... P22: =IF(P18=0,0,P21/P18) -> 1
A23: 果糖F42折绝干 | B23: t | D23: =D18*0.71 -> 243.885 | E23: =E18*0.71 -> 37.275 | F23: =F18*0.71 -> 53.25 | G23: =G18*0.71 -> 75.97 | H23: =H18*0.71 -> 121.41 | I23: =I18*0.71 -> 222.585 | J23: =J18*0.71 -> 347.545 | K23: =K18*0.71 -> 324.825 | ... P23: =P18*0.71 -> 2030.6 | Q23: =P18+P24+P29+P30+葡萄糖!P18+麦芽糖!P18 -> 204103.06 | R23: 总产量
A24: 果糖F55(77%) | B24: t | D24: =D25 -> 19000 | E24: =E25 -> 11000 | F24: =F25 -> 14000 | G24: =G25 -> 10000 | H24: =H25 -> 18000 | I24: =I25 -> 18000 | J24: =J25 -> 18000 | K24: =K25 -> 18000 | ... O24: =O25 -> 16000 | P24: =SUM(D24:O24) -> 170000
A25: 可乐标准 | B25: t | D25: =果糖一线!D25+果糖二线!D25 -> 19000 | E25: =果糖一线!E25+果糖二线!E25 -> 11000 | F25: =果糖一线!F25+果糖二线!F25 -> 14000 | G25: =果糖一线!G25+果糖二线!G25 -> 10000 | H25: =果糖一线!H25+果糖二线!H25 -> 18000 | I25: =果糖一线!I25+果糖二线!I25 -> 18000 | J25: =果糖一线!J25+果糖二线!J25 -> 18000 | K25: =果糖一线!K25+果糖二线!K25 -> 18000 | ... O25: =果糖一线!O25+果糖二线!O25 -> 16000 | P25: =SUM(D25:O25) -> 170000
A26: 比重 | B26: % | D26: =IF(D24=0,0,D25/D24) -> 1 | E26: =IF(E24=0,0,E25/E24) -> 1 | F26: =IF(F24=0,0,F25/F24) -> 1 | G26: =IF(G24=0,0,G25/G24) -> 1 | H26: =IF(H24=0,0,H25/H24) -> 1 | I26: =IF(I24=0,0,I25/I24) -> 1 | J26: =IF(J24=0,0,J25/J24) -> 1 | K26: =IF(K24=0,0,K25/K24) -> 1 | ... P26: =IF(P24=0,0,P25/P24) -> 1 | S26: =P18+P25+P29+P30+葡萄糖!P18+葡萄糖!P19+麦芽糖!P18+混配糖!P18 -> 228473.73
A27: 国标 | B27: t | D27: =D24-D25 -> 0 | E27: =E24-E25 -> 0 | F27: =F24-F25 -> 0 | G27: =G24-G25 -> 0 | H27: =H24-H25 -> 0 | I27: =I24-I25 -> 0 | J27: =J24-J25 -> 0 | K27: =K24-K25 -> 0 | ... O27: =O24-O25 -> 0 | P27: =SUM(D27:O27) -> 0
A28: 比重 | B28: % | D28: =IF(D24=0,0,D27/D24) -> 0 | E28: =IF(E24=0,0,E27/E24) -> 0 | F28: =IF(F24=0,0,F27/F24) -> 0 | G28: =IF(G24=0,0,G27/G24) -> 0 | H28: =IF(H24=0,0,H27/H24) -> 0 | I28: =IF(I24=0,0,I27/I24) -> 0 | J28: =IF(J24=0,0,J27/J24) -> 0 | K28: =IF(K24=0,0,K27/K24) -> 0 | ... P28: =IF(P24=0,0,P27/P24) -> 0
A29: 果糖F60(73.5%) | B29: t | D29: =果糖一线!D29+果糖二线!D29 -> 922.736 | E29: =果糖一线!E29+果糖二线!E29 -> 305.96 | F29: =果糖一线!F29+果糖二线!F29 -> 456.012 | G29: =果糖一线!G29+果糖二线!G29 -> 935.722 | H29: =果糖一线!H29+果糖二线!H29 -> 698.192 | I29: =果糖一线!I29+果糖二线!I29 -> 798.504 | J29: =果糖一线!J29+果糖二线!J29 -> 919.136 | K29: =果糖一线!K29+果糖二线!K29 -> 907.8 | ... O29: =果糖一线!O29+果糖二线!O29 -> 837 | P29: =SUM(D29:O29) -> 8880.062
A30: 果糖90(77%) | B30: t | D30: =果糖一线!D30+果糖二线!D30 -> 0 | E30: =果糖一线!E30+果糖二线!E30 -> 0 | F30: =果糖一线!F30+果糖二线!F30 -> 0 | G30: =果糖一线!G30+果糖二线!G30 -> 0 | H30: =果糖一线!H30+果糖二线!H30 -> 99 | I30: =果糖一线!I30+果糖二线!I30 -> 99 | J30: =果糖一线!J30+果糖二线!J30 -> 99 | K30: =果糖一线!K30+果糖二线!K30 -> 0 | ... O30: =果糖一线!O30+果糖二线!O30 -> 0 | P30: =SUM(D30:O30) -> 297
A31: 果糖F55折绝干 | B31: t | D31: =(D24+D30)*0.77+D29*0.735 -> 15308.211 | E31: =(E24+E30)*0.77+E29*0.735 -> 8694.8806 | F31: =(F24+F30)*0.77+F29*0.735 -> 11115.169 | G31: =(G24+G30)*0.77+G29*0.735 -> 8387.7557 | H31: =(H24+H30)*0.77+H29*0.735 -> 14449.401 | I31: =(I24+I30)*0.77+I29*0.735 -> 14523.13 | J31: =(J24+J30)*0.77+J29*0.735 -> 14611.795 | K31: =(K24+K30)*0.77+K29*0.735 -> 14527.233 | ... O31: =(O24+O30)*0.77+O29*0.735 -> 12935.195 | P31: =SUM(D31:O31) -> 137655.54
A32: 绝干果糖合计 | B32: t | D32: =D23+D31 -> 15552.096 | E32: =E23+E31 -> 8732.1556 | F32: =F23+F31 -> 11168.419 | G32: =G23+G31 -> 8463.7257 | H32: =H23+H31 -> 14570.811 | I32: =I23+I31 -> 14745.715 | J32: =J23+J31 -> 14959.34 | K32: =K23+K31 -> 14852.058 | ... P32: =P23+P31 -> 139686.14
A33: 五、辅助材料消耗计划 | D33: =D34/0.87 -> 16545.977 | E33: =E34/0.87 -> 9290.8046 | F33: =F34/0.87 -> 11883.908 | G33: =G34/0.87 -> 9008.046 | H33: =H34/0.87 -> 15502.299 | I33: =I34/0.87 -> 15688.506 | J33: =J34/0.87 -> 15916.092 | K33: =K34/0.87 -> 15801.149 | ... P33: =P34/0.87 -> 148628.74 | Q33: 商品单耗 | R33: 2020年预算
A34: 淀粉(绝干) | B34: t | D34: =ROUND(D35*D$32,0) -> 14395 | E34: =ROUND(E35*E$32,0) -> 8083 | F34: =ROUND(F35*F$32,0) -> 10339 | G34: =ROUND(G35*G$32,0) -> 7837 | H34: =ROUND(H35*H$32,0) -> 13487 | I34: =ROUND(I35*I$32,0) -> 13649 | J34: =ROUND(J35*J$32,0) -> 13847 | K34: =ROUND(K35*K$32,0) -> 13747 | ... O34: =ROUND(O35*O$32,0) -> 12036 | P34: =SUM(D34:O34) -> 129307
A35: 单耗 | B35: t/t | D35: =(果糖一线!D34+果糖二线!D34)/D$32 -> 0.92559871 | E35: =(果糖一线!E34+果糖二线!E34)/E$32 -> 0.92565918 | F35: =(果糖一线!F34+果糖二线!F34)/F$32 -> 0.92573534 | G35: =(果糖一线!G34+果糖二线!G34)/G$32 -> 0.92595156 | H35: =(果糖一线!H34+果糖二线!H34)/H$32 -> 0.92561765 | I35: =(果糖一线!I34+果糖二线!I34)/I$32 -> 0.92562481 | J35: =(果糖一线!J34+果糖二线!J34)/J$32 -> 0.92564244 | K35: =(果糖一线!K34+果糖二线!K34)/K$32 -> 0.92559563 | ... O35: =(果糖一线!O34+果糖二线!O34)/O$32 -> 0.92553147 | P35: =ROUND(IF(P$32=0,0,P34/P$32),3) -> 0.926 | Q35: =P35*0.77/0.86 -> 0.82909302 | R35: 0.82909302
A36: 盐酸(折百) | B36: kg | D36: =ROUND(D37*D$32,2) -> 60930.76 | E36: =ROUND(E37*E$32,2) -> 35292.16 | F36: =ROUND(F37*F$32,2) -> 44056.85 | G36: =ROUND(G37*G$32,2) -> 31823.61 | H36: =ROUND(H37*H$32,2) -> 57842.01 | I36: =ROUND(I37*I$32,2) -> 58499.65 | J36: =ROUND(J37*J$32,2) -> 59302.87 | K36: =ROUND(K37*K$32,2) -> 58862.14 | ... O36: =ROUND(O37*O$32,2) -> 52188.8 | P36: =SUM(D36:O36) -> 549476.93
A37: 单耗 | B37: kg/t | D37: =(果糖一线!D36+果糖二线!D36)/D$32 -> 3.9178488 | E37: =(果糖一线!E36+果糖二线!E36)/E$32 -> 4.0416321 | F37: =(果糖一线!F36+果糖二线!F36)/F$32 -> 3.9447706 | G37: =(果糖一线!G36+果糖二线!G36)/G$32 -> 3.7600002 | H37: =(果糖一线!H36+果糖二线!H36)/H$32 -> 3.9697179 | I37: =(果糖一线!I36+果糖二线!I36)/I$32 -> 3.9672304 | J37: =(果糖一线!J36+果糖二线!J36)/J$32 -> 3.9642705 | K37: =(果糖一线!K36+果糖二线!K36)/K$32 -> 3.9632312 | ... O37: =(果糖一线!O36+果糖二线!O36)/O$32 -> 4.0131586 | P37: =ROUND(IF(P$32=0,0,P36/P$32),3) -> 3.934 | Q37: =P37*0.77 -> 3.02918 | R37: 4.774
A38: 氢氧化钠(折百) | B38: kg | D38: =ROUND(D39*D$32,2) -> 71645.35 | E38: =ROUND(E39*E$32,2) -> 41279.82 | F38: =ROUND(F39*F$32,2) -> 50938.14 | G38: =ROUND(G39*G$32,2) -> 35124.46 | H38: =ROUND(H39*H$32,2) -> 68326.51 | I38: =ROUND(I39*I$32,2) -> 69052.36 | J38: =ROUND(J39*J$32,2) -> 69938.91 | K38: =ROUND(K39*K$32,2) -> 69397.64 | ... O38: =ROUND(O39*O$32,2) -> 62003.72 | P38: =SUM(D38:O38) -> 638881.77
A39: 单耗 | B39: kg/t | D39: =(果糖一线!D38+果糖二线!D38)/D$32 -> 4.6067971 | E39: =(果糖一线!E38+果糖二线!E38)/E$32 -> 4.7273345 | F39: =(果糖一线!F38+果糖二线!F38)/F$32 -> 4.5609088 | G39: =(果糖一线!G38+果糖二线!G38)/G$32 -> 4.1499998 | H39: =(果糖一线!H38+果糖二线!H38)/H$32 -> 4.6892729 | I39: =(果糖一线!I38+果糖二线!I38)/I$32 -> 4.6828762 | J39: =(果糖一线!J38+果糖二线!J38)/J$32 -> 4.6752671 | K39: =(果糖一线!K38+果糖二线!K38)/K$32 -> 4.6725942 | ... O39: =(果糖一线!O38+果糖二线!O38)/O$32 -> 4.7678958 | P39: =ROUND(IF(P$32=0,0,P38/P$32),3) -> 4.574 | Q39: =P39*0.77 -> 3.52198 | R39: 5.005
A40: 硅藻土 | B40: kg | D40: =ROUND(D41*D$32,2) -> 5971.4 | E40: =ROUND(E41*E$32,2) -> 3492.86 | F40: =ROUND(F41*F$32,2) -> 4386.48 | G40: =ROUND(G41*G$32,2) -> 3300.85 | H40: =ROUND(H41*H$32,2) -> 5682.62 | I40: =ROUND(I41*I$32,2) -> 5750.83 | J40: =ROUND(J41*J$32,2) -> 5834.14 | K40: =ROUND(K41*K$32,2) -> 5792.3 | ... O40: =ROUND(O41*O$32,2) -> 5010.12 | P40: =SUM(D40:O40) -> 54486.38
...

Sheet 葡萄糖
A1: 生产技术部麦芽糖年度生产计划(2025年)
P2: =能源消耗!Q2 -> 日 期：2024年9月10日
A3: 项 目 | B3: 单位 | C3: 指标 | D3: =果糖!D3 -> 2025年预算
D4: 1月 | E4: 2月 | F4: 3月 | G4: 4月 | H4: 5月 | I4: 6月 | J4: 7月 | K4: 8月 | L4: 9月 | M4: 10月 | N4: 11月 | O4: 12月 | P4: 合计
A5: 一、工时计划
A6: 日历时数 | B6: h | D6: 744 | E6: 672 | F6: 744 | G6: 720 | H6: 744 | I6: 720 | J6: 744 | K6: 744 | L6: 720 | M6: 744 | N6: 720 | O6: 744 | P6: =SUM(D6:O6) -> 8760
A7: 计划工时 | B7: h | D7: =D6-D9 -> 39 | E7: =E6-E9 -> 27 | F7: =F6-F9 -> 39 | G7: =G6-G9 -> 50 | H7: =H6-H9 -> 54 | I7: =I6-I9 -> 55 | J7: =J6-J9 -> 104 | K7: =K6-K9 -> 104 | ... O7: =O6-O9 -> 64 | P7: =SUM(D7:O7) -> 790
A8: 计划工时 | B8: 天 | D8: =D7/24 -> 1.625 | E8: =E7/24 -> 1.125 | F8: =F7/24 -> 1.625 | G8: =G7/24 -> 2.0833333 | H8: =H7/24 -> 2.25 | I8: =I7/24 -> 2.2916667 | J8: =J7/24 -> 4.3333333 | K8: =K7/24 -> 4.3333333 | ... P8: =P7/24 -> 32.916667
A9: 停车时数 | B9: h | D9: =SUM(D10:D12) -> 705 | E9: =SUM(E10:E12) -> 645 | F9: =SUM(F10:F12) -> 705 | G9: =SUM(G10:G12) -> 670 | H9: =SUM(H10:H12) -> 690 | I9: =SUM(I10:I12) -> 665 | J9: =SUM(J10:J12) -> 640 | K9: =SUM(K10:K12) -> 640 | ... O9: =SUM(O10:O12) -> 680 | P9: =SUM(D9:O9) -> 7970
A10: 计划停车 | B10: h | D10: 705 | E10: 645 | F10: 705 | G10: 670 | H10: 690 | I10: 665 | J10: 640 | K10: 640 | L10: 630 | M10: 660 | N10: 640 | O10: 680 | P10: =SUM(D10:O10) -> 7970
A11: 非计划停车 | B11: h | P11: =SUM(D11:O11) -> 0
A12: 外部原因停车 | B12: h | P12: =SUM(D12:O12) -> 0
A13: 二、绝干收率
A14: 葡萄糖 | B14: % | D14: =IF(D27=0,0,1/D27) -> 1.0799136 | E14: =IF(E27=0,0,1/E27) -> 1.0799136 | F14: =IF(F27=0,0,1/F27) -> 1.0799136 | G14: =IF(G27=0,0,1/G27) -> 1.0799136 | H14: =IF(H27=0,0,1/H27) -> 1.0799136 | I14: =IF(I27=0,0,1/I27) -> 1.0799136 | J14: =IF(J27=0,0,1/J27) -> 1.0799136 | K14: =IF(K27=0,0,1/K27) -> 1.0799136 | ... P14: =IF(P27=0,0,1/P27) -> 1.0799148
A15: 三、生产负荷计划 | P15: =SUM(D15:O15) -> 0
A16: 果糖装置 | B16: % | D16: =IF(D7=0,0,(D18)/D7/333*24) -> 0.83160083 | E16: =IF(E7=0,0,(E18)/E7/333*24) -> 0.88088088 | F16: =IF(F7=0,0,(F18)/F7/333*24) -> 0.83160083 | G16: =IF(G7=0,0,(G18)/G7/333*24) -> 0.90810811 | H16: =IF(H7=0,0,(H18)/H7/333*24) -> 0.84084084 | I16: =IF(I7=0,0,(I18)/I7/333*24) -> 0.86486486 | J16: =IF(J7=0,0,(J18)/J7/333*24) -> 0.87318087 | K16: =IF(K7=0,0,(K18)/K7/333*24) -> 0.87318087 | ... P16: =IF(P7=0,0,(P18)/P7/333*24) -> 0.86851408
A17: 四、产品产量 | D17: 120 | E17: 0 | F17: 60 | G17: 120 | H17: 120 | I17: 120 | J17: 120 | K17: 120 | L17: 90 | M17: 0 | N17: 60 | O17: 150
A18: 葡萄糖(60%) | B18: t | D18: 450 | E18: 330 | F18: 450 | G18: 630 | H18: 630 | I18: 660 | J18: 1260 | K18: 1260 | L18: 1060 | M18: 1030 | N18: 930 | O18: 830 | P18: =SUM(D18:O18) -> 9520
A19: 安琪标准 | B19: t | D19: 64 | E19: 64 | F19: 210 | G19: 364 | H19: 64 | I19: 0 | J19: 0 | K19: 0 | L19: 0 | M19: 64 | N19: 64 | O19: 64 | P19: =SUM(D19:O19) -> 958
A20: 比重 | B20: % | P20: =IF(P18=0,0,P19/P18) -> 0.10063025
A21: 国标 | B21: t | P21: =SUM(D21:O21) -> 0
A22: 比重 | B22: % | P22: =IF(P18=0,0,P21/P18) -> 0
A23: 葡萄糖折绝干 | B23: t | D23: =D18*0.6+D19*0.7 -> 314.8 | E23: =E18*0.6+E19*0.7 -> 242.8 | F23: =F18*0.6+F19*0.7 -> 417 | G23: =G18*0.6+G19*0.7 -> 632.8 | H23: =H18*0.6+H19*0.7 -> 422.8 | I23: =I18*0.6+I19*0.7 -> 396 | J23: =J18*0.6+J19*0.7 -> 756 | K23: =K18*0.6+K19*0.7 -> 756 | ... P23: =P18*0.6+P19*0.7 -> 6382.6
A24: 绝干果糖合计 | B24: t | D24: =D23 -> 314.8 | E24: =E23 -> 242.8 | F24: =F23 -> 417 | G24: =G23 -> 632.8 | H24: =H23 -> 422.8 | I24: =I23 -> 396 | J24: =J23 -> 756 | K24: =K23 -> 756 | ... P24: =P23 -> 6382.6
A25: 五、辅助材料消耗计划 | D25: =D26/0.87 -> 335.05747 | E25: =E26/0.87 -> 258.42529 | F25: =F26/0.87 -> 443.83908 | G25: =G26/0.87 -> 673.52874 | H25: =H26/0.87 -> 450.01149 | I25: =I26/0.87 -> 421.49425 | J25: =J26/0.87 -> 804.66667 | K25: =K26/0.87 -> 804.66667 | ... P25: =P26/0.87 -> 6793.4253 | Q25: 商品单耗
A26: 淀粉(绝干) | B26: t | D26: =ROUND(D27*D$24,2) -> 291.5 | E26: =ROUND(E27*E$24,2) -> 224.83 | F26: =ROUND(F27*F$24,2) -> 386.14 | G26: =ROUND(G27*G$24,2) -> 585.97 | H26: =ROUND(H27*H$24,2) -> 391.51 | I26: =ROUND(I27*I$24,2) -> 366.7 | J26: =ROUND(J27*J$24,2) -> 700.06 | K26: =ROUND(K27*K$24,2) -> 700.06 | ... O26: =ROUND(O27*O$24,2) -> 502.63 | P26: =SUM(D26:O26) -> 5910.28 | R26: 2020年预算
A27: 单耗 | B27: t/t | D27: 0.926 | E27: 0.926 | F27: 0.926 | G27: 0.926 | H27: 0.926 | I27: 0.926 | J27: 0.926 | K27: 0.926 | L27: 0.926 | M27: 0.926 | N27: 0.926 | O27: 0.926 | P27: =ROUND(IF(P$24=0,0,P26/P$24),6) -> 0.925999 | Q27: =O27*0.6/0.86 -> 0.64604651 | R27: 0.66069767 | S27: =R27*0.86/0.6 -> 0.947
A28: 盐酸(折百) | B28: kg | D28: =ROUND(D29*D$24,2) -> 1636.96 | E28: =ROUND(E29*E$24,2) -> 1357.25 | F28: =ROUND(F29*F$24,2) -> 2331.03 | G28: =ROUND(G29*G$24,2) -> 3353.84 | H28: =ROUND(H29*H$24,2) -> 2198.56 | I28: =ROUND(I29*I$24,2) -> 2059.2 | J28: =ROUND(J29*J$24,2) -> 3931.2 | K28: =ROUND(K29*K$24,2) -> 3931.2 | ... O28: =ROUND(O29*O$24,2) -> 2822.56 | P28: =SUM(D28:O28) -> 33763.88
A29: 单耗 | B29: kg/t | D29: 5.2 | E29: 5.59 | F29: 5.59 | G29: 5.3 | H29: 5.2 | I29: 5.2 | J29: 5.2 | K29: 5.2 | L29: 5.4 | M29: 5.3 | N29: 5.3 | O29: 5.2 | P29: =ROUND(IF(P$24=0,0,P28/P$24),3) -> 5.29 | Q29: =O29*0.6 -> 3.12 | R29: 3.24
A30: 氢氧化钠(折百) | B30: kg | D30: =ROUND(D31*D$24,2) -> 1674.74 | E30: =ROUND(E31*E$24,2) -> 1381.53 | F30: =ROUND(F31*F$24,2) -> 2372.73 | G30: =ROUND(G31*G$24,2) -> 3385.48 | H30: =ROUND(H31*H$24,2) -> 2249.3 | I30: =ROUND(I31*I$24,2) -> 2106.72 | J30: =ROUND(J31*J$24,2) -> 4021.92 | K30: =ROUND(K31*K$24,2) -> 4021.92 | ... O30: =ROUND(O31*O$24,2) -> 2887.7 | P30: =SUM(D30:O30) -> 34371
A31: 单耗 | B31: kg/t | D31: 5.32 | E31: 5.69 | F31: 5.69 | G31: 5.35 | H31: 5.32 | I31: 5.32 | J31: 5.32 | K31: 5.32 | L31: 5.5 | M31: 5.35 | N31: 5.35 | O31: 5.32 | P31: =ROUND(IF(P$24=0,0,P30/P$24),3) -> 5.385 | Q31: =O31*0.6 -> 3.192 | R31: 3.3
A32: 硅藻土 | B32: kg | D32: =ROUND(D33*D$24,2) -> 302.21 | E32: =ROUND(E33*E$24,2) -> 250.08 | F32: =ROUND(F33*F$24,2) -> 429.51 | G32: =ROUND(G33*G$24,2) -> 632.8 | H32: =ROUND(H33*H$24,2) -> 405.89 | I32: =ROUND(I33*I$24,2) -> 380.16 | J32: =ROUND(J33*J$24,2) -> 725.76 | K32: =ROUND(K33*K$24,2) -> 725.76 | ... O32: =ROUND(O33*O$24,2) -> 521.09 | P32: =SUM(D32:O32) -> 6319.38
A33: 单耗 | B33: kg/t | D33: 0.96 | E33: 1.03 | F33: 1.03 | G33: 1 | H33: 0.96 | I33: 0.96 | J33: 0.96 | K33: 0.96 | L33: 1.07 | M33: 1 | N33: 1 | O33: 0.96 | P33: =ROUND(IF(P$24=0,0,P32/P$24),3) -> 0.99 | Q33: =O33*0.6 -> 0.576 | R33: 0.6
A34: 活性炭 | B34: kg | D34: =ROUND(D35*D$24,2) -> 57.61 | E34: =ROUND(E35*E$24,2) -> 44.43 | F34: =ROUND(F35*F$24,2) -> 76.31 | G34: =ROUND(G35*G$24,2) -> 115.8 | H34: =ROUND(H35*H$24,2) -> 77.37 | I34: =ROUND(I35*I$24,2) -> 72.47 | J34: =ROUND(J35*J$24,2) -> 138.35 | K34: =ROUND(K35*K$24,2) -> 138.35 | ... O34: =ROUND(O35*O$24,2) -> 99.33 | P34: =SUM(D34:O34) -> 1168.01
A35: 单耗 | B35: kg/t | D35: 0.183 | E35: 0.183 | F35: 0.183 | G35: 0.183 | H35: 0.183 | I35: 0.183 | J35: 0.183 | K35: 0.183 | L35: 0.183 | M35: 0.183 | N35: 0.183 | O35: 0.183 | P35: =ROUND(IF(P$24=0,0,P34/P$24),3) -> 0.183 | Q35: =O35*0.6 -> 0.1098 | R35: 0.108
A36: α耐高温淀粉酶 | B36: kg | D36: =ROUND(D37*D$24,2) -> 57.61 | E36: =ROUND(E37*E$24,2) -> 44.43 | F36: =ROUND(F37*F$24,2) -> 76.31 | G36: =ROUND(G37*G$24,2) -> 115.8 | H36: =ROUND(H37*H$24,2) -> 77.37 | I36: =ROUND(I37*I$24,2) -> 72.47 | J36: =ROUND(J37*J$24,2) -> 138.35 | K36: =ROUND(K37*K$24,2) -> 138.35 | ... O36: =ROUND(O37*O$24,2) -> 99.33 | P36: =SUM(D36:O36) -> 1168.01
A37: 单耗 | B37: kg/t | D37: 0.183 | E37: 0.183 | F37: 0.183 | G37: 0.183 | H37: 0.183 | I37: 0.183 | J37: 0.183 | K37: 0.183 | L37: 0.183 | M37: 0.183 | N37: 0.183 | O37: 0.183 | P37: =ROUND(IF(P$24=0,0,P36/P$24),3) -> 0.183 | Q37: =O37*0.6 -> 0.1098 | R37: 0.168
A38: 复合糖化酶 | B38: kg | D38: =ROUND(D39*D$24,2) -> 99.79 | E38: =ROUND(E39*E$24,2) -> 76.97 | F38: =ROUND(F39*F$24,2) -> 132.19 | G38: =ROUND(G39*G$24,2) -> 200.6 | H38: =ROUND(H39*H$24,2) -> 134.03 | I38: =ROUND(I39*I$24,2) -> 125.53 | J38: =ROUND(J39*J$24,2) -> 239.65 | K38: =ROUND(K39*K$24,2) -> 239.65 | ... O38: =ROUND(O39*O$24,2) -> 172.07 | P38: =SUM(D38:O38) -> 2023.29
A39: 单耗 | B39: kg/t | D39: 0.317 | E39: 0.317 | F39: 0.317 | G39: 0.317 | H39: 0.317 | I39: 0.317 | J39: 0.317 | K39: 0.317 | L39: 0.317 | M39: 0.317 | N39: 0.317 | O39: 0.317 | P39: =ROUND(IF(P$24=0,0,P38/P$24),3) -> 0.317 | Q39: =O39*0.6 -> 0.1902 | R39: 0.3
A40: 六、能源动力消耗计划
...

Sheet 麦芽糖
A1: 生产技术部麦芽糖年度生产计划(2025年)
P2: =能源消耗!Q2 -> 日 期：2024年9月10日
A3: 项 目 | B3: 单位 | C3: 指标 | D3: =果糖!D3 -> 2025年预算
D4: 1月 | E4: 2月 | F4: 3月 | G4: 4月 | H4: 5月 | I4: 6月 | J4: 7月 | K4: 8月 | L4: 9月 | M4: 10月 | N4: 11月 | O4: 12月 | P4: 合计
A5: 一、工时计划
A6: 日历时数 | B6: h | D6: 744 | E6: 672 | F6: 744 | G6: 720 | H6: 744 | I6: 720 | J6: 744 | K6: 744 | L6: 720 | M6: 744 | N6: 720 | O6: 744 | P6: =SUM(D6:O6) -> 8760
A7: 计划工时 | B7: h | D7: =D6-D9 -> 154 | E7: =E6-E9 -> 222 | F7: =F6-F9 -> 214 | G7: =G6-G9 -> 300 | H7: =H6-H9 -> 334 | I7: =I6-I9 -> 450 | J7: =J6-J9 -> 474 | K7: =K6-K9 -> 744 | ... O7: =O6-O9 -> 324 | P7: =SUM(D7:O7) -> 4120
A8: 计划工时 | B8: 天 | D8: =D7/24 -> 6.4166667 | E8: =E7/24 -> 9.25 | F8: =F7/24 -> 8.9166667 | G8: =G7/24 -> 12.5 | H8: =H7/24 -> 13.916667 | I8: =I7/24 -> 18.75 | J8: =J7/24 -> 19.75 | K8: =K7/24 -> 31 | ... P8: =P7/24 -> 171.66667
A9: 停车时数 | B9: h | D9: =SUM(D10:D12) -> 590 | E9: =SUM(E10:E12) -> 450 | F9: =SUM(F10:F12) -> 530 | G9: =SUM(G10:G12) -> 420 | H9: =SUM(H10:H12) -> 410 | I9: =SUM(I10:I12) -> 270 | J9: =SUM(J10:J12) -> 270 | K9: =SUM(K10:K12) -> 0 | ... O9: =SUM(O10:O12) -> 420 | P9: =SUM(D9:O9) -> 4640
A10: 计划停车 | B10: h | D10: 590 | E10: 450 | F10: 530 | G10: 420 | H10: 410 | I10: 270 | J10: 270 | L10: 210 | M10: 530 | N10: 540 | O10: 420 | P10: =SUM(D10:O10) -> 4640
A11: 非计划停车 | B11: h | P11: =SUM(D11:O11) -> 0
A12: 外部原因停车 | B12: h | P12: =SUM(D12:O12) -> 0
A13: 二、绝干收率 | D13: 1530 | E13: 486 | F13: 820 | G13: 1065 | H13: 1080 | I13: 1925 | J13: 2025 | K13: 2015 | L13: 1450 | M13: 720 | N13: 710 | O13: 1205
A14: 麦芽糖 | B14: % | D14: =IF(D33=0,0,1/D33) -> 1.0204082 | E14: =IF(E33=0,0,1/E33) -> 1.0204082 | F14: =IF(F33=0,0,1/F33) -> 1.0204082 | G14: =IF(G33=0,0,1/G33) -> 1.0204082 | H14: =IF(H33=0,0,1/H33) -> 1.0204082 | I14: =IF(I33=0,0,1/I33) -> 1.0204082 | J14: =IF(J33=0,0,1/J33) -> 1.0204082 | K14: =IF(K33=0,0,1/K33) -> 1.0204082 | ... P14: =IF(P33=0,0,1/P33) -> 1.0204082
A15: 三、生产负荷计划 | P15: =SUM(D15:O15) -> 0
A16: 麦芽糖装置 | B16: % | D16: =IF(D7=0,0,(D18)/D7/83*24) -> 0.84493819 | E16: =IF(E7=0,0,(E18)/E7/83*24) -> 0.88049495 | F16: =IF(F7=0,0,(F18)/F7/83*24) -> 0.87152348 | G16: =IF(G7=0,0,(G18)/G7/83*24) -> 0.93108434 | H16: =IF(H7=0,0,(H18)/H7/83*24) -> 0.86746988 | I16: =IF(I7=0,0,(I18)/I7/83*24) -> 0.93429719 | J16: =IF(J7=0,0,(J18)/J7/83*24) -> 0.92725332 | K16: =IF(K7=0,0,(K18)/K7/83*24) -> 0.81111543 | ... O16: =IF(O7=0,0,(O18)/O7/83*24) -> 0.87550201 | P16: =IF(P7=0,0,(P18)/P7/333*24) -> 0.21946996
A17: 四、产品产量
A18: 麦芽糖(75%) | B18: t | D18: 450 | E18: 676 | F18: 645 | G18: 966 | H18: 1002 | I18: 1454 | J18: 1520 | K18: 2087 | L18: 1541 | M18: 663 | N18: 561 | O18: 981 | P18: =SUM(D18:O18) -> 12546
A19: 雪花标准 | B19: t | P19: =SUM(D19:O19) -> 0
A20: 比重 | B20: % | P20: =IF(P18=0,0,P19/P18) -> 0
A21: 国标 | B21: t | E21: 769 | G21: 1316 | I21: 1843 | K21: 1970 | M21: 852 | O21: 785 | P21: =SUM(D21:O21) -> 7535
A22: 比重 | B22: % | P22: =IF(P18=0,0,P21/P18) -> 0.60058983
A23: 麦芽糖折绝干 | B23: t | D23: =(D18+D21)*0.75 -> 337.5 | E23: =(E18+E21)*0.75 -> 1083.75 | F23: =(F18+F21)*0.75 -> 483.75 | G23: =(G18+G21)*0.75 -> 1711.5 | H23: =(H18+H21)*0.75 -> 751.5 | I23: =(I18+I21)*0.75 -> 2472.75 | J23: =(J18+J21)*0.75 -> 1140 | K23: =(K18+K21)*0.75 -> 3042.75 | ... P23: =(P18+P21)*0.75 -> 15060.75
A24: 混配糖 | B24: t | D24: =D25 -> 1600 | E24: =E25 -> 700 | F24: =F25 -> 300 | G24: =G25 -> 300 | H24: =H25 -> 840 | I24: =I25 -> 420 | J24: =J25 -> 480 | K24: =K25 -> 1620 | ... O24: =O25 -> 1620 | P24: =SUM(D24:O24) -> 9440
A25: 混配糖 | B25: t | D25: 1600 | E25: 700 | F25: 300 | G25: 300 | H25: 840 | I25: 420 | J25: 480 | K25: 1620 | L25: 540 | M25: 420 | N25: 600 | O25: 1620 | P25: =SUM(D25:O25) -> 9440
A26: 比重 | B26: % | D26: =IF(D24=0,0,D25/D24) -> 1 | E26: =IF(E24=0,0,E25/E24) -> 1 | F26: =IF(F24=0,0,F25/F24) -> 1 | G26: =IF(G24=0,0,G25/G24) -> 1 | H26: =IF(H24=0,0,H25/H24) -> 1 | I26: =IF(I24=0,0,I25/I24) -> 1 | J26: =IF(J24=0,0,J25/J24) -> 1 | K26: =IF(K24=0,0,K25/K24) -> 1 | ... P26: =IF(P24=0,0,P25/P24) -> 1
A27: 国标 | B27: t | D27: =D24-D25 -> 0 | E27: =E24-E25 -> 0 | F27: =F24-F25 -> 0 | G27: =G24-G25 -> 0 | H27: =H24-H25 -> 0 | I27: =I24-I25 -> 0 | J27: =J24-J25 -> 0 | K27: =K24-K25 -> 0 | ... O27: =O24-O25 -> 0 | P27: =SUM(D27:O27) -> 0
A28: 比重 | B28: % | D28: =IF(D24=0,0,D27/D24) -> 0 | E28: =IF(E24=0,0,E27/E24) -> 0 | F28: =IF(F24=0,0,F27/F24) -> 0 | G28: =IF(G24=0,0,G27/G24) -> 0 | H28: =IF(H24=0,0,H27/H24) -> 0 | I28: =IF(I24=0,0,I27/I24) -> 0 | J28: =IF(J24=0,0,J27/J24) -> 0 | K28: =IF(K24=0,0,K27/K24) -> 0 | ... P28: =IF(P24=0,0,P27/P24) -> 0
A29: 麦芽糖折绝干 | B29: t | D29: =D25*0.64 -> 1024 | E29: =E25*0.64 -> 448 | F29: =F25*0.64 -> 192 | G29: =G25*0.64 -> 192 | H29: =H25*0.64 -> 537.6 | I29: =I25*0.64 -> 268.8 | J29: =J25*0.64 -> 307.2 | K29: =K25*0.64 -> 1036.8 | ... O29: =O25*0.64 -> 1036.8 | P29: =SUM(D29:O29) -> 6041.6 | Q29: =P24*0.89 -> 8401.6
A30: 绝干糖浆合计 | B30: t | D30: =D23+D29 -> 1361.5 | E30: =E23+E29 -> 1531.75 | F30: =F23+F29 -> 675.75 | G30: =G23+G29 -> 1903.5 | H30: =H23+H29 -> 1289.1 | I30: =I23+I29 -> 2741.55 | J30: =J23+J29 -> 1447.2 | K30: =K23+K29 -> 4079.55 | ... P30: =P23+P29 -> 21102.35
A31: 五、辅助材料消耗计划 | D31: =D32/0.87 -> 1533.3333 | E31: =E32/0.87 -> 1725.2874 | F31: =F32/0.87 -> 760.91954 | G31: =G32/0.87 -> 2143.6782 | H31: =H32/0.87 -> 1451.7241 | I31: =I32/0.87 -> 3088.5057 | J31: =J32/0.87 -> 1629.8851 | K31: =K32/0.87 -> 4595.4023 | ... P31: =P32/0.87 -> 23768.966 | Q31: 商品单耗
A32: 淀粉(绝干) | B32: t | D32: =ROUND(D33*D$30,0) -> 1334 | E32: =ROUND(E33*E$30,0) -> 1501 | F32: =ROUND(F33*F$30,0) -> 662 | G32: =ROUND(G33*G$30,0) -> 1865 | H32: =ROUND(H33*H$30,0) -> 1263 | I32: =ROUND(I33*I$30,0) -> 2687 | J32: =ROUND(J33*J$30,0) -> 1418 | K32: =ROUND(K33*K$30,0) -> 3998 | ... O32: =ROUND(O33*O$30,0) -> 2314 | P32: {=SUM(D32:O32)} -> 20679
A33: 单耗 | B33: t/t | D33: 0.98 | E33: 0.98 | F33: 0.98 | G33: 0.98 | H33: 0.98 | I33: 0.98 | J33: 0.98 | K33: 0.98 | L33: 0.98 | M33: 0.98 | N33: 0.98 | O33: 0.98 | P33: =ROUND(IF(P$30=0,0,P32/P$30),3) -> 0.98 | Q33: =O33*0.75/0.86 -> 0.85465116 | R33: 0.86337209
A34: 盐酸(折百) | B34: kg | D34: =ROUND(D35*D$30,2) -> 6671.35 | E34: =ROUND(E35*E$30,2) -> 7505.58 | F34: =ROUND(F35*F$30,2) -> 3311.18 | G34: =ROUND(G35*G$30,2) -> 9136.8 | H34: =ROUND(H35*H$30,2) -> 6058.77 | I34: =ROUND(I35*I$30,2) -> 12611.13 | J34: =ROUND(J35*J$30,2) -> 6657.12 | K34: =ROUND(K35*K$30,2) -> 18765.93 | ... O34: =ROUND(O35*O$30,2) -> 11570.37 | P34: =SUM(D34:O34) -> 100032.1
A35: 单耗 | B35: kg/t | D35: 4.9 | E35: 4.9 | F35: 4.9 | G35: 4.8 | H35: 4.7 | I35: 4.6 | J35: 4.6 | K35: 4.6 | L35: 4.7 | M35: 4.8 | N35: 4.9 | O35: 4.9 | P35: =ROUND(IF(P$30=0,0,P34/P$30),3) -> 4.74 | Q35: =O35*0.75 -> 3.675 | R35: 4.65
A36: 氢氧化钠(折百) | B36: kg | D36: =ROUND(D37*D$30,2) -> 6671.35 | E36: =ROUND(E37*E$30,2) -> 7505.58 | F36: =ROUND(F37*F$30,2) -> 3311.18 | G36: =ROUND(G37*G$30,2) -> 9327.15 | H36: =ROUND(H37*H$30,2) -> 6058.77 | I36: =ROUND(I37*I$30,2) -> 12611.13 | J36: =ROUND(J37*J$30,2) -> 6657.12 | K36: =ROUND(K37*K$30,2) -> 18765.93 | ... O36: =ROUND(O37*O$30,2) -> 11570.37 | P36: =SUM(D36:O36) -> 100222.45
A37: 单耗 | B37: kg/t | D37: 4.9 | E37: 4.9 | F37: 4.9 | G37: 4.9 | H37: 4.7 | I37: 4.6 | J37: 4.6 | K37: 4.6 | L37: 4.7 | M37: 4.8 | N37: 4.9 | O37: 4.9 | P37: =ROUND(IF(P$30=0,0,P36/P$30),3) -> 4.749 | Q37: =O37*0.75 -> 3.675 | R37: 4.725
A38: 硅藻土 | B38: kg | D38: =ROUND(D39*D$30,2) -> 980.28 | E38: =ROUND(E39*E$30,2) -> 1072.23 | F38: =ROUND(F39*F$30,2) -> 473.03 | G38: =ROUND(G39*G$30,2) -> 1313.42 | H38: =ROUND(H39*H$30,2) -> 889.48 | I38: =ROUND(I39*I$30,2) -> 1864.25 | J38: =ROUND(J39*J$30,2) -> 984.1 | K38: =ROUND(K39*K$30,2) -> 2774.09 | ... O38: =ROUND(O39*O$30,2) -> 1629.3 | P38: =SUM(D38:O38) -> 14547.97
A39: 单耗 | B39: kg/t | D39: 0.72 | E39: 0.7 | F39: 0.7 | G39: 0.69 | H39: 0.69 | I39: 0.68 | J39: 0.68 | K39: 0.68 | L39: 0.68 | M39: 0.7 | N39: 0.7 | O39: 0.69 | P39: =ROUND(IF(P$30=0,0,P38/P$30),3) -> 0.689 | Q39: =O39*0.75 -> 0.5175 | R39: 0.69
A40: 活性炭 | B40: kg | D40: =ROUND(D41*D$30,2) -> 296.81 | E40: =ROUND(E41*E$30,2) -> 333.92 | F40: =ROUND(F41*F$30,2) -> 147.31 | G40: =ROUND(G41*G$30,2) -> 414.96 | H40: =ROUND(H41*H$30,2) -> 281.02 | I40: =ROUND(I41*I$30,2) -> 597.66 | J40: =ROUND(J41*J$30,2) -> 315.49 | K40: =ROUND(K41*K$30,2) -> 889.34 | ... O40: =ROUND(O41*O$30,2) -> 514.76 | P40: =SUM(D40:O40) -> 4600.3
...

Sheet 锅炉工段
A1: 生产技术部锅炉工段生产计划(2025年)
P2: =果糖!P2 -> 日 期：2024年9月10日
A3: 项 目 | B3: 单位 | C3: 指标 | D3: =果糖!D3 -> 2025年预算
D4: 1月 | E4: 2月 | F4: 3月 | G4: 4月 | H4: 5月 | I4: 6月 | J4: 7月 | K4: 8月 | L4: 9月 | M4: 10月 | N4: 11月 | O4: 12月 | P4: 合计
A5: 一、工时计划 | Q5: 停车
A6: 1、6吨锅炉
A7: 日历时数 | B7: h | D7: =果糖!D6 -> 744 | E7: =果糖!E6 -> 672 | F7: =果糖!F6 -> 744 | G7: =果糖!G6 -> 720 | H7: =果糖!H6 -> 744 | I7: =果糖!I6 -> 720 | J7: =果糖!J6 -> 744 | K7: =果糖!K6 -> 744 | ... O7: =果糖!O6 -> 744 | P7: =SUM(D7:O7) -> 8760
A8: 计划工时 | B8: h | D8: =D7-D10 -> 744 | E8: =E7-E10 -> 672 | F8: =F7-F10 -> 744 | G8: =G7-G10 -> 720 | H8: =H7-H10 -> 744 | I8: =I7-I10 -> 720 | J8: =J7-J10 -> 744 | K8: =K7-K10 -> 744 | ... O8: =O7-O10 -> 744 | P8: =SUM(D8:O8) -> 8760
A9: 计划工时 | B9: 天 | D9: =D8/24 -> 31 | E9: =E8/24 -> 28 | F9: =F8/24 -> 31 | G9: =G8/24 -> 30 | H9: =H8/24 -> 31 | I9: =I8/24 -> 30 | J9: =J8/24 -> 31 | K9: =K8/24 -> 31 | ... P9: =P8/24 -> 365
A10: 停车时数 | B10: h | D10: =SUM(D11:D13) -> 0 | E10: =SUM(E11:E13) -> 0 | F10: =SUM(F11:F13) -> 0 | G10: =SUM(G11:G13) -> 0 | H10: =SUM(H11:H13) -> 0 | I10: =SUM(I11:I13) -> 0 | J10: =SUM(J11:J13) -> 0 | K10: =SUM(K11:K13) -> 0 | ... O10: =SUM(O11:O13) -> 0 | P10: =SUM(D10:O10) -> 0
A11: 计划停车 | B11: h
A12: 非计划停车 | B12: h | P12: =SUM(D12:O12) -> 0
A13: 外部原因停车 | B13: h | P13: =SUM(D13:O13) -> 0
A14: 2、15吨锅炉
A15: 日历时数 | B15: h | D15: =D7 -> 744 | E15: =E7 -> 672 | F15: =F7 -> 744 | G15: =G7 -> 720 | H15: =H7 -> 744 | I15: =I7 -> 720 | J15: =J7 -> 744 | K15: =K7 -> 744 | ... O15: =O7 -> 744 | P15: =SUM(D15:O15) -> 8760
A16: 计划工时 | B16: h | D16: =D15-D18 -> 744 | E16: =E15-E18 -> 672 | F16: =F15-F18 -> 744 | G16: =G15-G18 -> 720 | H16: =H15-H18 -> 744 | I16: =I15-I18 -> 720 | J16: =J15-J18 -> 744 | K16: =K15-K18 -> 744 | ... O16: =O15-O18 -> 744 | P16: =SUM(D16:O16) -> 8760
A17: 计划工时 | B17: 天 | D17: =D16/24 -> 31 | E17: =E16/24 -> 28 | F17: =F16/24 -> 31 | G17: =G16/24 -> 30 | H17: =H16/24 -> 31 | I17: =I16/24 -> 30 | J17: =J16/24 -> 31 | K17: =K16/24 -> 31 | ... P17: =P16/24 -> 365
A18: 停车时数 | B18: h | D18: =SUM(D19:D21) -> 0 | E18: =SUM(E19:E21) -> 0 | F18: =SUM(F19:F21) -> 0 | G18: =SUM(G19:G21) -> 0 | H18: =SUM(H19:H21) -> 0 | I18: =SUM(I19:I21) -> 0 | J18: =SUM(J19:J21) -> 0 | K18: =SUM(K19:K21) -> 0 | ... O18: =SUM(O19:O21) -> 0 | P18: =SUM(D18:O18) -> 0
A19: 计划停车 | B19: h | P19: =SUM(D19:O19) -> 0
A20: 非计划停车 | B20: h | P20: =SUM(D20:O20) -> 0
A21: 外部原因停车 | B21: h | P21: =SUM(D21:O21) -> 0
A22: 二、蒸汽产量
A23: 自产比例 | B23: % | D23: 0 | E23: 0 | F23: 0 | G23: 0 | H23: 0 | I23: 0 | J23: 0 | K23: 0 | L23: 0 | M23: 0 | N23: 0 | O23: 0 | P23: 0
A24: 蒸汽产量 | B24: t | D24: =ROUND((果糖!D59+麦芽糖!D51+污水!D36)*D23,0) -> 0 | E24: =ROUND((果糖!E59+麦芽糖!E51+污水!E36)*E23,0) -> 0 | F24: =ROUND((果糖!F59+麦芽糖!F51+污水!F36)*F23,0) -> 0 | G24: =ROUND((果糖!G59+麦芽糖!G51+污水!G36)*G23,0) -> 0 | H24: =ROUND((果糖!H59+麦芽糖!H51+污水!H36)*H23,0) -> 0 | I24: =ROUND((果糖!I59+麦芽糖!I51+污水!I36)*I23,0) -> 0 | J24: =ROUND((果糖!J59+麦芽糖!J51+污水!J36)*J23,0) -> 0 | K24: =ROUND((果糖!K59+麦芽糖!K51+污水!K36)*K23,0) -> 0 | ... O24: =ROUND((果糖!O59+麦芽糖!O51+污水!O36)*O23,0) -> 0 | P24: =SUM(D24:O24) -> 0
A25: 三、消耗指标
A26: 脱盐水 | B26: t | D26: =ROUND(D27*D24,0) -> 0 | E26: =ROUND(E27*E24,0) -> 0 | F26: =ROUND(F27*F24,0) -> 0 | G26: =ROUND(G27*G24,0) -> 0 | H26: =ROUND(H27*H24,0) -> 0 | I26: =ROUND(I27*I24,0) -> 0 | J26: =ROUND(J27*J24,0) -> 0 | K26: =ROUND(K27*K24,0) -> 0 | ... O26: =ROUND(O27*O24,0) -> 0 | P26: =SUM(D26:O26) -> 0
A27: 单耗 | B27: t/t | P27: =IF(P24=0,0,ROUND(P26/P24,2)) -> 0
A28: 电 | B28: 万kw.h | D28: =ROUND(D29*D26,0)/10000 -> 0 | E28: =ROUND(E29*E26,0)/10000 -> 0 | F28: =ROUND(F29*F26,0)/10000 -> 0 | G28: =ROUND(G29*G26,0)/10000 -> 0 | H28: =ROUND(H29*H26,0)/10000 -> 0 | I28: =ROUND(I29*I26,0)/10000 -> 0 | J28: =ROUND(J29*J26,0)/10000 -> 0 | K28: =ROUND(K29*K26,0)/10000 -> 0 | ... O28: =ROUND(O29*O26,0)/10000 -> 0 | P28: =SUM(D28:O28) -> 0
A29: 单耗 | B29: kw.h/t | P29: =IF(P24=0,0,ROUND(P28/P24*10000,2)) -> 0
A30: 天然气 | B30: m3 | D30: =ROUND(D31*D24,0) -> 0 | E30: =ROUND(E31*E24,0) -> 0 | F30: =ROUND(F31*F24,0) -> 0 | G30: =ROUND(G31*G24,0) -> 0 | H30: =ROUND(H31*H24,0) -> 0 | I30: =ROUND(I31*I24,0) -> 0 | J30: =ROUND(J31*J24,0) -> 0 | K30: =ROUND(K31*K24,0) -> 0 | ... O30: =ROUND(O31*O24,0) -> 0 | P30: =SUM(D30:O30) -> 0
A31: 单耗 | B31: m3/t | P31: =IF(P24=0,0,ROUND(P30/P24,2)) -> 0
A32: 主管副总： | H32: 部门经理： | N32: 编制：
A33: 注：表格中绿色部分为自动计算，原则上不允许修改，如需修改请及时与财务部预算处相关预算员沟通。

Sheet 污水
A1: 生产技术部污水处理工段生产计划(2025年) | AG1: 锅炉工段生产计划 | AW1: 锅炉工段生产计划 | BM1: 锅炉工段生产计划 | CC1: 锅炉工段生产计划 | CS1: 锅炉工段生产计划 | DI1: 锅炉工段生产计划 | DY1: 锅炉工段生产计划 | EO1: 锅炉工段生产计划 | FE1: 锅炉工段生产计划 | FU1: 锅炉工段生产计划 | GK1: 锅炉工段生产计划 | HA1: 锅炉工段生产计划 | HQ1: 锅炉工段生产计划 | IG1: 锅炉工段生产计划 | IW1: 锅炉工段生产计划 | JM1: 锅炉工段生产计划 | KC1: 锅炉工段生产计划 | KS1: 锅炉工段生产计划 | LI1: 锅炉工段生产计划 | LY1: 锅炉工段生产计划 | MO1: 锅炉工段生产计划 | NE1: 锅炉工段生产计划 | NU1: 锅炉工段生产计划 | OK1: 锅炉工段生产计划 | PA1: 锅炉工段生产计划 | PQ1: 锅炉工段生产计划 | QG1: 锅炉工段生产计划 | QW1: 锅炉工段生产计划 | RM1: 锅炉工段生产计划 | SC1: 锅炉工段生产计划 | SS1: 锅炉工段生产计划 | TI1: 锅炉工段生产计划 | TY1: 锅炉工段生产计划 | UO1: 锅炉工段生产计划 | VE1: 锅炉工段生产计划 | VU1: 锅炉工段生产计划 | WK1: 锅炉工段生产计划 | XA1: 锅炉工段生产计划 | XQ1: 锅炉工段生产计划 | YG1: 锅炉工段生产计划 | YW1: 锅炉工段生产计划 | ZM1: 锅炉工段生产计划 | AAC1: 锅炉工段生产计划 | AAS1: 锅炉工段生产计划 | ABI1: 锅炉工段生产计划 | ABY1: 锅炉工段生产计划 | ACO1: 锅炉工段生产计划 | ADE1: 锅炉工段生产计划 | ADU1: 锅炉工段生产计划 | AEK1: 锅炉工段生产计划 | AFA1: 锅炉工段生产计划 | AFQ1: 锅炉工段生产计划 | AGG1: 锅炉工段生产计划 | AGW1: 锅炉工段生产计划 | AHM1: 锅炉工段生产计划 | AIC1: 锅炉工段生产计划 | AIS1: 锅炉工段生产计划 | AJI1: 锅炉工段生产计划 | AJY1: 锅炉工段生产计划 | AKO1: 锅炉工段生产计划 | ALE1: 锅炉工段生产计划 | ALU1: 锅炉工段生产计划 | AMK1: 锅炉工段生产计划 | ANA1: 锅炉工段生产计划 | ANQ1: 锅炉工段生产计划 | AOG1: 锅炉工段生产计划 | AOW1: 锅炉工段生产计划 | APM1: 锅炉工段生产计划 | AQC1: 锅炉工段生产计划 | AQS1: 锅炉工段生产计划 | ARI1: 锅炉工段生产计划 | ARY1: 锅炉工段生产计划 | ASO1: 锅炉工段生产计划 | ATE1: 锅炉工段生产计划 | ATU1: 锅炉工段生产计划 | AUK1: 锅炉工段生产计划 | AVA1: 锅炉工段生产计划 | AVQ1: 锅炉工段生产计划 | AWG1: 锅炉工段生产计划 | AWW1: 锅炉工段生产计划 | AXM1: 锅炉工段生产计划 | AYC1: 锅炉工段生产计划 | AYS1: 锅炉工段生产计划 | AZI1: 锅炉工段生产计划 | AZY1: 锅炉工段生产计划 | BAO1: 锅炉工段生产计划 | BBE1: 锅炉工段生产计划 | BBU1: 锅炉工段生产计划 | BCK1: 锅炉工段生产计划 | BDA1: 锅炉工段生产计划 | BDQ1: 锅炉工段生产计划 | BEG1: 锅炉工段生产计划 | BEW1: 锅炉工段生产计划 | BFM1: 锅炉工段生产计划 | BGC1: 锅炉工段生产计划 | BGS1: 锅炉工段生产计划 | BHI1: 锅炉工段生产计划 | BHY1: 锅炉工段生产计划 | BIO1: 锅炉工段生产计划 | BJE1: 锅炉工段生产计划 | BJU1: 锅炉工段生产计划 | BKK1: 锅炉工段生产计划 | BLA1: 锅炉工段生产计划 | BLQ1: 锅炉工段生产计划 | BMG1: 锅炉工段生产计划 | BMW1: 锅炉工段生产计划 | BNM1: 锅炉工段生产计划 | BOC1: 锅炉工段生产计划 | BOS1: 锅炉工段生产计划 | BPI1: 锅炉工段生产计划 | BPY1: 锅炉工段生产计划 | BQO1: 锅炉工段生产计划 | BRE1: 锅炉工段生产计划 | BRU1: 锅炉工段生产计划 | BSK1: 锅炉工段生产计划 | BTA1: 锅炉工段生产计划 | BTQ1: 锅炉工段生产计划 | BUG1: 锅炉工段生产计划 | BUW1: 锅炉工段生产计划 | BVM1: 锅炉工段生产计划 | BWC1: 锅炉工段生产计划 | BWS1: 锅炉工段生产计划 | BXI1: 锅炉工段生产计划 | BXY1: 锅炉工段生产计划 | BYO1: 锅炉工段生产计划 | BZE1: 锅炉工段生产计划 | BZU1: 锅炉工段生产计划 | CAK1: 锅炉工段生产计划 | CBA1: 锅炉工段生产计划 | CBQ1: 锅炉工段生产计划 | CCG1: 锅炉工段生产计划 | CCW1: 锅炉工段生产计划 | CDM1: 锅炉工段生产计划 | CEC1: 锅炉工段生产计划 | CES1: 锅炉工段生产计划 | CFI1: 锅炉工段生产计划 | CFY1: 锅炉工段生产计划 | CGO1: 锅炉工段生产计划 | CHE1: 锅炉工段生产计划 | CHU1: 锅炉工段生产计划 | CIK1: 锅炉工段生产计划 | CJA1: 锅炉工段生产计划 | CJQ1: 锅炉工段生产计划 | CKG1: 锅炉工段生产计划 | CKW1: 锅炉工段生产计划 | CLM1: 锅炉工段生产计划 | CMC1: 锅炉工段生产计划 | CMS1: 锅炉工段生产计划 | CNI1: 锅炉工段生产计划 | CNY1: 锅炉工段生产计划 | COO1: 锅炉工段生产计划 | CPE1: 锅炉工段生产计划 | CPU1: 锅炉工段生产计划 | CQK1: 锅炉工段生产计划 | CRA1: 锅炉工段生产计划 | CRQ1: 锅炉工段生产计划 | CSG1: 锅炉工段生产计划 | CSW1: 锅炉工段生产计划 | CTM1: 锅炉工段生产计划 | CUC1: 锅炉工段生产计划 | CUS1: 锅炉工段生产计划 | CVI1: 锅炉工段生产计划 | CVY1: 锅炉工段生产计划 | CWO1: 锅炉工段生产计划 | CXE1: 锅炉工段生产计划 | CXU1: 锅炉工段生产计划 | CYK1: 锅炉工段生产计划 | CZA1: 锅炉工段生产计划 | CZQ1: 锅炉工段生产计划 | DAG1: 锅炉工段生产计划 | DAW1: 锅炉工段生产计划 | DBM1: 锅炉工段生产计划 | DCC1: 锅炉工段生产计划 | DCS1: 锅炉工段生产计划 | DDI1: 锅炉工段生产计划 | DDY1: 锅炉工段生产计划 | DEO1: 锅炉工段生产计划 | DFE1: 锅炉工段生产计划 | DFU1: 锅炉工段生产计划 | DGK1: 锅炉工段生产计划 | DHA1: 锅炉工段生产计划 | DHQ1: 锅炉工段生产计划 | DIG1: 锅炉工段生产计划 | DIW1: 锅炉工段生产计划 | DJM1: 锅炉工段生产计划 | DKC1: 锅炉工段生产计划 | DKS1: 锅炉工段生产计划 | DLI1: 锅炉工段生产计划 | DLY1: 锅炉工段生产计划 | DMO1: 锅炉工段生产计划 | DNE1: 锅炉工段生产计划 | DNU1: 锅炉工段生产计划 | DOK1: 锅炉工段生产计划 | DPA1: 锅炉工段生产计划 | DPQ1: 锅炉工段生产计划 | DQG1: 锅炉工段生产计划 | DQW1: 锅炉工段生产计划 | DRM1: 锅炉工段生产计划 | DSC1: 锅炉工段生产计划 | DSS1: 锅炉工段生产计划 | DTI1: 锅炉工段生产计划 | DTY1: 锅炉工段生产计划 | DUO1: 锅炉工段生产计划 | DVE1: 锅炉工段生产计划 | DVU1: 锅炉工段生产计划 | DWK1: 锅炉工段生产计划 | DXA1: 锅炉工段生产计划 | DXQ1: 锅炉工段生产计划 | DYG1: 锅炉工段生产计划 | DYW1: 锅炉工段生产计划 | DZM1: 锅炉工段生产计划 | EAC1: 锅炉工段生产计划 | EAS1: 锅炉工段生产计划 | EBI1: 锅炉工段生产计划 | EBY1: 锅炉工段生产计划 | ECO1: 锅炉工段生产计划 | EDE1: 锅炉工段生产计划 | EDU1: 锅炉工段生产计划 | EEK1: 锅炉工段生产计划 | EFA1: 锅炉工段生产计划 | EFQ1: 锅炉工段生产计划 | EGG1: 锅炉工段生产计划 | EGW1: 锅炉工段生产计划 | EHM1: 锅炉工段生产计划 | EIC1: 锅炉工段生产计划 | EIS1: 锅炉工段生产计划 | EJI1: 锅炉工段生产计划 | EJY1: 锅炉工段生产计划 | EKO1: 锅炉工段生产计划 | ELE1: 锅炉工段生产计划 | ELU1: 锅炉工段生产计划 | EMK1: 锅炉工段生产计划 | ENA1: 锅炉工段生产计划 | ENQ1: 锅炉工段生产计划 | EOG1: 锅炉工段生产计划 | EOW1: 锅炉工段生产计划 | EPM1: 锅炉工段生产计划 | EQC1: 锅炉工段生产计划 | EQS1: 锅炉工段生产计划 | ERI1: 锅炉工段生产计划 | ERY1: 锅炉工段生产计划 | ESO1: 锅炉工段生产计划 | ETE1: 锅炉工段生产计划 | ETU1: 锅炉工段生产计划 | EUK1: 锅炉工段生产计划 | EVA1: 锅炉工段生产计划 | EVQ1: 锅炉工段生产计划 | EWG1: 锅炉工段生产计划 | EWW1: 锅炉工段生产计划 | EXM1: 锅炉工段生产计划 | EYC1: 锅炉工段生产计划 | EYS1: 锅炉工段生产计划 | EZI1: 锅炉工段生产计划 | EZY1: 锅炉工段生产计划 | FAO1: 锅炉工段生产计划 | FBE1: 锅炉工段生产计划 | FBU1: 锅炉工段生产计划 | FCK1: 锅炉工段生产计划 | FDA1: 锅炉工段生产计划 | FDQ1: 锅炉工段生产计划 | FEG1: 锅炉工段生产计划 | FEW1: 锅炉工段生产计划 | FFM1: 锅炉工段生产计划 | FGC1: 锅炉工段生产计划 | FGS1: 锅炉工段生产计划 | FHI1: 锅炉工段生产计划 | FHY1: 锅炉工段生产计划 | FIO1: 锅炉工段生产计划 | FJE1: 锅炉工段生产计划 | FJU1: 锅炉工段生产计划 | FKK1: 锅炉工段生产计划 | FLA1: 锅炉工段生产计划 | FLQ1: 锅炉工段生产计划 | FMG1: 锅炉工段生产计划 | FMW1: 锅炉工段生产计划 | FNM1: 锅炉工段生产计划 | FOC1: 锅炉工段生产计划 | FOS1: 锅炉工段生产计划 | FPI1: 锅炉工段生产计划 | FPY1: 锅炉工段生产计划 | FQO1: 锅炉工段生产计划 | FRE1: 锅炉工段生产计划 | FRU1: 锅炉工段生产计划 | FSK1: 锅炉工段生产计划 | FTA1: 锅炉工段生产计划 | FTQ1: 锅炉工段生产计划 | FUG1: 锅炉工段生产计划 | FUW1: 锅炉工段生产计划 | FVM1: 锅炉工段生产计划 | FWC1: 锅炉工段生产计划 | FWS1: 锅炉工段生产计划 | FXI1: 锅炉工段生产计划 | FXY1: 锅炉工段生产计划 | FYO1: 锅炉工段生产计划 | FZE1: 锅炉工段生产计划 | FZU1: 锅炉工段生产计划 | GAK1: 锅炉工段生产计划 | GBA1: 锅炉工段生产计划 | GBQ1: 锅炉工段生产计划 | GCG1: 锅炉工段生产计划 | GCW1: 锅炉工段生产计划 | GDM1: 锅炉工段生产计划 | GEC1: 锅炉工段生产计划 | GES1: 锅炉工段生产计划 | GFI1: 锅炉工段生产计划 | GFY1: 锅炉工段生产计划 | GGO1: 锅炉工段生产计划 | GHE1: 锅炉工段生产计划 | GHU1: 锅炉工段生产计划 | GIK1: 锅炉工段生产计划 | GJA1: 锅炉工段生产计划 | GJQ1: 锅炉工段生产计划 | GKG1: 锅炉工段生产计划 | GKW1: 锅炉工段生产计划 | GLM1: 锅炉工段生产计划 | GMC1: 锅炉工段生产计划 | GMS1: 锅炉工段生产计划 | GNI1: 锅炉工段生产计划 | GNY1: 锅炉工段生产计划 | GOO1: 锅炉工段生产计划 | GPE1: 锅炉工段生产计划 | GPU1: 锅炉工段生产计划 | GQK1: 锅炉工段生产计划 | GRA1: 锅炉工段生产计划 | GRQ1: 锅炉工段生产计划 | GSG1: 锅炉工段生产计划 | GSW1: 锅炉工段生产计划 | GTM1: 锅炉工段生产计划 | GUC1: 锅炉工段生产计划 | GUS1: 锅炉工段生产计划 | GVI1: 锅炉工段生产计划 | GVY1: 锅炉工段生产计划 | GWO1: 锅炉工段生产计划 | GXE1: 锅炉工段生产计划 | GXU1: 锅炉工段生产计划 | GYK1: 锅炉工段生产计划 | GZA1: 锅炉工段生产计划 | GZQ1: 锅炉工段生产计划 | HAG1: 锅炉工段生产计划 | HAW1: 锅炉工段生产计划 | HBM1: 锅炉工段生产计划 | HCC1: 锅炉工段生产计划 | HCS1: 锅炉工段生产计划 | HDI1: 锅炉工段生产计划 | HDY1: 锅炉工段生产计划 | HEO1: 锅炉工段生产计划 | HFE1: 锅炉工段生产计划 | HFU1: 锅炉工段生产计划 | HGK1: 锅炉工段生产计划 | HHA1: 锅炉工段生产计划 | HHQ1: 锅炉工段生产计划 | HIG1: 锅炉工段生产计划 | HIW1: 锅炉工段生产计划 | HJM1: 锅炉工段生产计划 | HKC1: 锅炉工段生产计划 | HKS1: 锅炉工段生产计划 | HLI1: 锅炉工段生产计划 | HLY1: 锅炉工段生产计划 | HMO1: 锅炉工段生产计划 | HNE1: 锅炉工段生产计划 | HNU1: 锅炉工段生产计划 | HOK1: 锅炉工段生产计划 | HPA1: 锅炉工段生产计划 | HPQ1: 锅炉工段生产计划 | HQG1: 锅炉工段生产计划 | HQW1: 锅炉工段生产计划 | HRM1: 锅炉工段生产计划 | HSC1: 锅炉工段生产计划 | HSS1: 锅炉工段生产计划 | HTI1: 锅炉工段生产计划 | HTY1: 锅炉工段生产计划 | HUO1: 锅炉工段生产计划 | HVE1: 锅炉工段生产计划 | HVU1: 锅炉工段生产计划 | HWK1: 锅炉工段生产计划 | HXA1: 锅炉工段生产计划 | HXQ1: 锅炉工段生产计划 | HYG1: 锅炉工段生产计划 | HYW1: 锅炉工段生产计划 | HZM1: 锅炉工段生产计划 | IAC1: 锅炉工段生产计划 | IAS1: 锅炉工段生产计划 | IBI1: 锅炉工段生产计划 | IBY1: 锅炉工段生产计划 | ICO1: 锅炉工段生产计划 | IDE1: 锅炉工段生产计划 | IDU1: 锅炉工段生产计划 | IEK1: 锅炉工段生产计划 | IFA1: 锅炉工段生产计划 | IFQ1: 锅炉工段生产计划 | IGG1: 锅炉工段生产计划 | IGW1: 锅炉工段生产计划 | IHM1: 锅炉工段生产计划 | IIC1: 锅炉工段生产计划 | IIS1: 锅炉工段生产计划 | IJI1: 锅炉工段生产计划 | IJY1: 锅炉工段生产计划 | IKO1: 锅炉工段生产计划 | ILE1: 锅炉工段生产计划 | ILU1: 锅炉工段生产计划 | IMK1: 锅炉工段生产计划 | INA1: 锅炉工段生产计划 | INQ1: 锅炉工段生产计划 | IOG1: 锅炉工段生产计划 | IOW1: 锅炉工段生产计划 | IPM1: 锅炉工段生产计划 | IQC1: 锅炉工段生产计划 | IQS1: 锅炉工段生产计划 | IRI1: 锅炉工段生产计划 | IRY1: 锅炉工段生产计划 | ISO1: 锅炉工段生产计划 | ITE1: 锅炉工段生产计划 | ITU1: 锅炉工段生产计划 | IUK1: 锅炉工段生产计划 | IVA1: 锅炉工段生产计划 | IVQ1: 锅炉工段生产计划 | IWG1: 锅炉工段生产计划 | IWW1: 锅炉工段生产计划 | IXM1: 锅炉工段生产计划 | IYC1: 锅炉工段生产计划 | IYS1: 锅炉工段生产计划 | IZI1: 锅炉工段生产计划 | IZY1: 锅炉工段生产计划 | JAO1: 锅炉工段生产计划 | JBE1: 锅炉工段生产计划 | JBU1: 锅炉工段生产计划 | JCK1: 锅炉工段生产计划 | JDA1: 锅炉工段生产计划 | JDQ1: 锅炉工段生产计划 | JEG1: 锅炉工段生产计划 | JEW1: 锅炉工段生产计划 | JFM1: 锅炉工段生产计划 | JGC1: 锅炉工段生产计划 | JGS1: 锅炉工段生产计划 | JHI1: 锅炉工段生产计划 | JHY1: 锅炉工段生产计划 | JIO1: 锅炉工段生产计划 | JJE1: 锅炉工段生产计划 | JJU1: 锅炉工段生产计划 | JKK1: 锅炉工段生产计划 | JLA1: 锅炉工段生产计划 | JLQ1: 锅炉工段生产计划 | JMG1: 锅炉工段生产计划 | JMW1: 锅炉工段生产计划 | JNM1: 锅炉工段生产计划 | JOC1: 锅炉工段生产计划 | JOS1: 锅炉工段生产计划 | JPI1: 锅炉工段生产计划 | JPY1: 锅炉工段生产计划 | JQO1: 锅炉工段生产计划 | JRE1: 锅炉工段生产计划 | JRU1: 锅炉工段生产计划 | JSK1: 锅炉工段生产计划 | JTA1: 锅炉工段生产计划 | JTQ1: 锅炉工段生产计划 | JUG1: 锅炉工段生产计划 | JUW1: 锅炉工段生产计划 | JVM1: 锅炉工段生产计划 | JWC1: 锅炉工段生产计划 | JWS1: 锅炉工段生产计划 | JXI1: 锅炉工段生产计划 | JXY1: 锅炉工段生产计划 | JYO1: 锅炉工段生产计划 | JZE1: 锅炉工段生产计划 | JZU1: 锅炉工段生产计划 | KAK1: 锅炉工段生产计划 | KBA1: 锅炉工段生产计划 | KBQ1: 锅炉工段生产计划 | KCG1: 锅炉工段生产计划 | KCW1: 锅炉工段生产计划 | KDM1: 锅炉工段生产计划 | KEC1: 锅炉工段生产计划 | KES1: 锅炉工段生产计划 | KFI1: 锅炉工段生产计划 | KFY1: 锅炉工段生产计划 | KGO1: 锅炉工段生产计划 | KHE1: 锅炉工段生产计划 | KHU1: 锅炉工段生产计划 | KIK1: 锅炉工段生产计划 | KJA1: 锅炉工段生产计划 | KJQ1: 锅炉工段生产计划 | KKG1: 锅炉工段生产计划 | KKW1: 锅炉工段生产计划 | KLM1: 锅炉工段生产计划 | KMC1: 锅炉工段生产计划 | KMS1: 锅炉工段生产计划 | KNI1: 锅炉工段生产计划 | KNY1: 锅炉工段生产计划 | KOO1: 锅炉工段生产计划 | KPE1: 锅炉工段生产计划 | KPU1: 锅炉工段生产计划 | KQK1: 锅炉工段生产计划 | KRA1: 锅炉工段生产计划 | KRQ1: 锅炉工段生产计划 | KSG1: 锅炉工段生产计划 | KSW1: 锅炉工段生产计划 | KTM1: 锅炉工段生产计划 | KUC1: 锅炉工段生产计划 | KUS1: 锅炉工段生产计划 | KVI1: 锅炉工段生产计划 | KVY1: 锅炉工段生产计划 | KWO1: 锅炉工段生产计划 | KXE1: 锅炉工段生产计划 | KXU1: 锅炉工段生产计划 | KYK1: 锅炉工段生产计划 | KZA1: 锅炉工段生产计划 | KZQ1: 锅炉工段生产计划 | LAG1: 锅炉工段生产计划 | LAW1: 锅炉工段生产计划 | LBM1: 锅炉工段生产计划 | LCC1: 锅炉工段生产计划 | LCS1: 锅炉工段生产计划 | LDI1: 锅炉工段生产计划 | LDY1: 锅炉工段生产计划 | LEO1: 锅炉工段生产计划 | LFE1: 锅炉工段生产计划 | LFU1: 锅炉工段生产计划 | LGK1: 锅炉工段生产计划 | LHA1: 锅炉工段生产计划 | LHQ1: 锅炉工段生产计划 | LIG1: 锅炉工段生产计划 | LIW1: 锅炉工段生产计划 | LJM1: 锅炉工段生产计划 | LKC1: 锅炉工段生产计划 | LKS1: 锅炉工段生产计划 | LLI1: 锅炉工段生产计划 | LLY1: 锅炉工段生产计划 | LMO1: 锅炉工段生产计划 | LNE1: 锅炉工段生产计划 | LNU1: 锅炉工段生产计划 | LOK1: 锅炉工段生产计划 | LPA1: 锅炉工段生产计划 | LPQ1: 锅炉工段生产计划 | LQG1: 锅炉工段生产计划 | LQW1: 锅炉工段生产计划 | LRM1: 锅炉工段生产计划 | LSC1: 锅炉工段生产计划 | LSS1: 锅炉工段生产计划 | LTI1: 锅炉工段生产计划 | LTY1: 锅炉工段生产计划 | LUO1: 锅炉工段生产计划 | LVE1: 锅炉工段生产计划 | LVU1: 锅炉工段生产计划 | LWK1: 锅炉工段生产计划 | LXA1: 锅炉工段生产计划 | LXQ1: 锅炉工段生产计划 | LYG1: 锅炉工段生产计划 | LYW1: 锅炉工段生产计划 | LZM1: 锅炉工段生产计划 | MAC1: 锅炉工段生产计划 | MAS1: 锅炉工段生产计划 | MBI1: 锅炉工段生产计划 | MBY1: 锅炉工段生产计划 | MCO1: 锅炉工段生产计划 | MDE1: 锅炉工段生产计划 | MDU1: 锅炉工段生产计划 | MEK1: 锅炉工段生产计划 | MFA1: 锅炉工段生产计划 | MFQ1: 锅炉工段生产计划 | MGG1: 锅炉工段生产计划 | MGW1: 锅炉工段生产计划 | MHM1: 锅炉工段生产计划 | MIC1: 锅炉工段生产计划 | MIS1: 锅炉工段生产计划 | MJI1: 锅炉工段生产计划 | MJY1: 锅炉工段生产计划 | MKO1: 锅炉工段生产计划 | MLE1: 锅炉工段生产计划 | MLU1: 锅炉工段生产计划 | MMK1: 锅炉工段生产计划 | MNA1: 锅炉工段生产计划 | MNQ1: 锅炉工段生产计划 | MOG1: 锅炉工段生产计划 | MOW1: 锅炉工段生产计划 | MPM1: 锅炉工段生产计划 | MQC1: 锅炉工段生产计划 | MQS1: 锅炉工段生产计划 | MRI1: 锅炉工段生产计划 | MRY1: 锅炉工段生产计划 | MSO1: 锅炉工段生产计划 | MTE1: 锅炉工段生产计划 | MTU1: 锅炉工段生产计划 | MUK1: 锅炉工段生产计划 | MVA1: 锅炉工段生产计划 | MVQ1: 锅炉工段生产计划 | MWG1: 锅炉工段生产计划 | MWW1: 锅炉工段生产计划 | MXM1: 锅炉工段生产计划 | MYC1: 锅炉工段生产计划 | MYS1: 锅炉工段生产计划 | MZI1: 锅炉工段生产计划 | MZY1: 锅炉工段生产计划 | NAO1: 锅炉工段生产计划 | NBE1: 锅炉工段生产计划 | NBU1: 锅炉工段生产计划 | NCK1: 锅炉工段生产计划 | NDA1: 锅炉工段生产计划 | NDQ1: 锅炉工段生产计划 | NEG1: 锅炉工段生产计划 | NEW1: 锅炉工段生产计划 | NFM1: 锅炉工段生产计划 | NGC1: 锅炉工段生产计划 | NGS1: 锅炉工段生产计划 | NHI1: 锅炉工段生产计划 | NHY1: 锅炉工段生产计划 | NIO1: 锅炉工段生产计划 | NJE1: 锅炉工段生产计划 | NJU1: 锅炉工段生产计划 | NKK1: 锅炉工段生产计划 | NLA1: 锅炉工段生产计划 | NLQ1: 锅炉工段生产计划 | NMG1: 锅炉工段生产计划 | NMW1: 锅炉工段生产计划 | NNM1: 锅炉工段生产计划 | NOC1: 锅炉工段生产计划 | NOS1: 锅炉工段生产计划 | NPI1: 锅炉工段生产计划 | NPY1: 锅炉工段生产计划 | NQO1: 锅炉工段生产计划 | NRE1: 锅炉工段生产计划 | NRU1: 锅炉工段生产计划 | NSK1: 锅炉工段生产计划 | NTA1: 锅炉工段生产计划 | NTQ1: 锅炉工段生产计划 | NUG1: 锅炉工段生产计划 | NUW1: 锅炉工段生产计划 | NVM1: 锅炉工段生产计划 | NWC1: 锅炉工段生产计划 | NWS1: 锅炉工段生产计划 | NXI1: 锅炉工段生产计划 | NXY1: 锅炉工段生产计划 | NYO1: 锅炉工段生产计划 | NZE1: 锅炉工段生产计划 | NZU1: 锅炉工段生产计划 | OAK1: 锅炉工段生产计划 | OBA1: 锅炉工段生产计划 | OBQ1: 锅炉工段生产计划 | OCG1: 锅炉工段生产计划 | OCW1: 锅炉工段生产计划 | ODM1: 锅炉工段生产计划 | OEC1: 锅炉工段生产计划 | OES1: 锅炉工段生产计划 | OFI1: 锅炉工段生产计划 | OFY1: 锅炉工段生产计划 | OGO1: 锅炉工段生产计划 | OHE1: 锅炉工段生产计划 | OHU1: 锅炉工段生产计划 | OIK1: 锅炉工段生产计划 | OJA1: 锅炉工段生产计划 | OJQ1: 锅炉工段生产计划 | OKG1: 锅炉工段生产计划 | OKW1: 锅炉工段生产计划 | OLM1: 锅炉工段生产计划 | OMC1: 锅炉工段生产计划 | OMS1: 锅炉工段生产计划 | ONI1: 锅炉工段生产计划 | ONY1: 锅炉工段生产计划 | OOO1: 锅炉工段生产计划 | OPE1: 锅炉工段生产计划 | OPU1: 锅炉工段生产计划 | OQK1: 锅炉工段生产计划 | ORA1: 锅炉工段生产计划 | ORQ1: 锅炉工段生产计划 | OSG1: 锅炉工段生产计划 | OSW1: 锅炉工段生产计划 | OTM1: 锅炉工段生产计划 | OUC1: 锅炉工段生产计划 | OUS1: 锅炉工段生产计划 | OVI1: 锅炉工段生产计划 | OVY1: 锅炉工段生产计划 | OWO1: 锅炉工段生产计划 | OXE1: 锅炉工段生产计划 | OXU1: 锅炉工段生产计划 | OYK1: 锅炉工段生产计划 | OZA1: 锅炉工段生产计划 | OZQ1: 锅炉工段生产计划 | PAG1: 锅炉工段生产计划 | PAW1: 锅炉工段生产计划 | PBM1: 锅炉工段生产计划 | PCC1: 锅炉工段生产计划 | PCS1: 锅炉工段生产计划 | PDI1: 锅炉工段生产计划 | PDY1: 锅炉工段生产计划 | PEO1: 锅炉工段生产计划 | PFE1: 锅炉工段生产计划 | PFU1: 锅炉工段生产计划 | PGK1: 锅炉工段生产计划 | PHA1: 锅炉工段生产计划 | PHQ1: 锅炉工段生产计划 | PIG1: 锅炉工段生产计划 | PIW1: 锅炉工段生产计划 | PJM1: 锅炉工段生产计划 | PKC1: 锅炉工段生产计划 | PKS1: 锅炉工段生产计划 | PLI1: 锅炉工段生产计划 | PLY1: 锅炉工段生产计划 | PMO1: 锅炉工段生产计划 | PNE1: 锅炉工段生产计划 | PNU1: 锅炉工段生产计划 | POK1: 锅炉工段生产计划 | PPA1: 锅炉工段生产计划 | PPQ1: 锅炉工段生产计划 | PQG1: 锅炉工段生产计划 | PQW1: 锅炉工段生产计划 | PRM1: 锅炉工段生产计划 | PSC1: 锅炉工段生产计划 | PSS1: 锅炉工段生产计划 | PTI1: 锅炉工段生产计划 | PTY1: 锅炉工段生产计划 | PUO1: 锅炉工段生产计划 | PVE1: 锅炉工段生产计划 | PVU1: 锅炉工段生产计划 | PWK1: 锅炉工段生产计划 | PXA1: 锅炉工段生产计划 | PXQ1: 锅炉工段生产计划 | PYG1: 锅炉工段生产计划 | PYW1: 锅炉工段生产计划 | PZM1: 锅炉工段生产计划 | QAC1: 锅炉工段生产计划 | QAS1: 锅炉工段生产计划 | QBI1: 锅炉工段生产计划 | QBY1: 锅炉工段生产计划 | QCO1: 锅炉工段生产计划 | QDE1: 锅炉工段生产计划 | QDU1: 锅炉工段生产计划 | QEK1: 锅炉工段生产计划 | QFA1: 锅炉工段生产计划 | QFQ1: 锅炉工段生产计划 | QGG1: 锅炉工段生产计划 | QGW1: 锅炉工段生产计划 | QHM1: 锅炉工段生产计划 | QIC1: 锅炉工段生产计划 | QIS1: 锅炉工段生产计划 | QJI1: 锅炉工段生产计划 | QJY1: 锅炉工段生产计划 | QKO1: 锅炉工段生产计划 | QLE1: 锅炉工段生产计划 | QLU1: 锅炉工段生产计划 | QMK1: 锅炉工段生产计划 | QNA1: 锅炉工段生产计划 | QNQ1: 锅炉工段生产计划 | QOG1: 锅炉工段生产计划 | QOW1: 锅炉工段生产计划 | QPM1: 锅炉工段生产计划 | QQC1: 锅炉工段生产计划 | QQS1: 锅炉工段生产计划 | QRI1: 锅炉工段生产计划 | QRY1: 锅炉工段生产计划 | QSO1: 锅炉工段生产计划 | QTE1: 锅炉工段生产计划 | QTU1: 锅炉工段生产计划 | QUK1: 锅炉工段生产计划 | QVA1: 锅炉工段生产计划 | QVQ1: 锅炉工段生产计划 | QWG1: 锅炉工段生产计划 | QWW1: 锅炉工段生产计划 | QXM1: 锅炉工段生产计划 | QYC1: 锅炉工段生产计划 | QYS1: 锅炉工段生产计划 | QZI1: 锅炉工段生产计划 | QZY1: 锅炉工段生产计划 | RAO1: 锅炉工段生产计划 | RBE1: 锅炉工段生产计划 | RBU1: 锅炉工段生产计划 | RCK1: 锅炉工段生产计划 | RDA1: 锅炉工段生产计划 | RDQ1: 锅炉工段生产计划 | REG1: 锅炉工段生产计划 | REW1: 锅炉工段生产计划 | RFM1: 锅炉工段生产计划 | RGC1: 锅炉工段生产计划 | RGS1: 锅炉工段生产计划 | RHI1: 锅炉工段生产计划 | RHY1: 锅炉工段生产计划 | RIO1: 锅炉工段生产计划 | RJE1: 锅炉工段生产计划 | RJU1: 锅炉工段生产计划 | RKK1: 锅炉工段生产计划 | RLA1: 锅炉工段生产计划 | RLQ1: 锅炉工段生产计划 | RMG1: 锅炉工段生产计划 | RMW1: 锅炉工段生产计划 | RNM1: 锅炉工段生产计划 | ROC1: 锅炉工段生产计划 | ROS1: 锅炉工段生产计划 | RPI1: 锅炉工段生产计划 | RPY1: 锅炉工段生产计划 | RQO1: 锅炉工段生产计划 | RRE1: 锅炉工段生产计划 | RRU1: 锅炉工段生产计划 | RSK1: 锅炉工段生产计划 | RTA1: 锅炉工段生产计划 | RTQ1: 锅炉工段生产计划 | RUG1: 锅炉工段生产计划 | RUW1: 锅炉工段生产计划 | RVM1: 锅炉工段生产计划 | RWC1: 锅炉工段生产计划 | RWS1: 锅炉工段生产计划 | RXI1: 锅炉工段生产计划 | RXY1: 锅炉工段生产计划 | RYO1: 锅炉工段生产计划 | RZE1: 锅炉工段生产计划 | RZU1: 锅炉工段生产计划 | SAK1: 锅炉工段生产计划 | SBA1: 锅炉工段生产计划 | SBQ1: 锅炉工段生产计划 | SCG1: 锅炉工段生产计划 | SCW1: 锅炉工段生产计划 | SDM1: 锅炉工段生产计划 | SEC1: 锅炉工段生产计划 | SES1: 锅炉工段生产计划 | SFI1: 锅炉工段生产计划 | SFY1: 锅炉工段生产计划 | SGO1: 锅炉工段生产计划 | SHE1: 锅炉工段生产计划 | SHU1: 锅炉工段生产计划 | SIK1: 锅炉工段生产计划 | SJA1: 锅炉工段生产计划 | SJQ1: 锅炉工段生产计划 | SKG1: 锅炉工段生产计划 | SKW1: 锅炉工段生产计划 | SLM1: 锅炉工段生产计划 | SMC1: 锅炉工段生产计划 | SMS1: 锅炉工段生产计划 | SNI1: 锅炉工段生产计划 | SNY1: 锅炉工段生产计划 | SOO1: 锅炉工段生产计划 | SPE1: 锅炉工段生产计划 | SPU1: 锅炉工段生产计划 | SQK1: 锅炉工段生产计划 | SRA1: 锅炉工段生产计划 | SRQ1: 锅炉工段生产计划 | SSG1: 锅炉工段生产计划 | SSW1: 锅炉工段生产计划 | STM1: 锅炉工段生产计划 | SUC1: 锅炉工段生产计划 | SUS1: 锅炉工段生产计划 | SVI1: 锅炉工段生产计划 | SVY1: 锅炉工段生产计划 | SWO1: 锅炉工段生产计划 | SXE1: 锅炉工段生产计划 | SXU1: 锅炉工段生产计划 | SYK1: 锅炉工段生产计划 | SZA1: 锅炉工段生产计划 | SZQ1: 锅炉工段生产计划 | TAG1: 锅炉工段生产计划 | TAW1: 锅炉工段生产计划 | TBM1: 锅炉工段生产计划 | TCC1: 锅炉工段生产计划 | TCS1: 锅炉工段生产计划 | TDI1: 锅炉工段生产计划 | TDY1: 锅炉工段生产计划 | TEO1: 锅炉工段生产计划 | TFE1: 锅炉工段生产计划 | TFU1: 锅炉工段生产计划 | TGK1: 锅炉工段生产计划 | THA1: 锅炉工段生产计划 | THQ1: 锅炉工段生产计划 | TIG1: 锅炉工段生产计划 | TIW1: 锅炉工段生产计划 | TJM1: 锅炉工段生产计划 | TKC1: 锅炉工段生产计划 | TKS1: 锅炉工段生产计划 | TLI1: 锅炉工段生产计划 | TLY1: 锅炉工段生产计划 | TMO1: 锅炉工段生产计划 | TNE1: 锅炉工段生产计划 | TNU1: 锅炉工段生产计划 | TOK1: 锅炉工段生产计划 | TPA1: 锅炉工段生产计划 | TPQ1: 锅炉工段生产计划 | TQG1: 锅炉工段生产计划 | TQW1: 锅炉工段生产计划 | TRM1: 锅炉工段生产计划 | TSC1: 锅炉工段生产计划 | TSS1: 锅炉工段生产计划 | TTI1: 锅炉工段生产计划 | TTY1: 锅炉工段生产计划 | TUO1: 锅炉工段生产计划 | TVE1: 锅炉工段生产计划 | TVU1: 锅炉工段生产计划 | TWK1: 锅炉工段生产计划 | TXA1: 锅炉工段生产计划 | TXQ1: 锅炉工段生产计划 | TYG1: 锅炉工段生产计划 | TYW1: 锅炉工段生产计划 | TZM1: 锅炉工段生产计划 | UAC1: 锅炉工段生产计划 | UAS1: 锅炉工段生产计划 | UBI1: 锅炉工段生产计划 | UBY1: 锅炉工段生产计划 | UCO1: 锅炉工段生产计划 | UDE1: 锅炉工段生产计划 | UDU1: 锅炉工段生产计划 | UEK1: 锅炉工段生产计划 | UFA1: 锅炉工段生产计划 | UFQ1: 锅炉工段生产计划 | UGG1: 锅炉工段生产计划 | UGW1: 锅炉工段生产计划 | UHM1: 锅炉工段生产计划 | UIC1: 锅炉工段生产计划 | UIS1: 锅炉工段生产计划 | UJI1: 锅炉工段生产计划 | UJY1: 锅炉工段生产计划 | UKO1: 锅炉工段生产计划 | ULE1: 锅炉工段生产计划 | ULU1: 锅炉工段生产计划 | UMK1: 锅炉工段生产计划 | UNA1: 锅炉工段生产计划 | UNQ1: 锅炉工段生产计划 | UOG1: 锅炉工段生产计划 | UOW1: 锅炉工段生产计划 | UPM1: 锅炉工段生产计划 | UQC1: 锅炉工段生产计划 | UQS1: 锅炉工段生产计划 | URI1: 锅炉工段生产计划 | URY1: 锅炉工段生产计划 | USO1: 锅炉工段生产计划 | UTE1: 锅炉工段生产计划 | UTU1: 锅炉工段生产计划 | UUK1: 锅炉工段生产计划 | UVA1: 锅炉工段生产计划 | UVQ1: 锅炉工段生产计划 | UWG1: 锅炉工段生产计划 | UWW1: 锅炉工段生产计划 | UXM1: 锅炉工段生产计划 | UYC1: 锅炉工段生产计划 | UYS1: 锅炉工段生产计划 | UZI1: 锅炉工段生产计划 | UZY1: 锅炉工段生产计划 | VAO1: 锅炉工段生产计划 | VBE1: 锅炉工段生产计划 | VBU1: 锅炉工段生产计划 | VCK1: 锅炉工段生产计划 | VDA1: 锅炉工段生产计划 | VDQ1: 锅炉工段生产计划 | VEG1: 锅炉工段生产计划 | VEW1: 锅炉工段生产计划 | VFM1: 锅炉工段生产计划 | VGC1: 锅炉工段生产计划 | VGS1: 锅炉工段生产计划 | VHI1: 锅炉工段生产计划 | VHY1: 锅炉工段生产计划 | VIO1: 锅炉工段生产计划 | VJE1: 锅炉工段生产计划 | VJU1: 锅炉工段生产计划 | VKK1: 锅炉工段生产计划 | VLA1: 锅炉工段生产计划 | VLQ1: 锅炉工段生产计划 | VMG1: 锅炉工段生产计划 | VMW1: 锅炉工段生产计划 | VNM1: 锅炉工段生产计划 | VOC1: 锅炉工段生产计划 | VOS1: 锅炉工段生产计划 | VPI1: 锅炉工段生产计划 | VPY1: 锅炉工段生产计划 | VQO1: 锅炉工段生产计划 | VRE1: 锅炉工段生产计划 | VRU1: 锅炉工段生产计划 | VSK1: 锅炉工段生产计划 | VTA1: 锅炉工段生产计划 | VTQ1: 锅炉工段生产计划 | VUG1: 锅炉工段生产计划 | VUW1: 锅炉工段生产计划 | VVM1: 锅炉工段生产计划 | VWC1: 锅炉工段生产计划 | VWS1: 锅炉工段生产计划 | VXI1: 锅炉工段生产计划 | VXY1: 锅炉工段生产计划 | VYO1: 锅炉工段生产计划 | VZE1: 锅炉工段生产计划 | VZU1: 锅炉工段生产计划 | WAK1: 锅炉工段生产计划 | WBA1: 锅炉工段生产计划 | WBQ1: 锅炉工段生产计划 | WCG1: 锅炉工段生产计划 | WCW1: 锅炉工段生产计划 | WDM1: 锅炉工段生产计划 | WEC1: 锅炉工段生产计划 | WES1: 锅炉工段生产计划 | WFI1: 锅炉工段生产计划 | WFY1: 锅炉工段生产计划 | WGO1: 锅炉工段生产计划 | WHE1: 锅炉工段生产计划 | WHU1: 锅炉工段生产计划 | WIK1: 锅炉工段生产计划 | WJA1: 锅炉工段生产计划 | WJQ1: 锅炉工段生产计划 | WKG1: 锅炉工段生产计划 | WKW1: 锅炉工段生产计划 | WLM1: 锅炉工段生产计划 | WMC1: 锅炉工段生产计划 | WMS1: 锅炉工段生产计划 | WNI1: 锅炉工段生产计划 | WNY1: 锅炉工段生产计划 | WOO1: 锅炉工段生产计划 | WPE1: 锅炉工段生产计划 | WPU1: 锅炉工段生产计划 | WQK1: 锅炉工段生产计划 | WRA1: 锅炉工段生产计划 | WRQ1: 锅炉工段生产计划 | WSG1: 锅炉工段生产计划 | WSW1: 锅炉工段生产计划 | WTM1: 锅炉工段生产计划 | WUC1: 锅炉工段生产计划 | WUS1: 锅炉工段生产计划 | WVI1: 锅炉工段生产计划 | WVY1: 锅炉工段生产计划 | WWO1: 锅炉工段生产计划 | WXE1: 锅炉工段生产计划 | WXU1: 锅炉工段生产计划 | WYK1: 锅炉工段生产计划 | WZA1: 锅炉工段生产计划 | WZQ1: 锅炉工段生产计划 | XAG1: 锅炉工段生产计划 | XAW1: 锅炉工段生产计划 | XBM1: 锅炉工段生产计划 | XCC1: 锅炉工段生产计划 | XCS1: 锅炉工段生产计划 | XDI1: 锅炉工段生产计划 | XDY1: 锅炉工段生产计划 | XEO1: 锅炉工段生产计划
