Workbook
Name mth: 目录!$C$1

Sheet 目录
C1: 8
A2: =CONCATENATE("综合成本表(2025年"&mth&"月)") -> 综合成本表(2025年8月)
A3: 公司名称：融氏公司
A4: 序 号 | B4: 报表名称 | C4: 备 注
A5: 1 | B5: 编制说明
A6: 2 | B6: 与账面对比
A7: 3 | B7: 分销
A8: 4 | B8: 所有装置汇总-含税
A9: 5 | B9: 果糖装置汇总-含税
A10: 6 | B10: 麦芽糖浆-含税
A11: 7 | B11: F55-含税
A12: 8 | B12: F55OEM-含税
A13: 9 | B13: F42-含税
A14: 10 | B14: F60-含税
A15: 11 | B15: 成本分配表
A16: 12 | B16: 基础表
A17: 13 | B17: 销售收入与运费表

Sheet 说明
B2: 编制说明：
B3: 表格 | C3: 项目 | D3: 说明
B4: 基础表： | C4: 产量 | D4: 包括商品量绝干量，绝干比例
C5: 淀粉 | D5: 只录入自投部分淀粉消耗量、消耗成本；还需录入淀粉水分，以折算折成13个水的淀粉消耗量、单位成本
C6: 辅料 | D6: 存在联产产品的，如果F42/葡萄糖浆的消耗是定额的，则需要录入定额消耗，如果全部按照绝干比例分配的，则不需要录入
D7: 树脂没有消耗，但有成本，衡水需要将计入在建的成本分摊
C8: 动力能源
C9: 蒸汽
C10: 电
C11: 水
C12: 天然气
C13: 污水
C14: 固定成本：
C15: 折旧 | D15: 需要分车间、管理费用、销售费用
C16: 人工 | D16: 需要分车间、管理费用、销售费用，需要含外包劳务，但不含装卸运输费的劳务
C17: 制造费用 | D17: 录入总制造费用，减去人工、折旧，如果有外包劳务，需要录入并减去，但装卸费、运输费的劳务不减去。
C18: 管理费用 | D18: 录入总管理费用，减去人工、折旧、保安保洁的劳务
C19: 销售费用 | D19: 录入总制造费用，减去人工、折旧、运输费
C20: 财务费用 | D20: 包含利息、手续费支出，汇兑损益在其他项目中
C21: 其他 | D21: 包含营业外收支（不含大额补贴）、汇兑损益、营业税金及附加
B22: 分配表： | C22: 原料、辅料、动力能源 | D22: 对于有消耗数量、消耗成本的，分配表只分配数量，展现表成本用单价*数量计算得出 只有消耗成本的，如污水、固定成本，
D23: 辅料消耗，如果F42采用定额，则F42的辅料消耗量需要在基础表中录入， 如果F42辅料消耗量按照绝干量分配，则不需要录入，各企业需要特别注意。
C24: 污水、树脂及固定成本 | D24: 分配表直接分配成本
D25: 目前为按照绝干产量分配，也可以按照产值分配。
D26: 其他固定成本只分配给果葡糖浆正常产品
B27: 展现表 | C27: 分产品表： | D27: 收入与运费：从销售收入与运费表中取数。销售收入、运输费总额为单吨运费*产量，总数与账面运费由差异
D28: 原辅料、动力能源：从分配表中取单价、总消耗；单耗为总消耗除以总产量；F42表直接取F55的单价；
D29: 原辅料、动力能源的总成本、收入为单价、单位成本与产量的乘积
D30: 各项固定成本、辅料中的树脂总成本直接从分配表取数，单位成本为总成本除以总产量
C31: 汇总表： | D31: 汇总F55、F55(OEM)、F42；总产量统一折成77%干物；
D32: 汇总表的总成本、总消耗为各分产品的总成本、总消耗之和；各项单耗为总消耗除以总产量
D33: 由于F55（OEM）各项消耗没有分开列示，故汇总表辅料、动力能源从分配表中取数。
D34: 淀粉消耗量只包括F55、F42消耗量，故汇总表的单耗偏低。
C35: 不含税表与含税表 | D35: 含税表从不含税表中取数，涉及价格的乘以税率，不涉及价格的直接取数
D36: 含税表中的增值税为测算税额，部分不重要项目增值税税率不必与实际税率完全一致

Sheet 装置汇总
A1: =CONCATENATE("汇总综合成本利润表_不含税(2025年"&mth&"月)") -> 汇总综合成本利润表_不含税(2025年8月) | I1: =CONCATENATE("汇总综合成本利润表_不含税(2025年1-"&mth&"月)") -> 汇总综合成本利润表_不含税(2025年1-8月)
A3: 全部产品 | E3: 本月产量： | F3: =OFFSET(基础表!C30,0,mth-1,1,1)/0.77 -> 0 | G3: 吨 | M3: 本年产量： | N3: =基础表!O30/0.77 -> 97033.583 | O3: 吨
B4: 单位 | C4: 单价 | D4: 单耗 | E4: 单位成本 | F4: 总耗量 | G4: 总成本 | J4: 单位 | K4: 单价 | L4: 单耗 | M4: 单位成本 | N4: 总耗量 | O4: 总成本
A5: 一、收入 | E5: =E6-E7 -> 0 | G5: =G6-G7 -> #DIV/0! | I5: 一、收入 | M5: =M6-M7 -> 2872.7247 | O5: =O6-O7 -> 2.7875077e+08
A6: （一）销售价格 | E6: =IF(F$3=0,0,G6/F$3) -> 0 | G6: =专用糖!G6+'F55'!G6+'F42'!G6+'F60'!G6+风味糖!G6+调味糖!G6+'F90'!G6 -> 0 | I6: （一）销售价格 | M6: =IF($N$3=0,,O6/$N$3) -> 3002.6793 | O6: =专用糖!O6+'F55'!O6+'F42'!O6+'F60'!O6+风味糖!O6+调味糖!O6+'F90'!O6 -> 2.9136073e+08
A7: （二）物流费 | E7: =IF($F$3=0,,G7/$F$3) -> 0 | G7: =专用糖!G7+'F55'!G7+'F42'!G7+'F60'!G7+风味糖!G7+调味糖!G7+'F90'!G7 -> #DIV/0! | I7: （二）物流费 | M7: =IF($N$3=0,,O7/$N$3) -> 129.95458 | O7: =专用糖!O7+'F55'!O7+'F42'!O7+'F60'!O7+风味糖!O7+调味糖!O7+'F90'!O7 -> 12609958
A8: 1、运费 | E8: =IF($F$3=0,,G8/$F$3) -> 0 | G8: =专用糖!G8+'F55'!G8+'F42'!G8+'F60'!G8+风味糖!G8+调味糖!G8+'F90'!G8 -> #DIV/0! | I8: 1、运费 | M8: =IF($N$3=0,,O8/$N$3) -> 65.61797 | O8: =专用糖!O8+'F55'!O8+'F42'!O8+'F60'!O8+风味糖!O8+调味糖!O8+'F90'!O8 -> 6367146.8
A9: 2、包装费、租赁费等 | E9: =IF($F$3=0,,G9/$F$3) -> 0 | G9: =专用糖!G9+'F55'!G9+'F42'!G9+'F60'!G9+风味糖!G9+调味糖!G9+'F90'!G9 -> #DIV/0! | I9: 2、包装费、租赁费等 | M9: =IF($N$3=0,,O9/$N$3) -> 64.336607 | O9: =专用糖!O9+'F55'!O9+'F42'!O9+'F60'!O9+风味糖!O9+调味糖!O9+'F90'!O9 -> 6242811.5
A10: 二、变动成本 | E10: =E11+E14+E16+E21+E24+E15 -> #DIV/0! | G10: =G11+G14+G16+G21+G24+G15 -> #DIV/0! | I10: 二、变动成本 | M10: =M11+M14+M16+M21+M24+M15 -> #DIV/0! | O10: =O11+O14+O16+O21+O24+O15 -> #DIV/0!
A11: (一)淀粉 | B11: 吨 | C11: =C12 -> #DIV/0! | D11: =IF(C11=0,0,E11/C11) -> #DIV/0! | E11: =E12+E13 -> #DIV/0! | F11: =F12 -> 0 | G11: =G12+G13 -> 0 | I11: (一)淀粉 | J11: 吨 | K11: =IF(N11=0,0,O11/N11) -> 2512.1589 | L11: =L12 -> 0.84614503 | M11: =M12+M13 -> 2125.6507 | N11: =N12 -> 82104.484 | O11: =O12+O13 -> 2.0625951e+08
A12: 1、淀粉(14%) | B12: 吨 | C12: =E12/D12 -> #DIV/0! | D12: =IF(F3=0,,F12/F3) -> 0 | E12: =G12/F3 -> #DIV/0! | F12: =专用糖!F12+'F55'!F12+'F42'!F12+'F60'!F12+'F90'!F12 -> 0 | G12: =专用糖!G12+'F55'!G12+'F42'!G12+'F60'!G12+'F90'!G12 -> 0 | I12: 1、淀粉(14%) | J12: 吨 | K12: =M12/L12 -> 2498.9643 | L12: =IF(N3=0,,N12/N3) -> 0.84614503 | M12: =O12/N3 -> 2114.4862 | N12: =专用糖!N12+'F55'!N12+'F42'!N12+'F60'!N12+'F90'!N12 -> 82104.484 | O12: =专用糖!O12+'F55'!O12+'F42'!O12+'F60'!O12+'F90'!O12 -> 2.0517617e+08
A13: 2、淀粉糖 | E13: =G13/F3 -> #DIV/0! | G13: =调味糖!G11+风味糖!G11 -> 0 | I13: 2、淀粉糖 | M13: =O13/N3 -> 11.164507 | O13: =风味糖!O11+调味糖!O11 -> 1083332.1
A14: (二）辅料 | E14: =G14/F3 -> #DIV/0! | G14: =专用糖!G13+'F55'!G13+'F42'!G13+'F60'!G13+风味糖!G20+调味糖!G20+'F90'!G13 -> #DIV/0! | I14: (二）辅料 | M14: =O14/N3 -> #DIV/0! | O14: =专用糖!O13+'F55'!O13+'F42'!O13+'F60'!O13+风味糖!O20+调味糖!O20+'F90'!O13 -> #DIV/0!
A15: (三)包装物 | E15: =G15/F3 -> #DIV/0! | G15: =果糖汇总!G25+专用糖!G27+风味糖!G57 -> 0 | I15: (三)包装物 | M15: =O15/N3 -> 0 | O15: =果糖汇总!O25+专用糖!O27+风味糖!O57 -> 0
A16: (四)动力能源 | E16: =SUM(E17:E20) -> 0 | G16: =SUM(G17:G20) -> 0 | I16: (四)动力能源 | M16: =SUM(M17:M20) -> #DIV/0! | O16: =SUM(O17:O20) -> #DIV/0!
A17: 1、蒸汽 | B17: 吨 | C17: =IF(G17=0,0,G17/F17) -> 0 | D17: =IF($F$3=0,0,F17/$F$3) -> 0 | E17: =C17*D17 -> 0 | F17: =专用糖!F29+'F55'!F27+'F42'!F27+'F60'!F27+风味糖!F59+'F90'!F27+调味糖!F52 -> #DIV/0! | G17: =专用糖!G29+'F55'!G27+'F42'!G27+'F60'!G27+调味糖!G52+风味糖!G59+'F90'!G27 -> 0 | I17: 1、蒸汽 | J17: 吨 | K17: =IF(O17=0,0,O17/N17) -> #DIV/0! | L17: =IF($N$3=0,0,N17/$N$3) -> #DIV/0! | M17: =K17*L17 -> #DIV/0! | N17: =专用糖!N29+'F55'!N27+'F42'!N27+'F60'!N27+风味糖!N59+'F90'!N27 -> #DIV/0! | O17: =专用糖!O29+'F55'!O27+'F42'!O27+'F60'!O27+调味糖!O52+风味糖!O577+'F90'!O27 -> #DIV/0!
A18: 2、电 | B18: 度 | C18: =IF(G18=0,0,G18/F18) -> 0 | D18: =IF($F$3=0,0,F18/$F$3) -> 0 | E18: =C18*D18 -> 0 | F18: =专用糖!F30+'F55'!F28+'F42'!F28+'F60'!F28+风味糖!F60+'F90'!F28+调味糖!F53 -> #DIV/0! | G18: =专用糖!G30+'F55'!G28+'F42'!G28+'F60'!G28+调味糖!G53+风味糖!G60+'F90'!G28 -> 0 | I18: 2、电 | J18: 度 | K18: =IF(O18=0,0,O18/N18) -> #DIV/0! | L18: =IF($N$3=0,0,N18/$N$3) -> #DIV/0! | M18: =K18*L18 -> #DIV/0! | N18: =专用糖!N30+'F55'!N28+'F42'!N28+'F60'!N28+风味糖!N60+'F90'!N28+调味糖!N53 -> #DIV/0! | O18: =专用糖!O30+'F55'!O28+'F42'!O28+'F60'!O28+调味糖!O53+风味糖!O60+'F90'!O28 -> #DIV/0!
A19: 3、水 | B19: 吨 | C19: =IF(G19=0,0,G19/F19) -> 0 | D19: =IF($F$3=0,0,F19/$F$3) -> 0 | E19: =C19*D19 -> 0 | F19: =专用糖!F31+'F55'!F29+'F42'!F29+'F60'!F29+风味糖!F61+'F90'!F29+调味糖!F54 -> #DIV/0! | G19: =专用糖!G31+'F55'!G29+'F42'!G29+'F60'!G29+调味糖!G54+风味糖!G61+'F90'!G29 -> 0 | I19: 3、水 | J19: 吨 | K19: =IF(O19=0,0,O19/N19) -> #DIV/0! | L19: =IF($N$3=0,0,N19/$N$3) -> #DIV/0! | M19: =K19*L19 -> #DIV/0! | N19: =专用糖!N31+'F55'!N29+'F42'!N29+'F60'!N29+风味糖!N61+调味糖!N54+'F90'!N29 -> #DIV/0! | O19: =专用糖!O31+'F55'!O29+'F42'!O29+'F60'!O29+调味糖!O54+风味糖!O61+'F90'!O29 -> #DIV/0!
A20: 4、其他 | B20: M3 | I20: 4、其他 | J20: M3 | K20: =IF(O20=0,0,O20/N20) -> 0 | L20: =IF($N$3=0,0,N20/$N$3) -> 0 | M20: =K20*L20 -> 0 | N20: =专用糖!N32+'F55'!N30+'F42'!N30+'F60'!N30+'F90'!N30 -> 0 | O20: =专用糖!O32+'F55'!O30+'F42'!O30+'F60'!O30+'F90'!O30 -> 0
A21: (五)排污费 | E21: =IF(F$3=0,0,G21/F$3) -> 0 | G21: =专用糖!G33+'F55'!G31+'F42'!G31+'F60'!G31+调味糖!G56+风味糖!G63+'F90'!G31 -> #DIV/0! | I21: (五)排污费 | M21: =IF(N$3=0,0,O21/N$3) -> #DIV/0! | O21: =专用糖!O33+'F55'!O31+'F42'!O31+'F60'!O31+调味糖!O56+风味糖!O63+'F90'!O31 -> #DIV/0!
A22: 1.污水处理 | E22: =E21 -> 0 | G22: =G21 -> #DIV/0! | I22: 1.污水处理 | M22: =M21 -> #DIV/0! | O22: =O21 -> #DIV/0!
A23: 2.污水固定成本 | I23: 2.污水固定成本
A24: (六)增值税 | I24: (六)增值税
A25: 三、边际贡献 | E25: =E5-E10 -> #DIV/0! | G25: =G5-G10 -> #DIV/0! | I25: 三、边际贡献 | M25: =M5-M10 -> #DIV/0! | O25: =O5-O10 -> #DIV/0!
A26: 四、固定成本 | E26: =SUM(E27:E33) -> 0 | G26: =SUM(G27:G33) -> #DIV/0! | I26: 四、固定成本 | M26: =IF(N$3=0,0,O26/N$3) -> #DIV/0! | O26: =SUM(O27:O33) -> #DIV/0!
A27: （一）折旧与摊销 | E27: =IF(F$3=0,0,G27/F$3) -> 0 | G27: =专用糖!G39+'F55'!G37+'F42'!G37+'F60'!G37+调味糖!G62+风味糖!G69+'F90'!G37 -> #DIV/0! | I27: （一）折旧与摊销 | M27: =IF(N$3=0,0,O27/N$3) -> #DIV/0! | O27: =专用糖!O39+'F55'!O37+'F42'!O37+'F60'!O37+调味糖!O62+风味糖!O69+'F90'!O37 -> #DIV/0!
A28: （二）工资 | E28: =IF(F$3=0,0,G28/F$3) -> 0 | G28: =专用糖!G40+'F55'!G38+'F42'!G38+'F60'!G38+调味糖!G63+风味糖!G70+'F90'!G38 -> #DIV/0! | I28: （二）工资 | M28: =IF(N$3=0,0,O28/N$3) -> #DIV/0! | O28: =专用糖!O40+'F55'!O38+'F42'!O38+'F60'!O38+调味糖!O63+风味糖!O70+'F90'!O38 -> #DIV/0!
A29: （三）制造费用 | E29: =IF(F$3=0,0,G29/F$3) -> 0 | G29: =专用糖!G41+'F55'!G39+'F42'!G39+'F60'!G39+调味糖!G64+风味糖!G71+'F90'!G39 -> #DIV/0! | I29: （三）制造费用 | M29: =IF(N$3=0,0,O29/N$3) -> #DIV/0! | O29: =专用糖!O41+'F55'!O39+'F42'!O39+'F60'!O39+调味糖!O64+风味糖!O71+'F90'!O39 -> #DIV/0!
A30: （四）销售费用 | E30: =IF(F$3=0,0,G30/F$3) -> 0 | G30: =专用糖!G42+'F55'!G40+'F42'!G40+'F60'!G40+调味糖!G65+风味糖!G72+'F90'!G40 -> #DIV/0! | I30: （四）销售费用 | M30: =IF(N$3=0,0,O30/N$3) -> #DIV/0! | O30: =专用糖!O42+'F55'!O40+'F42'!O40+'F60'!O40+调味糖!O65+风味糖!O72+'F90'!O40 -> #DIV/0!
A31: （五）管理费用 | E31: =IF(F$3=0,0,G31/F$3) -> 0 | G31: =专用糖!G43+'F55'!G41+'F42'!G41+'F60'!G41+调味糖!G66+风味糖!G73+'F90'!G41 -> #DIV/0! | I31: （五）管理费用 | M31: =IF(N$3=0,0,O31/N$3) -> #DIV/0! | O31: =专用糖!O43+'F55'!O41+'F42'!O41+'F60'!O41+调味糖!O66+风味糖!O73+'F90'!O41 -> #DIV/0!
A32: （六）财务费用 | E32: =IF(F$3=0,0,G32/F$3) -> 0 | G32: =专用糖!G44+'F55'!G42+'F42'!G42+'F60'!G42+调味糖!G67+风味糖!G74+'F90'!G42 -> #DIV/0! | I32: （六）财务费用 | M32: =IF(N$3=0,0,O32/N$3) -> #DIV/0! | O32: =专用糖!O44+'F55'!O42+'F42'!O42+'F60'!O42+调味糖!O67+风味糖!O74+'F90'!O42 -> #DIV/0!
A33: （七）其他 | E33: =IF(F$3=0,0,G33/F$3) -> 0 | G33: =专用糖!G45+'F55'!G43+'F42'!G43+'F60'!G43+调味糖!G68+风味糖!G75+'F90'!G43 -> #DIV/0! | I33: （七） 其他 | M33: =IF(N$3=0,0,O33/N$3) -> #DIV/0! | O33: =专用糖!O45+'F55'!O43+'F42'!O43+'F60'!O43+调味糖!O68+风味糖!O75+'F90'!O43 -> #DIV/0!
A34: 其中：税金及附加 | E34: =IF(F$3=0,0,G34/F$3) -> 0 | G34: =果糖汇总!G44+专用糖!G46+调味糖!G69+风味糖!G76 -> #DIV/0! | I34: 其中：税金及附加 | M34: =IF(N$3=0,0,O34/N$3) -> #DIV/0! | O34: =果糖汇总!O44+专用糖!O46+调味糖!O69+风味糖!O76 -> #DIV/0!
A35: 其他业务收支 | E35: =IF(F$3=0,0,G35/F$3) -> 0 | G35: =果糖汇总!G45+专用糖!G47+调味糖!G70+风味糖!G77 -> #DIV/0! | I35: 其他业务收支 | M35: =IF(N$3=0,0,O35/N$3) -> #DIV/0! | O35: =果糖汇总!O45+专用糖!O47+调味糖!O70+风味糖!O77 -> #DIV/0!
A36: 营业外收支 | E36: =IF(F$3=0,0,G36/F$3) -> 0 | G36: =果糖汇总!G46+专用糖!G48+调味糖!G71+风味糖!G78 -> #DIV/0! | I36: 营业外收支 | M36: =IF(N$3=0,0,O36/N$3) -> #DIV/0! | O36: =果糖汇总!O46+专用糖!O48+调味糖!O71+风味糖!O78 -> #DIV/0!
A37: 投资收益+公允价值变动损益 | E37: =IF(F$3=0,0,G37/F$3) -> 0 | G37: =果糖汇总!G47+专用糖!G49+调味糖!G72+风味糖!G79 -> #DIV/0! | I37: 投资收益+公允价值变动损益 | M37: =IF(N$3=0,0,O37/N$3) -> #DIV/0! | O37: =果糖汇总!O47+专用糖!O49+调味糖!O72+风味糖!O79 -> #DIV/0!
A38: 其他收益 | E38: =IF(F$3=0,0,G38/F$3) -> 0 | G38: =果糖汇总!G48+专用糖!G50+调味糖!G73+风味糖!G80 -> #DIV/0! | I38: 其他收益 | M38: =IF(N$3=0,0,O38/N$3) -> #DIV/0! | O38: =果糖汇总!O48+专用糖!O50+调味糖!O73+风味糖!O80 -> #DIV/0!
A39: 资产减值损失 | E39: =IF(F$3=0,0,G39/F$3) -> 0 | G39: =果糖汇总!G49+专用糖!G51+调味糖!G74+风味糖!G81 -> #DIV/0! | I39: 资产减值损失 | M39: =IF(N$3=0,0,O39/N$3) -> #DIV/0! | O39: =果糖汇总!O49+专用糖!O51+调味糖!O74+风味糖!O81 -> #DIV/0!
A40: 其他 | E40: =IF(F$3=0,0,G40/F$3) -> 0 | G40: =果糖汇总!G50+专用糖!G52+调味糖!G75+风味糖!G82 -> #DIV/0! | I40: 其他 | M40: =IF(N$3=0,0,O40/N$3) -> #DIV/0! | O40: =果糖汇总!O50+专用糖!O52+调味糖!O75+风味糖!O82 -> #DIV/0!
A41: 五、完全成本 | B41: 元 | E41: =E10+E26 -> #DIV/0! | G41: =G10+G26 -> #DIV/0! | I41: 五、完全成本 | J41: 元 | M41: =M10+M26 -> #DIV/0! | O41: =O10+O26 -> #DIV/0!
...

Sheet 装置汇总-含税
A1: =CONCATENATE("汇总综合成本利润表_含税(2025年"&mth&"月)") -> 汇总综合成本利润表_含税(2025年8月) | I1: =CONCATENATE("汇总综合成本利润表_含税(2025年1-"&mth&"月)") -> 汇总综合成本利润表_含税(2025年1-8月)
E3: 本月折77固形物产量： | F3: =装置汇总!F3 -> 0 | G3: 吨 | M3: 本年折77固形物产量： | N3: =装置汇总!N3 -> 97033.583 | O3: 吨
B4: 单位 | C4: 单价 | D4: 单耗 | E4: 单位成本 | F4: 总耗量 | G4: 总成本 | J4: 单位 | K4: 单价 | L4: 单耗 | M4: 单位成本 | N4: 总耗量 | O4: 总成本
A5: 一、收入 | E5: =E6-E7 -> 0 | G5: =G6-G7 -> 0 | I5: 一、收入 | M5: =M6-M7 -> 3184.9767 | O5: =O6-O7 -> 3.090497e+08
A6: （一）销售价格 | E6: =IF(F$3=0,0,G6/F$3) -> 0 | G6: ='果糖汇总-含税'!G6+'专用糖-含税'!G6+'风味糖-含税'!G6+'调味糖-含税'!G6 -> 0 | I6: （一）销售价格 | M6: =IF($N$3=0,,O6/$N$3) -> 3317.406 | O6: ='果糖汇总-含税'!O6+'专用糖-含税'!O6+'风味糖-含税'!O6 -> 3.2189979e+08
A7: （二）物流费 | E7: =IF($F$3=0,,G7/$F$3) -> 0 | G7: ='果糖汇总-含税'!G7+'专用糖-含税'!G7+'风味糖-含税'!G7+'调味糖-含税'!G7 -> 0 | I7: （二）物流费 | M7: =IF($N$3=0,,O7/$N$3) -> 132.42929 | O7: ='果糖汇总-含税'!O7+'专用糖-含税'!O7+'风味糖-含税'!O7 -> 12850088
A8: 1、运费 | E8: =IF($F$3=0,,G8/$F$3) -> 0 | G8: ='果糖汇总-含税'!G8+'专用糖-含税'!G8+'风味糖-含税'!G8+'调味糖-含税'!G8 -> #DIV/0! | I8: 1、运费 | M8: =IF($N$3=0,,O8/$N$3) -> 69.461384 | O8: ='果糖汇总-含税'!O8+'专用糖-含税'!O8+'风味糖-含税'!O8 -> 6740086.9
A9: 2、包装费、租赁费等 | E9: =IF($F$3=0,,G9/$F$3) -> 0 | G9: ='果糖汇总-含税'!G9+'专用糖-含税'!G9+'风味糖-含税'!G9+'调味糖-含税'!G9 -> #DIV/0! | I9: 2、包装费、租赁费等 | M9: =IF($N$3=0,,O9/$N$3) -> 62.967902 | O9: ='果糖汇总-含税'!O9+'专用糖-含税'!O9+'风味糖-含税'!O9 -> 6110001.2
A10: 二、变动成本 | E10: =E11+E14+E16+E21+E24+E15 -> #DIV/0! | G10: =G11+G14+G16+G21+G24+G15 -> #DIV/0! | I10: 二、变动成本 | M10: =M11+M14+M16+M21+M24+M15 -> #DIV/0! | O10: =O11+O14+O16+O21+O24+O15 -> #DIV/0!
A11: (一)淀粉 | B11: 吨 | C11: =C12 -> #DIV/0! | D11: =D12 -> 0 | E11: =E12 -> #DIV/0! | F11: =F12 -> 0 | G11: =G12 -> 0 | I11: (一)淀粉 | J11: 吨 | K11: =IF(N11=0,0,O11/N11) -> 2823.8297 | L11: =IF(K11=0,0,M11/K11) -> 0.84614503 | M11: =M12 -> 2389.3694 | N11: =N12 -> 82104.484 | O11: =O12 -> 2.3184908e+08
A12: 1、淀粉(14%) | B12: 吨 | C12: =装置汇总!C12*1.13 -> #DIV/0! | D12: =装置汇总!D12 -> 0 | E12: =装置汇总!E12*1.13 -> #DIV/0! | F12: =装置汇总!F12 -> 0 | G12: =装置汇总!G12*1.13 -> 0 | I12: 1、淀粉(14%) | J12: 吨 | K12: =装置汇总!K12*1.13 -> 2823.8297 | L12: =装置汇总!L12 -> 0.84614503 | M12: =装置汇总!M12*1.13 -> 2389.3694 | N12: =装置汇总!N12 -> 82104.484 | O12: =装置汇总!O12*1.13 -> 2.3184908e+08
A13: 2、淀粉糖 | I13: 2、淀粉糖
A14: (二)辅助材料 | E14: =装置汇总!E14*1.13 -> #DIV/0! | G14: =装置汇总!G14*1.13 -> #DIV/0! | I14: (二)辅助材料 | M14: =装置汇总!M14*1.13 -> #DIV/0! | O14: =装置汇总!O14*1.13 -> #DIV/0!
A15: (三)包装物 | E15: =装置汇总!E15*1.13 -> #DIV/0! | G15: =装置汇总!G15*1.13 -> 0 | I15: (三)包装物 | M15: =装置汇总!M15*1.13 -> 0 | O15: =装置汇总!O15*1.13 -> 0
A16: (四)动力能源 | E16: =SUM(E17:E20) -> 0 | G16: =SUM(G17:G20) -> 0 | I16: (四)动力能源 | M16: =SUM(M17:M20) -> #DIV/0! | O16: =SUM(O17:O20) -> #DIV/0!
A17: 1、蒸汽 | B17: 吨 | C17: =IF(G17=0,0,G17/F17) -> 0 | D17: =装置汇总!D17 -> 0 | E17: =C17*D17 -> 0 | F17: =装置汇总!F17 -> #DIV/0! | G17: ='专用糖-含税'!G29+'F55-含税'!G27+'F42-含税'!G27+'F60-含税'!G27+'风味糖-含税'!G59+'F90-含税 '!G27+'调味糖-含税'!G51 -> 0 | I17: 1、蒸汽 | J17: 吨 | K17: =IF(O17=0,0,O17/N17) -> #DIV/0! | L17: =装置汇总!L17 -> #DIV/0! | M17: =K17*L17 -> #DIV/0! | N17: =装置汇总!N17 -> #DIV/0! | O17: ='专用糖-含税'!O29+'F55-含税'!O27+'F42-含税'!O27+'F60-含税'!O27+'风味糖-含税'!O59 -> #DIV/0!
A18: 2、电 | B18: 度 | C18: =IF(G18=0,0,G18/F18) -> 0 | D18: =装置汇总!D18 -> 0 | E18: =装置汇总!E18*1.13 -> 0 | F18: =装置汇总!F18 -> #DIV/0! | G18: =装置汇总!G18*1.13 -> 0 | I18: 2、电 | J18: 度 | K18: =IF(O18=0,0,O18/N18) -> #DIV/0! | L18: =装置汇总!L18 -> #DIV/0! | M18: =装置汇总!M18*1.13 -> #DIV/0! | N18: =装置汇总!N18 -> #DIV/0! | O18: =装置汇总!O18*1.13 -> #DIV/0!
A19: 3、水 | B19: 吨 | C19: =IF(G19=0,0,G19/F19) -> 0 | D19: =装置汇总!D19 -> 0 | E19: =D19*C19 -> 0 | F19: =装置汇总!F19 -> #DIV/0! | G19: ='果糖汇总-含税'!G29+'专用糖-含税'!G31+'风味糖-含税'!G61+'调味糖-含税'!G53 -> 0 | I19: 3、水 | J19: 吨 | K19: =IF(O19=0,0,O19/N19) -> #DIV/0! | L19: =装置汇总!L19 -> #DIV/0! | M19: =L19*K19 -> #DIV/0! | N19: =装置汇总!N19 -> #DIV/0! | O19: ='果糖汇总-含税'!O29+'专用糖-含税'!O31+'风味糖-含税'!O61 -> #DIV/0!
A20: 4、其他 | I20: 4、其他
A21: (五)排污费 | E21: =装置汇总!E21*1.13 -> 0 | G21: =装置汇总!G21*1.13 -> #DIV/0! | I21: (五)排污费 | M21: =装置汇总!M21*1.13 -> #DIV/0! | O21: =装置汇总!O21*1.13 -> #DIV/0!
A22: 1.污水处理 | E22: =E21 -> 0 | G22: =G21 -> #DIV/0! | I22: 1.污水处理 | M22: =M21 -> #DIV/0! | O22: =O21 -> #DIV/0!
A23: 2.污水固定成本 | I23: 2.污水固定成本
A24: (六)增值税 | E24: =SUM(E5,-E11,-E14,-E16,-E21)-SUM(装置汇总!E5,-装置汇总!E11,-装置汇总!E14,-装置汇总!E16,-装置汇总!E21) -> #DIV/0! | G24: =SUM(G5,-G11,-G14,-G16,-G21,-G15)-SUM(装置汇总!G5,-装置汇总!G11,-装置汇总!G14,-装置汇总!G16,-装置汇总!G21,-装置汇总!G15) -> #DIV/0! | I24: (六)增值税 | M24: =SUM(M5,-M11,-M14,-M16,-M21)-SUM(装置汇总!M5,-装置汇总!M11,-装置汇总!M14,-装置汇总!M16,-装置汇总!M21) -> #DIV/0! | O24: =SUM(O5,-O11,-O14,-O16,-O21,-O15)-SUM(装置汇总!O5,-装置汇总!O11,-装置汇总!O14,-装置汇总!O16,-装置汇总!O21,-装置汇总!O15) -> #DIV/0!
A25: 三、边际贡献 | E25: =E5-E10 -> #DIV/0! | G25: =G5-G10 -> #DIV/0! | I25: 三、边际贡献 | M25: =M5-M10 -> #DIV/0! | O25: =O5-O10 -> #DIV/0!
A26: 四、固定成本 | E26: =SUM(E27:E33) -> 0 | G26: =SUM(G27:G33) -> #DIV/0! | I26: 四、固定成本 | M26: =SUM(M27:M33) -> #DIV/0! | O26: =SUM(O27:O33) -> #DIV/0!
A27: （一）折旧与摊销 | E27: =IF(F$3=0,0,G27/F$3) -> 0 | G27: =装置汇总!G27 -> #DIV/0! | I27: （一）折旧与摊销 | M27: =IF(N$3=0,0,O27/N$3) -> #DIV/0! | O27: =装置汇总!O27 -> #DIV/0!
A28: （二）工资 | E28: =IF(F$3=0,0,G28/F$3) -> 0 | G28: =装置汇总!G28 -> #DIV/0! | I28: （二）工资 | M28: =IF(N$3=0,0,O28/N$3) -> #DIV/0! | O28: =装置汇总!O28 -> #DIV/0!
A29: （三）制造费用 | E29: =IF(F$3=0,0,G29/F$3) -> 0 | G29: =装置汇总!G29 -> #DIV/0! | I29: （三）制造费用 | M29: =IF(N$3=0,0,O29/N$3) -> #DIV/0! | O29: =装置汇总!O29 -> #DIV/0!
A30: （四）销售费用 | E30: =IF(F$3=0,0,G30/F$3) -> 0 | G30: =装置汇总!G30 -> #DIV/0! | I30: （四）销售费用 | M30: =IF(N$3=0,0,O30/N$3) -> #DIV/0! | O30: =装置汇总!O30 -> #DIV/0!
A31: （五）管理费用 | E31: =IF(F$3=0,0,G31/F$3) -> 0 | G31: =装置汇总!G31 -> #DIV/0! | I31: （五）管理费用 | M31: =IF(N$3=0,0,O31/N$3) -> #DIV/0! | O31: =装置汇总!O31 -> #DIV/0!
A32: （六）财务费用 | E32: =IF(F$3=0,0,G32/F$3) -> 0 | G32: =装置汇总!G32 -> #DIV/0! | I32: （六）财务费用 | M32: =IF(N$3=0,0,O32/N$3) -> #DIV/0! | O32: =装置汇总!O32 -> #DIV/0!
A33: （七）其他 | E33: =IF(F$3=0,0,G33/F$3) -> 0 | G33: =装置汇总!G33 -> #DIV/0! | I33: （七） 其他 | M33: =IF(N$3=0,0,O33/N$3) -> #DIV/0! | O33: =装置汇总!O33 -> #DIV/0!
A34: 其中：税金及附加 | E34: =IF(F$3=0,0,G34/F$3) -> 0 | G34: =装置汇总!G34 -> #DIV/0! | I34: 其中：税金及附加 | M34: =IF(N$3=0,0,O34/N$3) -> #DIV/0! | O34: =装置汇总!O34 -> #DIV/0!
A35: 其他业务收支 | E35: =IF(F$3=0,0,G35/F$3) -> 0 | G35: =装置汇总!G35 -> #DIV/0! | I35: 其他业务收支 | M35: =IF(N$3=0,0,O35/N$3) -> #DIV/0! | O35: =装置汇总!O35 -> #DIV/0!
A36: 营业外收支 | E36: =IF(F$3=0,0,G36/F$3) -> 0 | G36: =装置汇总!G36 -> #DIV/0! | I36: 营业外收支 | M36: =IF(N$3=0,0,O36/N$3) -> #DIV/0! | O36: =装置汇总!O36 -> #DIV/0!
A37: 投资收益+公允价值变动损益 | E37: =IF(F$3=0,0,G37/F$3) -> 0 | G37: =装置汇总!G37 -> #DIV/0! | I37: 投资收益+公允价值变动损益 | M37: =IF(N$3=0,0,O37/N$3) -> #DIV/0! | O37: =装置汇总!O37 -> #DIV/0!
A38: 其他收益 | E38: =IF(F$3=0,0,G38/F$3) -> 0 | G38: =装置汇总!G38 -> #DIV/0! | I38: 其他收益 | M38: =IF(N$3=0,0,O38/N$3) -> #DIV/0! | O38: =装置汇总!O38 -> #DIV/0!
... A40: 其他 | E40: =IF(F$3=0,0,G40/F$3) -> 0 | G40: =装置汇总!G40 -> #DIV/0! | I40: 其他 | M40: =IF(N$3=0,0,O40/N$3) -> #DIV/0! | O40: =装置汇总!O40 -> #DIV/0!
A41: 五、完全成本 | B41: 元 | E41: =E10+E26 -> #DIV/0! | G41: =G10+G26 -> #DIV/0! | I41: 五、完全成本 | J41: 元 | M41: =M10+M26 -> #DIV/0! | O41: =O10+O26 -> #DIV/0!
A42: 六、利润总额 | B42: 元 | E42: =E25-E26 -> #DIV/0! | G42: =G25-G26 -> #DIV/0! | I42: 六、利润总额 | J42: 元 | M42: =M25-M26 -> #DIV/0! | O42: =O25-O26 -> #DIV/0!
...

Sheet F60
A1: =CONCATENATE("果葡糖浆F60综合成本利润表_不含税(2025年"&mth&"月)") -> 果葡糖浆F60综合成本利润表_不含税(2025年8月) | I1: =CONCATENATE("果葡糖浆F60综合成本利润表_不含税(2025年1-"&mth&"月)") -> 果葡糖浆F60综合成本利润表_不含税(2025年1-8月)
A3: 产量 | E3: 本月产量 | F3: =OFFSET(基础表!C10,0,mth-1,1,1) -> 0 | G3: 吨 | M3: 本年产量 | N3: =基础表!O10 -> 6845.043 | O3: 吨
B4: 单位 | C4: 单价 | D4: 单耗 | E4: 单位成本 | F4: 总耗量 | G4: 总成本 | J4: 单位 | K4: 单价 | L4: 单耗 | M4: 单位成本 | N4: 总耗量 | O4: 总成本
A5: 一、收入 | E5: =E6-E7 -> #DIV/0! | G5: =G6-G7 -> #DIV/0! | I5: 一、收入 | M5: =M6-M7 -> 3131.9523 | O5: =O6-O7 -> 21438348
A6: （一）销售价格 | E6: =OFFSET(销售收入及运费!C71,0,mth-1,1,1) -> 0 | G6: =E6*$F$3 -> 0 | I6: （一）销售价格 | M6: =销售收入及运费!O71 -> 3852.7044 | O6: =M6*$N$3 -> 26371927
A7: （二）运费 | E7: =E8+E9 -> #DIV/0! | G7: =E7*$F$3 -> #DIV/0! | I7: （二）运费 | M7: =M8+M9 -> 720.75213 | O7: =M7*$N$3 -> 4933579.3
A8: 1、运费 | E8: =OFFSET(销售收入及运费!C128,0,mth-1,1,1)/1.09/OFFSET(销售收入及运费!C11,0,mth-1,1,1) -> #DIV/0! | G8: =E8*$F$3 -> #DIV/0! | I8: 1、运费 | M8: =销售收入及运费!O128/1.09/销售收入及运费!O11 -> 211.24352 | O8: =M8*$N$3 -> 1445971
A9: 2、包装费、租赁费等 | E9: =(OFFSET(销售收入及运费!C148,0,mth-1,1,1)/1.13+OFFSET(销售收入及运费!C168,0,mth-1,1,1)/1.13)/OFFSET(销售收入及运费!C11,0,mth-1,1,1) -> #DIV/0! | G9: =E9*$F$3 -> #DIV/0! | I9: 2、包装费、租赁费等 | M9: =(销售收入及运费!O148/1.13+销售收入及运费!O168/1.13)/销售收入及运费!O11 -> 509.50861 | O9: =M9*$N$3 -> 3487608.3
A10: 二、变动成本 | E10: =E11+E13+E26+E31+E25 -> 0 | G10: =G11+G13+G26+G31+G25 -> #DIV/0! | I10: 二、变动成本 | M10: =M11+M13+M26+M31+M25 -> #DIV/0! | O10: =O11+O13+O26+O31+O25 -> #DIV/0!
A11: (一)淀粉 | B11: 吨 | C11: =C12 -> 0 | D11: =IF(C11=0,0,E11/C11) -> 0 | E11: =E12 -> 0 | F11: =F12 -> 0 | G11: =G12 -> 0 | I11: (一)淀粉 | J11: 吨 | K11: =IF(N11=0,0,O11/N11) -> 2502.5327 | L11: =IF(K11=0,0,M11/K11) -> 0.82529689 | M11: =M12 -> 2065.3324 | N11: =N12 -> 5649.1927 | O11: =O12 -> 14137289
A12: 1、淀粉(14%) | B12: 吨 | C12: =OFFSET(分配表!C68,0,mth-1,1,1) -> 0 | D12: =IF(VALUE($F$3)=0,0,F12/$F$3) -> 0 | E12: =C12*D12 -> 0 | F12: =OFFSET(分配表!C82,0,mth-1,1,1) -> 0 | G12: =E12*F3 -> 0 | I12: 1、淀粉(14%) | J12: 吨 | K12: =分配表!O68 -> 2502.5327 | L12: =IF($N$3=0,0,N12/$N$3) -> 0.82529689 | M12: =K12*L12 -> 2065.3324 | N12: =分配表!O82 -> 5649.1927 | O12: =K12*N12 -> 14137289
A13: (二）辅料 | E13: =SUM(E14:E24) -> 0 | G13: =SUM(G14:G24) -> #DIV/0! | I13: (二）辅料 | M13: =SUM(M14:M24) -> #DIV/0! | O13: =SUM(O14:O24) -> #DIV/0!
A14: 盐酸(折百) | C14: ='F55'!C14 -> 0 | D14: =IF(VALUE($F$3)=0,0,F14/$F$3) -> 0 | E14: =C14*D14 -> 0 | F14: =OFFSET(分配表!C153,0,mth-1,1,1) -> 0 | G14: =E14*$F$3 -> 0 | I14: 盐酸(折百) | K14: ='F55'!K14 -> 1.0336348 | L14: =IF($N$3=0,0,N14/$N$3) -> 4.448574 | M14: =K14*L14 -> 4.5982007 | N14: =分配表!O153 -> 30450.68 | O14: =M14*$N$3 -> 31474.881
A15: 氢氧化钠(折百) | C15: ='F55'!C15 -> 0 | D15: =IF(VALUE($F$3)=0,0,F15/$F$3) -> 0 | E15: =C15*D15 -> 0 | F15: =OFFSET(分配表!C154,0,mth-1,1,1) -> 0 | G15: =E15*$F$3 -> 0 | I15: 氢氧化钠(折百) | K15: ='F55'!K15 -> 3.1653036 | L15: =IF($N$3=0,0,N15/$N$3) -> 4.9385811 | M15: =K15*L15 -> 15.632109 | N15: =分配表!O154 -> 33804.8 | O15: =M15*$N$3 -> 107002.46
A16: 硅藻土 | C16: ='F55'!C16 -> 0 | D16: =IF(VALUE($F$3)=0,0,F16/$F$3) -> 0 | E16: =C16*D16 -> 0 | F16: =OFFSET(分配表!C155,0,mth-1,1,1) -> 0 | G16: =E16*$F$3 -> 0 | I16: 硅藻土 | K16: ='F55'!K16 -> 2.60487 | L16: =IF($N$3=0,0,N16/$N$3) -> 0.74784044 | M16: =K16*L16 -> 1.9480272 | N16: =分配表!O155 -> 5119 | O16: =M16*$N$3 -> 13334.33
A17: 活性炭 | C17: ='F55'!C17 -> 0 | D17: =IF(VALUE($F$3)=0,0,F17/$F$3) -> 0 | E17: =C17*D17 -> 0 | F17: =OFFSET(分配表!C157,0,mth-1,1,1) -> 0 | G17: =E17*$F$3 -> 0 | I17: 活性炭 | K17: ='F55'!K17 -> 7.0797015 | L17: =IF($N$3=0,0,N17/$N$3) -> 1.5528025 | M17: =K17*L17 -> 10.993378 | N17: =分配表!O157 -> 10629 | O17: =M17*$N$3 -> 75250.147
A18: 淀粉酶 | C18: ='F55'!C18 -> 0 | D18: =IF(VALUE($F$3)=0,0,F18/$F$3) -> 0 | E18: =C18*D18 -> 0 | F18: =OFFSET(分配表!C158,0,mth-1,1,1) -> 0 | G18: =E18*$F$3 -> 0 | I18: 淀粉酶 | K18: ='F55'!K18 -> 47.801409 | L18: =IF($N$3=0,0,N18/$N$3) -> 0.080642298 | M18: =K18*L18 -> 3.8548155 | N18: =分配表!O158 -> 552 | O18: =M18*$N$3 -> 26386.378
A19: 复合糖化酶 | C19: ='F55'!C19 -> 0 | D19: =IF(VALUE($F$3)=0,0,F19/$F$3) -> 0 | E19: =C19*D19 -> 0 | F19: =OFFSET(分配表!C159,0,mth-1,1,1) -> 0 | G19: =E19*$F$3 -> 0 | I19: 复合糖化酶 | K19: ='F55'!K19 -> 32.197431 | L19: =IF($N$3=0,0,N19/$N$3) -> 0.15660968 | M19: =K19*L19 -> 5.0424294 | N19: =分配表!O159 -> 1072 | O19: =M19*$N$3 -> 34515.646
A20: 异构酶 | C20: ='F55'!C20 -> 0 | D20: =IF(VALUE($F$3)=0,0,F20/$F$3) -> 0 | E20: =C20*D20 -> 0 | F20: =OFFSET(分配表!C160,0,mth-1,1,1) -> 0 | G20: =E20*$F$3 -> 0 | I20: 异构酶 | K20: ='F55'!K20 -> 218.57702 | L20: =IF($N$3=0,0,N20/$N$3) -> 0.095499765 | M20: =K20*L20 -> 20.874054 | N20: =分配表!O160 -> 653.7 | O20: =M20*$N$3 -> 142883.8
A21: 硫酸镁(食品级) | C21: ='F55'!C21 -> 0 | D21: =IF(VALUE($F$3)=0,0,F21/$F$3) -> 0 | E21: =C21*D21 -> 0 | F21: =OFFSET(分配表!C161,0,mth-1,1,1) -> 0 | G21: =E21*$F$3 -> 0 | I21: 硫酸镁(食品级) | K21: ='F55'!K21 -> 0.97947435 | L21: =IF($N$3=0,0,N21/$N$3) -> 0.48341552 | M21: =K21*L21 -> 0.4734931 | N21: =分配表!O161 -> 3309 | O21: =M21*$N$3 -> 3241.0806
A22: 焦亚硫酸钠(食品级) | C22: ='F55'!C22 -> 0 | D22: =IF(VALUE($F$3)=0,0,F22/$F$3) -> 0 | E22: =C22*D22 -> 0 | F22: =OFFSET(分配表!C162,0,mth-1,1,1) -> 0 | G22: =E22*$F$3 -> 0 | I22: 焦亚硫酸钠 | K22: ='F55'!K22 -> 1.8560801 | L22: =IF($N$3=0,0,N22/$N$3) -> 0.28429332 | M22: =K22*L22 -> 0.52767118 | N22: =分配表!O162 -> 1946 | O22: =M22*$N$3 -> 3611.9319
A23: 树脂 | E23: =IF(VALUE($F$3)=0,0,G23/$F$3) -> 0 | F23: =OFFSET(分配表!C163,0,mth-1,1,1) -> 0 | G23: =OFFSET(分配表!C209,0,mth-1,1,1) -> #DIV/0! | I23: 树脂 | M23: =IF($N$3=0,0,O23/$N$3) -> #DIV/0! | N23: =分配表!O163 -> 0 | O23: =分配表!O209 -> #DIV/0!
A24: 其他 | E24: =IF(VALUE($F$3)=0,0,G24/$F$3) -> 0 | G24: =OFFSET(分配表!C220,0,mth-1) -> #DIV/0! | I24: 其他 | M24: =O24/N3 -> #DIV/0! | O24: =分配表!O220 -> #DIV/0!
A25: (三)包装物 | I25: (三)包装物
A26: (四)动力能源 | E26: =SUM(E27:E30) -> 0 | G26: =SUM(G27:G30) -> 0 | I26: (四)动力能源 | M26: =SUM(M27:M30) -> #DIV/0! | O26: =SUM(O27:O30) -> #DIV/0!
A27: 1、蒸汽 | B27: 吨 | C27: ='F55'!C27 -> 0 | D27: =IF(VALUE($F$3)=0,0,F27/$F$3) -> 0 | E27: =C27*D27 -> 0 | F27: =OFFSET(分配表!C312,0,mth-1,1,1) -> 0 | G27: =E27*F$3 -> 0 | I27: 1、蒸汽 | J27: 吨 | K27: ='F55'!K27 -> 374.79903 | L27: =IF($N$3=0,0,N27/$N$3) -> 0.30291994 | M27: =K27*L27 -> 113.5341 | N27: =分配表!O312 -> 2073.5 | O27: =M27*N$3 -> 777145.78
A28: 2、电 | B28: 度 | C28: ='F55'!C28 -> 0 | D28: =IF(VALUE($F$3)=0,0,F28/$F$3) -> 0 | E28: =C28*D28 -> 0 | F28: =OFFSET(分配表!C331,0,mth-1,1,1) -> #DIV/0! | G28: =E28*F$3 -> 0 | I28: 2、电 | J28: 度 | K28: ='F55'!K28 -> 0.6806368 | L28: =IF($N$3=0,0,N28/$N$3) -> #DIV/0! | M28: =K28*L28 -> #DIV/0! | N28: =分配表!O331 -> #DIV/0! | O28: =M28*N$3 -> #DIV/0!
A29: 3、水 | B29: 吨 | C29: ='F55'!C29 -> 0 | D29: =IF(VALUE($F$3)=0,0,F29/$F$3) -> 0 | E29: =C29*D29 -> 0 | F29: =OFFSET(分配表!C349,0,mth-1,1,1) -> #DIV/0! | G29: =E29*F$3 -> 0 | I29: 3、水 | J29: 吨 | K29: ='F55'!K29 -> 5.8950402 | L29: =IF($N$3=0,0,N29/$N$3) -> #DIV/0! | M29: =K29*L29 -> #DIV/0! | N29: =分配表!O349 -> #DIV/0! | O29: =M29*N$3 -> #DIV/0!
A30: 4、其他 | B30: 吨 | C30: ='F55'!C30 -> 0 | D30: =IF(VALUE($F$3)=0,0,F30/$F$3) -> 0 | E30: =C30*D30 -> 0 | G30: =E30*F$3 -> 0 | I30: 4、其他 | J30: 吨 | K30: ='F55'!K30 -> 0 | L30: =IF($N$3=0,0,N30/$N$3) -> 0 | M30: =K30*L30 -> 0 | O30: =M30*N$3 -> 0
A31: (五)排污费 | E31: =IF(VALUE($F$3)=0,0,G31/$F$3) -> 0 | G31: =OFFSET(分配表!C377,0,mth-1,1,1) -> #DIV/0! | I31: (五)排污费 | M31: =IF($N$3=0,,O31/$N$3) -> #DIV/0! | O31: =分配表!O377 -> #DIV/0!
A32: 1.污水处理 | E32: =E31 -> 0 | G32: =G31 -> #DIV/0! | I32: 1.污水处理 | M32: =M31 -> #DIV/0! | O32: =O31 -> #DIV/0!
A33: 2.污水固定成本 | I33: 2.污水固定成本
A34: (六)增值税 | I34: (六)增值税
A35: 三、边际贡献 | E35: =E5-E10 -> #DIV/0! | G35: =G5-G10 -> #DIV/0! | I35: 三、边际贡献 | M35: =M5-M10 -> #DIV/0! | O35: =O5-O10 -> #DIV/0!
A36: 四、固定成本 | E36: =SUM(E37:E43) -> 0 | G36: =SUM(G37:G43) -> #DIV/0! | I36: 四、固定成本 | M36: =IF(N$3=0,0,O36/N$3) -> #DIV/0! | O36: =SUM(O37:O43) -> #DIV/0!
A37: （一）折旧与摊销 | E37: =IF(VALUE($F$3)=0,0,G37/$F$3) -> 0 | G37: =OFFSET(分配表!C410,0,mth-1,1,1) -> #DIV/0! | I37: （一）折旧与摊销 | M37: =IF($N$3=0,0,O37/$N$3) -> #DIV/0! | O37: =分配表!O410 -> #DIV/0!
A38: （二）工资 | E38: =IF(VALUE($F$3)=0,0,G38/$F$3) -> 0 | G38: =OFFSET(分配表!C430,0,mth-1,1,1) -> #DIV/0! | I38: （二）工资 | M38: =IF($N$3=0,0,O38/$N$3) -> #DIV/0! | O38: =分配表!O430 -> #DIV/0!
A39: （三）制造费用 | E39: =IF(VALUE($F$3)=0,0,G39/$F$3) -> 0 | G39: =OFFSET(分配表!C450,0,mth-1,1,1) -> #DIV/0! | I39: （三）制造费用 | M39: =IF($N$3=0,0,O39/$N$3) -> #DIV/0! | O39: =分配表!O450 -> #DIV/0!
A40: （四）销售费用 | E40: =IF(VALUE($F$3)=0,0,G40/$F$3) -> 0 | G40: =OFFSET(分配表!C470,0,mth-1,1,1) -> #DIV/0! | I40: （四）销售费用 | M40: =IF($N$3=0,0,O40/$N$3) -> #DIV/0! | O40: =分配表!O470 -> #DIV/0!
A41: （五）管理费用 | E41: =IF(VALUE($F$3)=0,0,G41/$F$3) -> 0 | G41: =OFFSET(分配表!C490,0,mth-1,1,1) -> #DIV/0! | I41: （五）管理费用 | M41: =IF($N$3=0,0,O41/$N$3) -> #DIV/0! | O41: =分配表!O490 -> #DIV/0!
...

Sheet F55
A1: =CONCATENATE("果葡糖浆F55综合成本利润表_不含税(2025年"&mth&"月)") -> 果葡糖浆F55综合成本利润表_不含税(2025年8月) | I1: =CONCATENATE("果葡糖浆F55综合成本利润表_不含税(2025年1-"&mth&"月)") -> 果葡糖浆F55综合成本利润表_不含税(2025年1-8月)
A3: 自产部分 | E3: 自产产量 | F3: =OFFSET(基础表!C6,0,mth-1,1,1) -> 0 | M3: 自产产量 | N3: =基础表!O6 -> 49280.176 | O3: 吨
B4: 单位 | C4: 单价 | D4: 单耗 | E4: 单位成本 | F4: 总耗量 | G4: 总成本 | J4: 单位 | K4: 单价 | L4: 单耗 | M4: 单位成本 | N4: 总耗量 | O4: 总成本
A5: 一、收入 | E5: =E6-E7 -> #DIV/0! | G5: =G6-G7 -> #DIV/0! | I5: 一、收入 | M5: =M6-M7 -> 2655.2821 | O5: =O6-O7 -> 1.3085277e+08
A6: （一）销售价格 | E6: =OFFSET(销售收入及运费!C66,0,mth-1,1,1) -> 0 | G6: =E6*$F$3 -> 0 | I6: （一）销售价格 | M6: =销售收入及运费!O66 -> 2712.7846 | O6: =M6*$N$3 -> 1.336865e+08
A7: （二）物流费 | E7: =E8+E9 -> #DIV/0! | G7: =E7*$F$3 -> #DIV/0! | I7: （二）物流费 | M7: =M8+M9 -> 57.502534 | O7: =M7*$N$3 -> 2833735
A8: 1、运费 | E8: =OFFSET(销售收入及运费!C123,0,mth-1,1,1)/1.09/OFFSET(销售收入及运费!C6,0,mth-1,1,1) -> #DIV/0! | G8: =E8*$F$3 -> #DIV/0! | I8: 1、运费 | M8: =销售收入及运费!O123/1.09/销售收入及运费!O6 -> 44.847494 | O8: =M8*$N$3 -> 2210092.4
A9: 2、包装费、租赁费等 | E9: =(OFFSET(销售收入及运费!C143,0,mth-1,1,1)/1.13+OFFSET(销售收入及运费!C163,0,mth-1,1,1)/1.13)/OFFSET(销售收入及运费!C6,0,mth-1,1,1) -> #DIV/0! | G9: =E9*$F$3 -> #DIV/0! | I9: 2、包装费、租赁费等 | M9: =(销售收入及运费!O143/1.13+销售收入及运费!O163/1.13)/销售收入及运费!O6 -> 12.655039 | O9: =M9*$N$3 -> 623642.57
A10: 二、变动成本 | E10: =E11+E13+E26+E31+E34+E25 -> 0 | G10: =G11+G13+G26+G31+G25 -> #DIV/0! | I10: 二、变动成本 | M10: =M11+M13+M26+M31+M34+M25 -> #DIV/0! | O10: =O11+O13+O26+O31+O25 -> #DIV/0!
A11: (一)淀粉 | B11: 吨 | C11: =C12 -> 0 | D11: =IF(C11=0,0,E11/C11) -> 0 | E11: =E12 -> 0 | F11: =F12 -> 0 | G11: =G12 -> 0 | I11: (一)淀粉 | J11: 吨 | K11: =IF(N11=0,0,O11/N11) -> 2499.441 | L11: =IF(K11=0,0,M11/K11) -> 0.84877003 | M11: =M12 -> 2121.4506 | N11: =N12 -> 41827.536 | O11: =O12 -> 1.0454546e+08
A12: 1、淀粉(14%) | B12: 吨 | C12: =OFFSET(分配表!C65,0,mth-1,1,1) -> 0 | D12: =IF(VALUE($F$3)=0,0,F12/$F$3) -> 0 | E12: =C12*D12 -> 0 | F12: =OFFSET(分配表!C78,0,mth-1,1,1) -> 0 | G12: =E12*F3 -> 0 | I12: 1、淀粉(14%) | J12: 吨 | K12: =分配表!O65 -> 2499.441 | L12: =IF($N$3=0,,N12/$N$3) -> 0.84877003 | M12: =K12*L12 -> 2121.4506 | N12: =分配表!O78 -> 41827.536 | O12: =K12*N12 -> 1.0454546e+08
A13: (二）辅料 | E13: =SUM(E14:E24) -> 0 | G13: =SUM(G14:G24) -> #DIV/0! | I13: (二）辅料 | M13: =SUM(M14:M24) -> #DIV/0! | O13: =SUM(O14:O24) -> #DIV/0!
A14: 盐酸(折百) | C14: =OFFSET(分配表!C179,0,mth-1,1,1) -> 0 | D14: =IF(VALUE($F$3)=0,0,F14/$F$3) -> 0 | E14: =C14*D14 -> 0 | F14: =OFFSET(分配表!C101,0,mth-1) -> 0 | G14: =E14*$F$3 -> 0 | I14: 盐酸(折百) | K14: =分配表!O179 -> 1.0336348 | L14: =IF($N$3=0,,N14/$N$3) -> 4.5578743 | M14: =K14*L14 -> 4.7111774 | N14: =分配表!O101 -> 224612.85 | O14: =M14*$N$3 -> 232167.65
A15: 氢氧化钠(折百) | C15: =OFFSET(分配表!C180,0,mth-1,1,1) -> 0 | D15: =IF(VALUE($F$3)=0,0,F15/$F$3) -> 0 | E15: =C15*D15 -> 0 | F15: =OFFSET(分配表!C102,0,mth-1) -> 0 | G15: =E15*$F$3 -> 0 | I15: 氢氧化钠(折百) | K15: =分配表!O180 -> 3.1653036 | L15: =IF($N$3=0,,N15/$N$3) -> 5.0625869 | M15: =K15*L15 -> 16.024625 | N15: =分配表!O102 -> 249485.17 | O15: =M15*$N$3 -> 789696.32
A16: 硅藻土 | C16: =OFFSET(分配表!C181,0,mth-1,1,1) -> 0 | D16: =IF(VALUE($F$3)=0,0,F16/$F$3) -> 0 | E16: =C16*D16 -> 0 | F16: =OFFSET(分配表!C103,0,mth-1) -> 0 | G16: =E16*$F$3 -> 0 | I16: 硅藻土 | K16: =分配表!O181 -> 2.60487 | L16: =IF($N$3=0,,N16/$N$3) -> 0.76650844 | M16: =K16*L16 -> 1.9966549 | N16: =分配表!O103 -> 37773.671 | O16: =M16*$N$3 -> 98395.503
A17: 活性炭 | C17: =OFFSET(分配表!C183,0,mth-1,1,1) -> 0 | D17: =IF(VALUE($F$3)=0,0,F17/$F$3) -> 0 | E17: =C17*D17 -> 0 | F17: =OFFSET(分配表!C105,0,mth-1) -> 0 | G17: =E17*$F$3 -> 0 | I17: 活性炭 | K17: =分配表!O183 -> 7.0797015 | L17: =IF($N$3=0,,N17/$N$3) -> 1.5998718 | M17: =K17*L17 -> 11.326615 | N17: =分配表!O105 -> 78841.965 | O17: =M17*$N$3 -> 558177.58
A18: 淀粉酶 | C18: =OFFSET(分配表!C184,0,mth-1,1,1) -> 0 | D18: =IF(VALUE($F$3)=0,0,F18/$F$3) -> 0 | E18: =C18*D18 -> 0 | F18: =OFFSET(分配表!C106,0,mth-1) -> 0 | G18: =E18*$F$3 -> 0 | I18: 淀粉酶 | K18: =分配表!O184 -> 47.801409 | L18: =IF($N$3=0,,N18/$N$3) -> 0.082519047 | M18: =K18*L18 -> 3.9445268 | N18: =分配表!O106 -> 4066.5532 | O18: =M18*$N$3 -> 194386.97
A19: 复合糖化酶 | C19: =OFFSET(分配表!C185,0,mth-1,1,1) -> 0 | D19: =IF(VALUE($F$3)=0,0,F19/$F$3) -> 0 | E19: =C19*D19 -> 0 | F19: =OFFSET(分配表!C107,0,mth-1) -> 0 | G19: =E19*$F$3 -> 0 | I19: 复合糖化酶 | K19: =分配表!O185 -> 32.197431 | L19: =IF($N$3=0,,N19/$N$3) -> 0.16120776 | M19: =K19*L19 -> 5.1904757 | N19: =分配表!O107 -> 7944.3467 | O19: =M19*$N$3 -> 255787.56
A20: 异构酶 | C20: =OFFSET(分配表!C186,0,mth-1,1,1) -> 0 | D20: =IF(VALUE($F$3)=0,0,F20/$F$3) -> 0 | E20: =C20*D20 -> 0 | F20: =OFFSET(分配表!C108,0,mth-1) -> 0 | G20: =E20*$F$3 -> 0 | I20: 异构酶 | K20: =分配表!O186 -> 218.57702 | L20: =IF($N$3=0,,N20/$N$3) -> 0.097700032 | M20: =K20*L20 -> 21.354982 | N20: =分配表!O108 -> 4814.6748 | O20: =M20*$N$3 -> 1052377.3
A21: 硫酸镁 | C21: =OFFSET(分配表!C187,0,mth-1,1,1) -> 0 | D21: =IF(VALUE($F$3)=0,0,F21/$F$3) -> 0 | E21: =C21*D21 -> 0 | F21: =OFFSET(分配表!C109,0,mth-1) -> 0 | G21: =E21*$F$3 -> 0 | I21: 硫酸镁 | K21: =分配表!O187 -> 0.97947435 | L21: =IF($N$3=0,,N21/$N$3) -> 0.49607959 | M21: =K21*L21 -> 0.48589723 | N21: =分配表!O109 -> 24446.89 | O21: =M21*$N$3 -> 23945.101
A22: 焦亚硫酸钠 | C22: =OFFSET(分配表!C188,0,mth-1,1,1) -> 0 | D22: =IF(VALUE($F$3)=0,0,F22/$F$3) -> 0 | E22: =C22*D22 -> 0 | F22: =OFFSET(分配表!C110,0,mth-1) -> 0 | G22: =E22*$F$3 -> 0 | I22: 焦亚硫酸钠 | K22: =分配表!O188 -> 1.8560801 | L22: =IF($N$3=0,,N22/$N$3) -> 0.29181585 | M22: =K22*L22 -> 0.54163359 | N22: =分配表!O110 -> 14380.736 | O22: =M22*$N$3 -> 26691.799
A23: 树脂 | E23: =IF(VALUE($F$3)=0,0,G23/$F$3) -> 0 | G23: =OFFSET(分配表!C205,0,mth-1,1,1) -> #DIV/0! | I23: 树脂 | M23: =IF($N$3=0,0,O23/$N$3) -> #DIV/0! | O23: =分配表!O205 -> #DIV/0!
A24: 其他 | E24: =IF(VALUE($F$3)=0,0,G24/$F$3) -> 0 | G24: =OFFSET(分配表!C216,0,mth-1,1,1) -> #DIV/0! | I24: 其他 | M24: =IF($N$3=0,0,O24/$N$3) -> #DIV/0! | O24: =分配表!O216 -> #DIV/0!
A25: (三)包装物 | I25: (三)包装物
A26: (四)动力能源 | E26: =SUM(E27:E30) -> 0 | G26: =SUM(G27:G30) -> 0 | I26: (四)动力能源 | M26: =SUM(M27:M30) -> #DIV/0! | O26: =SUM(O27:O30) -> #DIV/0!
A27: 1、蒸汽 | B27: 吨 | C27: =OFFSET(分配表!C305,0,mth-1,1,1) -> 0 | D27: =IF(VALUE($F$3)=0,0,F27/$F$3) -> 0 | E27: =C27*D27 -> 0 | F27: =OFFSET(分配表!C308,0,mth-1,1,1) -> 0 | G27: =E27*F$3 -> 0 | I27: 1、蒸汽 | J27: 吨 | K27: =分配表!O305 -> 374.79903 | L27: =IF($N$3=0,0,N27/$N$3) -> 0.30859932 | M27: =K27*L27 -> 115.66272 | N27: =分配表!O308 -> 15207.829 | O27: =M27*N$3 -> 5699879.4
A28: 2、电 | B28: 度 | C28: =OFFSET(分配表!C324,0,mth-1,1,1) -> 0 | D28: =IF(VALUE($F$3)=0,0,F28/$F$3) -> 0 | E28: =C28*D28 -> 0 | F28: =OFFSET(分配表!C327,0,mth-1,1,1) -> #DIV/0! | G28: =E28*F$3 -> 0 | I28: 2、电 | J28: 度 | K28: =分配表!O324 -> 0.6806368 | L28: =IF($N$3=0,0,N28/$N$3) -> #DIV/0! | M28: =K28*L28 -> #DIV/0! | N28: =分配表!O327 -> #DIV/0! | O28: =M28*N$3 -> #DIV/0!
A29: 3、水 | B29: 吨 | C29: =OFFSET(分配表!C343,0,mth-1,1,1) -> 0 | D29: =IF(VALUE($F$3)=0,0,F29/$F$3) -> 0 | E29: =C29*D29 -> 0 | F29: =OFFSET(分配表!C345,0,mth-1,1,1) -> #DIV/0! | G29: =E29*F$3 -> 0 | I29: 3、水 | J29: 吨 | K29: =分配表!O343 -> 5.8950402 | L29: =IF($N$3=0,0,N29/$N$3) -> #DIV/0! | M29: =K29*L29 -> #DIV/0! | N29: =分配表!O345 -> #DIV/0! | O29: =M29*N$3 -> #DIV/0!
A30: 4、其他 | B30: 吨 | C30: =OFFSET(分配表!C360,0,mth-1,1,1) -> 0 | D30: =IF(VALUE($F$3)=0,0,F30/$F$3) -> 0 | E30: =C30*D30 -> 0 | F30: =OFFSET(分配表!C362,0,mth-1,1,1) -> 0 | G30: =E30*F$3 -> 0 | I30: 4、其他 | J30: 吨 | K30: =分配表!O360 -> 0 | L30: =IF($N$3=0,0,N30/$N$3) -> 0 | M30: =K30*L30 -> 0 | N30: =分配表!O362 -> 0 | O30: =M30*N$3 -> 0
A31: (五)排污费 | E31: =IF(VALUE($F$3)=0,0,G31/$F$3) -> 0 | G31: =OFFSET(分配表!C373,0,mth-1,1,1) -> #DIV/0! | I31: (五)排污费 | M31: =IF($N$3=0,,O31/$N$3) -> #DIV/0! | O31: =分配表!O373 -> #DIV/0!
A32: 1.污水处理 | E32: =E31 -> 0 | G32: =G31 -> #DIV/0! | I32: 1.污水处理 | M32: =M31 -> #DIV/0! | O32: =O31 -> #DIV/0!
A33: 2.污水固定成本 | I33: 2.污水固定成本
A34: (六)增值税 | I34: (六)增值税
A35: 三、边际贡献 | E35: =E5-E10 -> #DIV/0! | G35: =G5-G10 -> #DIV/0! | I35: 三、边际贡献 | M35: =M5-M10 -> #DIV/0! | O35: =O5-O10 -> #DIV/0!
A36: 四、固定成本 | E36: =SUM(E37:E43) -> 0 | G36: =SUM(G37:G43) -> #DIV/0! | I36: 四、固定成本 | M36: =IF(N$3=0,0,O36/N$3) -> #DIV/0! | O36: =SUM(O37:O43) -> #DIV/0!
A37: （一）折旧与摊销 | E37: =IF(VALUE($F$3)=0,0,G37/$F$3) -> 0 | G37: =OFFSET(分配表!C406,0,mth-1,1,1) -> #DIV/0! | I37: （一）折旧与摊销 | M37: =IF($N$3=0,0,O37/$N$3) -> #DIV/0! | O37: =分配表!O406 -> #DIV/0!
A38: （二）工资 | E38: =IF(VALUE($F$3)=0,0,G38/$F$3) -> 0 | G38: =OFFSET(分配表!C426,0,mth-1,1,1) -> #DIV/0! | I38: （二）工资 | M38: =IF($N$3=0,0,O38/$N$3) -> #DIV/0! | O38: =分配表!O426 -> #DIV/0!
A39: （三）制造费用 | E39: =IF(VALUE($F$3)=0,0,G39/$F$3) -> 0 | G39: =OFFSET(分配表!C446,0,mth-1,1,1) -> #DIV/0! | I39: （三）制造费用 | M39: =IF($N$3=0,0,O39/$N$3) -> #DIV/0! | O39: =分配表!O446 -> #DIV/0!
A40: （四）销售费用 | E40: =IF(VALUE($F$3)=0,0,G40/$F$3) -> 0 | G40: =OFFSET(分配表!C466,0,mth-1,1,1) -> #DIV/0! | I40: （四）销售费用 | M40: =IF($N$3=0,0,O40/$N$3) -> #DIV/0! | O40: =分配表!O466 -> #DIV/0!
A41: （五）管理费用 | E41: =IF(VALUE($F$3)=0,0,G41/$F$3) -> 0 | G41: =OFFSET(分配表!C486,0,mth-1,1,1) -> #DIV/0! | I41: （五）管理费用 | M41: =IF($N$3=0,0,O41/$N$3) -> #DIV/0! | O41: =分配表!O486 -> #DIV/0!
...

Sheet 果糖汇总
A1: =CONCATENATE("汇总综合成本利润表_不含税(2025年"&mth&"月)") -> 汇总综合成本利润表_不含税(2025年8月) | I1: =CONCATENATE("汇总综合成本利润表_不含税(2025年1-"&mth&"月)") -> 汇总综合成本利润表_不含税(2025年1-8月)
A3: 全部产品 | E3: 本月产量： | F3: =OFFSET(基础表!C25,0,mth-1,1,1)/0.77 -> 0 | G3: 吨 | M3: 本年产量： | N3: =基础表!O25/0.77 -> 57934.763 | O3: 吨
B4: 单位 | C4: 单价 | D4: 单耗 | E4: 单位成本 | F4: 总耗量 | G4: 总成本 | J4: 单位 | K4: 单价 | L4: 单耗 | M4: 单位成本 | N4: 总耗量 | O4: 总成本
A5: 一、收入 | E5: =E6-E7 -> 0 | G5: =G6-G7 -> #DIV/0! | I5: 一、收入 | M5: =M6-M7 -> 2722.3523 | O5: =O6-O7 -> 1.5771884e+08
A6: （一）销售价格 | E6: =IF(F$3=0,0,G6/F$3) -> 0 | G6: ='F55'!G6+'F42'!G6+'F60'!G6+'F90'!G6 -> 0 | I6: （一）销售价格 | M6: =IF($N$3=0,,O6/$N$3) -> 2858.5148 | O6: ='F55'!O6+'F42'!O6+'F60'!O6+'F90'!O6 -> 1.6560738e+08
A7: （二）物流费 | E7: =IF($F$3=0,,G7/$F$3) -> 0 | G7: ='F55'!G7+'F42'!G7+'F60'!G7+'F90'!G7 -> #DIV/0! | I7: （二）物流费 | M7: =IF($N$3=0,,O7/$N$3) -> 136.16246 | O7: ='F55'!O7+'F42'!O7+'F60'!O7+'F90'!O7 -> 7888540.2
A8: 1、运费 | E8: =IF($F$3=0,,G8/$F$3) -> 0 | G8: ='F55'!G8+'F42'!G8+'F60'!G8+'F90'!G8 -> #DIV/0! | I8: 1、运费 | M8: =IF($N$3=0,,O8/$N$3) -> 64.429155 | O8: ='F55'!O8+'F42'!O8+'F60'!O8+'F90'!O8 -> 3732687.8
A9: 2、包装费、租赁费等 | E9: =IF($F$3=0,,G9/$F$3) -> 0 | G9: ='F55'!G9+'F42'!G9+'F60'!G9+'F90'!G9 -> #DIV/0! | I9: 2、包装费、租赁费等 | M9: =IF($N$3=0,,O9/$N$3) -> 71.73331 | O9: ='F55'!O9+'F42'!O9+'F60'!O9+'F90'!O9 -> 4155852.3
A10: 二、变动成本 | E10: =E11+E13+E26+E31+E34+E25 -> 0 | G10: =G11+G13+G26+G31+G25 -> #DIV/0! | I10: 二、变动成本 | M10: =M11+M13+M26+M31+M34+M25 -> #DIV/0! | O10: =O11+O13+O26+O31+O25 -> #DIV/0!
A11: (一)淀粉 | B11: 吨 | C11: =C12 -> 0 | D11: =IF(C11=0,0,E11/C11) -> 0 | E11: =E12 -> 0 | F11: =F12 -> 0 | G11: =G12 -> 0 | I11: (一)淀粉 | J11: 吨 | K11: =IF(N11=0,0,O11/N11) -> 2499.4112 | L11: =L12 -> 0.84550165 | M11: =M12 -> 2113.2563 | N11: =N12 -> 48983.938 | O11: =O12 -> 1.22431e+08
A12: 1、淀粉(14%) | B12: 吨 | C12: =IF(E12=0,0,E12/D12) -> 0 | D12: =IF(F3=0,,F12/F3) -> 0 | E12: =IF(F3=0,0,G12/F3) -> 0 | F12: ='F55'!F12+'F42'!F12+'F60'!F12+'F90'!F12 -> 0 | G12: ='F55'!G12+'F42'!G12+'F60'!G12+'F90'!G12 -> 0 | I12: 1、淀粉(14%) | J12: 吨 | K12: =M12/L12 -> 2499.4112 | L12: =IF(N3=0,,N12/N3) -> 0.84550165 | M12: =O12/N3 -> 2113.2563 | N12: ='F55'!N12+'F42'!N12+'F60'!N12+'F90'!N12 -> 48983.938 | O12: ='F55'!O12+'F42'!O12+'F60'!O12+'F90'!O12 -> 1.22431e+08
A13: (二）辅料 | E13: =IF(VALUE($F$3)=0,0,G13/$F$3) -> 0 | G13: ='F55'!G13+'F42'!G13+'F60'!G13+'F90'!G13 -> #DIV/0! | I13: (二）辅料 | M13: =O13/N3 -> #DIV/0! | O13: ='F55'!O13+'F42'!O13+'F60'!O13+'F90'!O13 -> #DIV/0!
A14: 盐酸(折百) | C14: ='F55'!C14 -> 0 | D14: =IF($F$3=0,,F14/$F$3) -> 0 | E14: =C14*D14 -> 0 | F14: ='F55'!F14+'F42'!F14+'F60'!F14+'F90'!F14 -> 0 | G14: ='F55'!G14+'F42'!G14+'F60'!G14+'F90'!G14 -> 0 | I14: 盐酸(折百) | K14: ='F55'!K14 -> 1.0336348 | L14: =IF($N$3=0,,N14/$N$3) -> 4.5394438 | M14: =K14*L14 -> 4.6921269 | N14: ='F55'!N14+'F42'!N14+'F60'!N14+'F90'!N14 -> 262991.6 | O14: ='F55'!O14+'F42'!O14+'F60'!O14+'F90'!O14 -> 271837.26
A15: 氢氧化钠(折百) | C15: ='F55'!C15 -> 0 | D15: =IF($F$3=0,,F15/$F$3) -> 0 | E15: =C15*D15 -> 0 | F15: ='F55'!F15+'F42'!F15+'F60'!F15+'F90'!F15 -> 0 | G15: ='F55'!G15+'F42'!G15+'F60'!G15+'F90'!G15 -> 0 | I15: 氢氧化钠(折百) | K15: ='F55'!K15 -> 3.1653036 | L15: =IF($N$3=0,,N15/$N$3) -> 5.0423611 | M15: =K15*L15 -> 15.960604 | N15: ='F55'!N15+'F42'!N15+'F60'!N15+'F90'!N15 -> 292128 | O15: ='F55'!O15+'F42'!O15+'F60'!O15+'F90'!O15 -> 924673.82
A16: 硅藻土 | C16: ='F55'!C16 -> 0 | D16: =IF($F$3=0,,F16/$F$3) -> 0 | E16: =C16*D16 -> 0 | F16: ='F55'!F16+'F42'!F16+'F60'!F16+'F90'!F16 -> 0 | G16: ='F55'!G16+'F42'!G16+'F60'!G16+'F90'!G16 -> 0 | I16: 硅藻土 | K16: ='F55'!K16 -> 2.60487 | L16: =IF($N$3=0,,N16/$N$3) -> 0.76499838 | M16: =K16*L16 -> 1.9927213 | N16: ='F55'!N16+'F42'!N16+'F60'!N16+'F90'!N16 -> 44320 | O16: ='F55'!O16+'F42'!O16+'F60'!O16+'F90'!O16 -> 115447.84
A17: 活性炭 | C17: ='F55'!C17 -> 0 | D17: =IF($F$3=0,,F17/$F$3) -> 0 | E17: =C17*D17 -> 0 | F17: ='F55'!F17+'F42'!F17+'F60'!F17+'F90'!F17 -> 0 | G17: ='F55'!G17+'F42'!G17+'F60'!G17+'F90'!G17 -> 0 | I17: 活性炭 | K17: ='F55'!K17 -> 7.0797015 | L17: =IF($N$3=0,,N17/$N$3) -> 1.5935165 | M17: =K17*L17 -> 11.281621 | N17: ='F55'!N17+'F42'!N17+'F60'!N17+'F90'!N17 -> 92320 | O17: ='F55'!O17+'F42'!O17+'F60'!O17+'F90'!O17 -> 653598.04
A18: 淀粉酶 | C18: ='F55'!C18 -> 0 | D18: =IF($F$3=0,,F18/$F$3) -> 0 | E18: =C18*D18 -> 0 | F18: ='F55'!F18+'F42'!F18+'F60'!F18+'F90'!F18 -> 0 | G18: ='F55'!G18+'F42'!G18+'F60'!G18+'F90'!G18 -> 0 | I18: 淀粉酶 | K18: ='F55'!K18 -> 47.801409 | L18: =IF($N$3=0,,N18/$N$3) -> 0.08242029 | M18: =K18*L18 -> 3.939806 | N18: ='F55'!N18+'F42'!N18+'F60'!N18+'F90'!N18 -> 4775 | O18: ='F55'!O18+'F42'!O18+'F60'!O18+'F90'!O18 -> 228251.73
A19: 复合糖化酶 | C19: ='F55'!C19 -> 0 | D19: =IF($F$3=0,,F19/$F$3) -> 0 | E19: =C19*D19 -> 0 | F19: ='F55'!F19+'F42'!F19+'F60'!F19+'F90'!F19 -> 0 | G19: ='F55'!G19+'F42'!G19+'F60'!G19+'F90'!G19 -> 0 | I19: 复合糖化酶 | K19: ='F55'!K19 -> 32.197431 | L19: =IF($N$3=0,,N19/$N$3) -> 0.16059442 | M19: =K19*L19 -> 5.1707279 | N19: ='F55'!N19+'F42'!N19+'F60'!N19+'F90'!N19 -> 9304 | O19: ='F55'!O19+'F42'!O19+'F60'!O19+'F90'!O19 -> 299564.9
A20: 异构酶 | C20: ='F55'!C20 -> 0 | D20: =IF($F$3=0,,F20/$F$3) -> 0 | E20: =C20*D20 -> 0 | F20: ='F55'!F20+'F42'!F20+'F60'!F20+'F90'!F20 -> 0 | G20: ='F55'!G20+'F42'!G20+'F60'!G20+'F90'!G20 -> 0 | I20: 异构酶 | K20: ='F55'!K20 -> 218.57702 | L20: =IF($N$3=0,,N20/$N$3) -> 0.097368137 | M20: =K20*L20 -> 21.282437 | N20: ='F55'!N20+'F42'!N20+'F60'!N20+'F90'!N20 -> 5641 | O20: ='F55'!O20+'F42'!O20+'F60'!O20+'F90'!O20 -> 1232993
A21: 硫酸镁 | C21: ='F55'!C21 -> 0 | D21: =IF($F$3=0,,F21/$F$3) -> 0 | E21: =C21*D21 -> 0 | F21: ='F55'!F21+'F42'!F21+'F60'!F21+'F90'!F21 -> 0 | G21: ='F55'!G21+'F42'!G21+'F60'!G21+'F90'!G21 -> 0 | I21: 硫酸镁 | K21: ='F55'!K21 -> 0.97947435 | L21: =IF($N$3=0,,N21/$N$3) -> 0.49452174 | M21: =K21*L21 -> 0.48437136 | N21: ='F55'!N21+'F42'!N21+'F60'!N21+'F90'!N21 -> 28650 | O21: ='F55'!O21+'F42'!O21+'F60'!O21+'F90'!O21 -> 28061.94
A22: 焦亚硫酸钠 | C22: ='F55'!C22 -> 0 | D22: =IF($F$3=0,,F22/$F$3) -> 0 | E22: =C22*D22 -> 0 | F22: ='F55'!F22+'F42'!F22+'F60'!F22+'F90'!F22 -> 0 | G22: ='F55'!G22+'F42'!G22+'F60'!G22+'F90'!G22 -> 0 | I22: 焦亚硫酸钠 | K22: ='F55'!K22 -> 1.8560801 | L22: =IF($N$3=0,,N22/$N$3) -> 0.29084437 | M22: =K22*L22 -> 0.53983046 | N22: ='F55'!N22+'F42'!N22+'F60'!N22+'F90'!N22 -> 16850 | O22: ='F55'!O22+'F42'!O22+'F60'!O22+'F90'!O22 -> 31274.95
A23: 树脂 | E23: =IF($F$3=0,0,G23/$F$3) -> 0 | F23: ='F55'!F23+'F42'!F23+'F60'!F23 -> 0 | G23: ='F55'!G23+'F42'!G23+'F60'!G23+'F90'!G23 -> #DIV/0! | I23: 树脂 | M23: =IF($N$3=0,0,O23/$N$3) -> #DIV/0! | N23: ='F55'!N23+'F42'!N23+'F60'!N23+'F90'!N23 -> 0 | O23: ='F55'!O23+'F42'!O23+'F60'!O23+'F90'!O23 -> #DIV/0!
A24: 其他 | E24: =IF($F$3=0,0,G24/$F$3) -> 0 | F24: ='F55'!F24+'F42'!F24+'F60'!F24 -> 0 | G24: ='F55'!G24+'F42'!G24+'F60'!G24+'F90'!G24 -> #DIV/0! | I24: 其他 | M24: =O24/N3 -> #DIV/0! | N24: ='F55'!N24+'F42'!N24+'F60'!N24+'F90'!N24 -> 0 | O24: ='F55'!O24+'F42'!O24+'F60'!O24+'F90'!O24 -> #DIV/0!
A25: (三)包装物 | E25: =IF($F$3=0,,G25/$F$3) -> 0 | G25: ='F55'!G25+'F60'!G25+'F42'!G25+'F90'!G25 -> 0 | I25: (三)包装物 | M25: =IF($N$3=0,,O25/$N$3) -> 0 | O25: ='F55'!O25+'F60'!O25+'F42'!O25+'F90'!O25 -> 0
A26: (四)动力能源 | E26: =SUM(E27:E30) -> 0 | G26: =SUM(G27:G30) -> 0 | I26: (四)动力能源 | M26: =SUM(M27:M30) -> #DIV/0! | O26: =SUM(O27:O30) -> #DIV/0!
A27: 1、蒸汽 | B27: 吨 | C27: ='F55'!C27 -> 0 | D27: =IF($F$3=0,0,F27/$F$3) -> 0 | E27: =C27*D27 -> 0 | F27: ='F55'!F27+'F42'!F27+'F60'!F27+'F90'!F27 -> 0 | G27: ='F55'!G27+'F42'!G27+'F60'!G27+'F90'!G27 -> 0 | I27: 1、蒸汽 | J27: 吨 | K27: ='F55'!K27 -> 374.79903 | L27: =IF($N$3=0,0,N27/$N$3) -> 0.30803612 | M27: =K27*L27 -> 115.45164 | N27: ='F55'!N27+'F42'!N27+'F60'!N27+'F90'!N27 -> 17846 | O27: ='F55'!O27+'F42'!O27+'F60'!O27+'F90'!O27 -> 6688663.4
A28: 2、电 | B28: 度 | C28: ='F55'!C28 -> 0 | D28: =IF($F$3=0,0,F28/$F$3) -> 0 | E28: =C28*D28 -> 0 | F28: ='F55'!F28+'F42'!F28+'F60'!F28+'F90'!F28 -> #DIV/0! | G28: ='F55'!G28+'F42'!G28+'F60'!G28+'F90'!G28 -> 0 | I28: 2、电 | J28: 度 | K28: ='F55'!K28 -> 0.6806368 | L28: =IF($N$3=0,0,N28/$N$3) -> #DIV/0! | M28: =K28*L28 -> #DIV/0! | N28: ='F55'!N28+'F42'!N28+'F60'!N28+'F90'!N28 -> #DIV/0! | O28: ='F55'!O28+'F42'!O28+'F60'!O28+'F90'!O28 -> #DIV/0!
A29: 3、水 | B29: 吨 | C29: ='F55'!C29 -> 0 | D29: =IF($F$3=0,0,F29/$F$3) -> 0 | E29: =C29*D29 -> 0 | F29: ='F55'!F29+'F42'!F29+'F60'!F29+'F90'!F29 -> #DIV/0! | G29: ='F55'!G29+'F42'!G29+'F60'!G29+'F90'!G29 -> 0 | I29: 3、水 | J29: 吨 | K29: ='F55'!K29 -> 5.8950402 | L29: =IF($N$3=0,0,N29/$N$3) -> #DIV/0! | M29: =K29*L29 -> #DIV/0! | N29: ='F55'!N29+'F42'!N29+'F60'!N29+'F90'!N29 -> #DIV/0! | O29: ='F55'!O29+'F42'!O29+'F60'!O29+'F90'!O29 -> #DIV/0!
A30: 4、其他 | B30: 吨 | C30: =IF(G30=0,0,G30/F30) -> 0 | D30: =IF($F$3=0,0,F30/$F$3) -> 0 | E30: =C30*D30 -> 0 | F30: ='F55'!F30+'F42'!F30+'F60'!F30+'F90'!F30 -> 0 | G30: ='F55'!G30+'F42'!G30+'F60'!G30+'F90'!G30 -> 0 | I30: 4、其他 | J30: 吨 | K30: ='F55'!K30 -> 0 | L30: =IF($N$3=0,0,N30/$N$3) -> 0 | M30: =K30*L30 -> 0 | N30: ='F55'!N30+'F42'!N30+'F60'!N30+'F90'!N30 -> 0 | O30: ='F55'!O30+'F42'!O30+'F60'!O30+'F90'!O30 -> 0
A31: (五)排污费 | E31: =IF(F$3=0,0,G31/F$3) -> 0 | F31: ='F55'!F31+'F42'!F31+'F60'!F31+'F90'!F31 -> 0 | G31: ='F55'!G31+'F60'!G31+'F42'!G31+'F90'!G31 -> #DIV/0! | I31: (五)排污费 | M31: =IF(N$3=0,0,O31/N$3) -> #DIV/0! | N31: ='F55'!N31+'F42'!N31+'F60'!N31+'F90'!N31 -> 0 | O31: ='F55'!O31+'F60'!O31+'F42'!O301+'F90'!O31 -> #DIV/0!
A32: 1.污水处理 | E32: =E31 -> 0 | F32: =F31 -> 0 | G32: =G31 -> #DIV/0! | I32: 1.污水处理 | M32: =M31 -> #DIV/0! | N32: =N31 -> 0 | O32: =O31 -> #DIV/0!
A33: 2.污水固定成本 | I33: 2.污水固定成本
A34: (六)增值税 | I34: (六)增值税
A35: 三、边际贡献 | E35: =E5-E10 -> 0 | G35: =G5-G10 -> #DIV/0! | I35: 三、边际贡献 | M35: =M5-M10 -> #DIV/0! | O35: =O5-O10 -> #DIV/0!
A36: 四、固定成本 | E36: =SUM(E37:E43) -> 0 | G36: =SUM(G37:G43) -> #DIV/0! | I36: 四、固定成本 | M36: =IF(N$3=0,0,O36/N$3) -> #DIV/0! | O36: =SUM(O37:O43) -> #DIV/0!
A37: （一）折旧与摊销 | E37: =IF(F$3=0,0,G37/F$3) -> 0 | G37: ='F55'!G37+'F42'!G37+'F60'!G37+'F90'!G37 -> #DIV/0! | I37: （一）折旧与摊销 | M37: =IF(N$3=0,0,O37/N$3) -> #DIV/0! | O37: ='F55'!O37+'F42'!O37+'F60'!O37+'F90'!O37 -> #DIV/0!
A38: （二）工资 | E38: =IF(F$3=0,0,G38/F$3) -> 0 | G38: ='F55'!G38+'F42'!G38+'F60'!G38+'F90'!G38 -> #DIV/0! | I38: （二）工资 | M38: =IF(N$3=0,0,O38/N$3) -> #DIV/0! | O38: ='F55'!O38+'F42'!O38+'F60'!O38+'F90'!O38 -> #DIV/0!
A39: （三）制造费用 | E39: =IF(F$3=0,0,G39/F$3) -> 0 | G39: ='F55'!G39+'F42'!G39+'F60'!G39+'F90'!G39 -> #DIV/0! | I39: （三）制造费用 | M39: =IF(N$3=0,0,O39/N$3) -> #DIV/0! | O39: ='F55'!O39+'F42'!O39+'F60'!O39+'F90'!O39 -> #DIV/0!
A40: （四）销售费用 | E40: =IF(F$3=0,0,G40/F$3) -> 0 | G40: ='F55'!G40+'F42'!G40+'F60'!G40+'F90'!G40 -> #DIV/0! | I40: （四）销售费用 | M40: =IF(N$3=0,0,O40/N$3) -> #DIV/0! | O40: ='F55'!O40+'F42'!O40+'F60'!O40+'F90'!O40 -> #DIV/0!
A41: （五）管理费用 | E41: =IF(F$3=0,0,G41/F$3) -> 0 | G41: ='F55'!G41+'F42'!G41+'F60'!G41+'F90'!G41 -> #DIV/0! | I41: （五）管理费用 | M41: =IF(N$3=0,0,O41/N$3) -> #DIV/0! | O41: ='F55'!O41+'F42'!O41+'F60'!O41+'F90'!O41 -> #DIV/0!
...

Sheet 专用糖
A1: =CONCATENATE("糖浆老线综合成本利润表_不含税(2025年"&mth&"月)") -> 糖浆老线综合成本利润表_不含税(2025年8月) | I1: =CONCATENATE("糖浆老线综合成本利润表_不含税(2025年1-"&mth&"月)") -> 糖浆老线综合成本利润表_不含税(2025年1-8月)
A3: 产量 | E3: 本月产量 | F3: =OFFSET(基础表!C13,0,mth-1,1,1) -> 0 | G3: 吨 | M3: 本年产量 | N3: =基础表!O13 -> 38999.431 | O3: 吨
B4: 单位 | C4: 单价 | D4: 单耗 | E4: 单位成本 | F4: 总耗量 | G4: 总成本 | J4: 单位 | K4: 单价 | L4: 单耗 | M4: 单位成本 | N4: 总耗量 | O4: 总成本
A5: 一、收入 | E5: =E6-E7 -> #DIV/0! | G5: =G6-G7 -> #DIV/0! | I5: 一、收入 | M5: =M6-M7 -> 2838.4466 | O5: =O6-O7 -> 1.106978e+08
A6: （一）销售价格 | E6: =OFFSET(销售收入及运费!C78,0,mth-1,1,1) -> 0 | G6: =E6*$F$3 -> 0 | I6: （一）销售价格 | M6: =销售收入及运费!O78 -> 2907.4664 | O6: =M6*$N$3 -> 1.1338954e+08
A7: （二）物流费 | E7: =E8+E9 -> #DIV/0! | G7: =E7*$F$3 -> #DIV/0! | I7: （二）物流费 | M7: =M8+M9 -> 69.019841 | O7: =M7*$N$3 -> 2691734.5
A8: 1、运费 | E8: =OFFSET(销售收入及运费!C135,0,mth-1,1,1)/1.09/OFFSET(销售收入及运费!C18,0,mth-1,1,1) -> #DIV/0! | G8: =E8*$F$3 -> #DIV/0! | I8: 1、运费 | M8: =销售收入及运费!O135/1.09/销售收入及运费!O18 -> 58.974504 | O8: =M8*$N$3 -> 2299972.1
A9: 2、包装费、租赁费等 | E9: =(OFFSET(销售收入及运费!C155,0,mth-1,1,1)/1.13+OFFSET(销售收入及运费!C175,0,mth-1,1,1)/1.13)/(OFFSET(销售收入及运费!C18,0,mth-1,1,1)) -> #DIV/0! | G9: =E9*$F$3 -> #DIV/0! | I9: 2、包装费、租赁费等 | M9: =(销售收入及运费!O155+销售收入及运费!O175)/1.13/销售收入及运费!O18 -> 10.045337 | O9: =M9*$N$3 -> 391762.42
A10: 二、变动成本 | E10: =E11+E13+E28+E33 -> 0 | G10: =G11+G13+G28+G33+G27 -> #DIV/0! | I10: 二、变动成本 | M10: =M11+M13+M28+M33 -> #DIV/0! | O10: =O11+O13+O28+O33+O27 -> #DIV/0! | Q10: =F3*0.84 -> 0
A11: (一)淀粉 | B11: 吨 | C11: =C12 -> 0 | D11: =IF(C11=0,0,E11/C11) -> 0 | E11: =E12 -> 0 | F11: =F12 -> 0 | G11: =G12 -> 0 | I11: (一)淀粉 | J11: 吨 | K11: =IF(N11=0,0,O11/N11) -> 2498.3033 | L11: =IF(K11=0,0,M11/K11) -> 0.84925716 | M11: =M12 -> 2121.702 | N11: =N12 -> 33120.546 | O11: =O12 -> 82745169
A12: 1、淀粉(14%) | B12: 吨 | C12: =OFFSET(分配表!C70,0,mth-1,1,1) -> 0 | D12: =IF(VALUE($F$3)=0,0,F12/$F$3) -> 0 | E12: =C12*D12 -> 0 | F12: =OFFSET(分配表!C84,0,mth-1,1,1) -> 0 | G12: =E12*F3 -> 0 | I12: 1、淀粉(14%) | J12: 吨 | K12: =分配表!O70 -> 2498.3033 | L12: =IF($N$3=0,0,N12/$N$3) -> 0.84925716 | M12: =K12*L12 -> 2121.702 | N12: =分配表!O84 -> 33120.546 | O12: =K12*N12 -> 82745169
A13: (二)辅助材料 | E13: =IF(VALUE($F$3)=0,0,G13/$F$3) -> 0 | G13: =OFFSET(分配表!C281,0,mth-1) -> 0 | I13: (二)辅助材料 | M13: =IF($N$3=0,0,O13/$N$3) -> 45.096402 | O13: =分配表!O281 -> 1758734
A14: 活性炭 | C14: =OFFSET(分配表!C240,0,mth-1,1,1) -> 0 | D14: =IF(VALUE($F$3)=0,0,F14/$F$3) -> 0 | E14: =C14*D14 -> 0 | F14: =OFFSET(分配表!C226,0,mth-1) -> 0 | G14: =E14*$F$3 -> 0 | I14: 活性炭 | K14: =分配表!O240 -> 3.5720579 | L14: =IF($N$3=0,,N14/$N$3) -> 3.7759525 | M14: =K14*L14 -> 13.487921 | N14: =分配表!O226 -> 147260 | O14: =M14*$N$3 -> 526021.24
A15: 食用级盐酸（折百） | C15: =OFFSET(分配表!C241,0,mth-1,1,1) -> 0 | D15: =IF(VALUE($F$3)=0,0,F15/$F$3) -> 0 | E15: =C15*D15 -> 0 | F15: =OFFSET(分配表!C227,0,mth-1) -> 0 | G15: =E15*$F$3 -> 0 | I15: 食用级盐酸（折百） | K15: =分配表!O241 -> 1.0323967 | L15: =IF($N$3=0,,N15/$N$3) -> 3.6441429 | M15: =K15*L15 -> 3.762201 | N15: =分配表!O227 -> 142119.5 | O15: =M15*$N$3 -> 146723.7
A16: 食用级液碱（折百） | C16: =OFFSET(分配表!C242,0,mth-1,1,1) -> 0 | D16: =IF(VALUE($F$3)=0,0,F16/$F$3) -> 0 | E16: =C16*D16 -> 0 | F16: =OFFSET(分配表!C228,0,mth-1) -> 0 | G16: =E16*$F$3 -> 0 | I16: 食用级液碱（折百） | K16: =分配表!O242 -> 3.1537633 | L16: =IF($N$3=0,,N16/$N$3) -> 4.4881065 | M16: =K16*L16 -> 14.154425 | N16: =分配表!O228 -> 175033.6 | O16: =M16*$N$3 -> 552014.54
A17: 纯碱 | C17: =OFFSET(分配表!C243,0,mth-1,1,1) -> 0 | D17: =IF(VALUE($F$3)=0,0,F17/$F$3) -> 0 | E17: =C17*D17 -> 0 | F17: =OFFSET(分配表!C229,0,mth-1) -> 0 | G17: =E17*$F$3 -> 0 | I17: 纯碱 | K17: =分配表!O243 -> 2.1446133 | L17: =IF($N$3=0,,N17/$N$3) -> 0.076924199 | M17: =K17*L17 -> 0.16497266 | N17: =分配表!O229 -> 3000 | O17: =M17*$N$3 -> 6433.84
A18: 真菌酶 | C18: =OFFSET(分配表!C244,0,mth-1,1,1) -> 0 | D18: =IF(VALUE($F$3)=0,0,F18/$F$3) -> 0 | E18: =C18*D18 -> 0 | F18: =OFFSET(分配表!C230,0,mth-1) -> 0 | G18: =E18*$F$3 -> 0 | I18: 真菌酶 | K18: =分配表!O244 -> 35.398243 | L18: =IF($N$3=0,,N18/$N$3) -> 0.035308207 | M18: =K18*L18 -> 1.2498485 | N18: =分配表!O230 -> 1377 | O18: =M18*$N$3 -> 48743.38
A19: 2X型高温酶 | C19: =OFFSET(分配表!C245,0,mth-1,1,1) -> 0 | D19: =IF(VALUE($F$3)=0,0,F19/$F$3) -> 0 | E19: =C19*D19 -> 0 | F19: =OFFSET(分配表!C231,0,mth-1) -> 0 | G19: =E19*$F$3 -> 0 | I19: 2X型高温酶 | K19: =分配表!O245 -> 18.550904 | L19: =IF($N$3=0,,N19/$N$3) -> 0.13864305 | M19: =K19*L19 -> 2.5719539 | N19: =分配表!O231 -> 5407 | O19: =M19*$N$3 -> 100304.74
A20: 普鲁兰酶 | C20: =OFFSET(分配表!C246,0,mth-1,1,1) -> 0 | D20: =IF(VALUE($F$3)=0,0,F20/$F$3) -> 0 | E20: =C20*D20 -> 0 | F20: =OFFSET(分配表!C232,0,mth-1) -> 0 | G20: =E20*$F$3 -> 0 | I20: 普鲁兰酶 | K20: =分配表!O246 -> 35.398211 | L20: =IF($N$3=0,,N20/$N$3) -> 0.016910503 | M20: =K20*L20 -> 0.59860155 | N20: =分配表!O232 -> 659.5 | O20: =M20*$N$3 -> 23345.12
A21: β淀粉酶 | C21: =OFFSET(分配表!C247,0,mth-1,1,1) -> 0 | D21: =IF(VALUE($F$3)=0,0,F21/$F$3) -> 0 | E21: =C21*D21 -> 0 | F21: =OFFSET(分配表!C233,0,mth-1) -> 0 | G21: =E21*$F$3 -> 0 | I21: β淀粉酶 | K21: =分配表!O247 -> 62.022154 | L21: =IF($N$3=0,,N21/$N$3) -> 0.083090956 | M21: =K21*L21 -> 5.1534801 | N21: =分配表!O233 -> 3240.5 | O21: =M21*$N$3 -> 200982.79
A22: DX1.5X强效糖化酶 | C22: =OFFSET(分配表!C248,0,mth-1,1,1) -> 0 | D22: =IF(VALUE($F$3)=0,0,F22/$F$3) -> 0 | E22: =C22*D22 -> 0 | F22: =OFFSET(分配表!C234,0,mth-1) -> 0 | G22: =E22*$F$3 -> 0 | I22: DX1.5X强效糖化酶 | K22: =分配表!O248 -> 25.292485 | L22: =IF($N$3=0,,N22/$N$3) -> 0.033231254 | M22: =K22*L22 -> 0.84050098 | N22: =分配表!O234 -> 1296 | O22: =M22*$N$3 -> 32779.06
A23: 转甘酶 | C23: =OFFSET(分配表!C249,0,mth-1,1,1) -> 0 | D23: =IF(VALUE($F$3)=0,0,F23/$F$3) -> 0 | E23: =C23*D23 -> 0 | F23: =OFFSET(分配表!C235,0,mth-1) -> 0 | G23: =E23*$F$3 -> 0 | I23: 转甘酶 | K23: =分配表!O249 -> 529.20353 | L23: =IF($N$3=0,,N23/$N$3) -> 0.00384621 | M23: =K23*L23 -> 2.0354279 | N23: =分配表!O235 -> 150 | O23: =M23*$N$3 -> 79380.53
A24: 葡糖淀粉酶 | C24: =OFFSET(分配表!C250,0,mth-1,1,1) -> 0 | D24: =IF(VALUE($F$3)=0,0,F24/$F$3) -> 0 | E24: =C24*D24 -> 0 | F24: =OFFSET(分配表!C236,0,mth-1) -> 0 | G24: =E24*$F$3 -> 0 | I24: 葡糖淀粉酶 | K24: =分配表!O250 -> 0 | L24: =IF($N$3=0,,N24/$N$3) -> 0 | M24: =K24*L24 -> 0 | N24: =分配表!O236 -> 0 | O24: =M24*$N$3 -> 0
A25: 麦芽糖淀粉酶 | C25: =OFFSET(分配表!C251,0,mth-1,1,1) -> 0 | D25: =IF(VALUE($F$3)=0,0,F25/$F$3) -> 0 | E25: =C25*D25 -> 0 | F25: =OFFSET(分配表!C237,0,mth-1) -> 0 | G25: =E25*$F$3 -> 0 | I25: 麦芽糖淀粉酶 | K25: =分配表!O251 -> 0 | L25: =IF($N$3=0,,N25/$N$3) -> 0 | M25: =K25*L25 -> 0 | N25: =分配表!O237 -> 0 | O25: =M25*$N$3 -> 0
A26: 其他 | E26: =G26/F3 -> #DIV/0! | G26: =OFFSET(分配表!C280,0,mth-1,1,1) -> 0 | I26: 其他 | M26: =O26/N3 -> 1.0770693 | O26: =分配表!O280 -> 42005.09
A27: (三)包装物 | I27: (三)包装物
A28: (四)动力能源 | E28: =SUM(E29:E32) -> 0 | G28: =SUM(G29:G32) -> 0 | I28: (四)动力能源 | M28: =SUM(M29:M32) -> 215.05444 | O28: =SUM(O29:O32) -> 8387000.8
A29: 1、蒸汽 | B29: 吨 | C29: ='F55'!C27 -> 0 | D29: =IF(VALUE($F$3)=0,0,F29/$F$3) -> 0 | E29: =C29*D29 -> 0 | F29: =OFFSET(分配表!C314,0,mth-1,1,1) -> 0 | G29: =E29*F$3 -> 0 | I29: 1、蒸汽 | J29: 吨 | K29: ='F55'!K27 -> 374.79903 | L29: =IF($N$3=0,0,N29/$N$3) -> 0.43431403 | M29: =K29*L29 -> 162.78047 | N29: =分配表!O314 -> 16938 | O29: =M29*N$3 -> 6348345.9
A30: 2、电 | B30: 度 | C30: ='F55'!C28 -> 0 | D30: =IF(VALUE($F$3)=0,0,F30/$F$3) -> 0 | E30: =C30*D30 -> 0 | F30: =OFFSET(分配表!C333,0,mth-1,1,1) -> 0 | G30: =E30*F$3 -> 0 | I30: 2、电 | J30: 度 | K30: ='F55'!K28 -> 0.6806368 | L30: =IF($N$3=0,0,N30/$N$3) -> 61.258714 | M30: =K30*L30 -> 41.694935 | N30: =分配表!O333 -> 2389055 | O30: =M30*N$3 -> 1626078.7
A31: 3、水 | B31: 吨 | C31: ='F55'!C29 -> 0 | D31: =IF(VALUE($F$3)=0,0,F31/$F$3) -> 0 | E31: =C31*D31 -> 0 | F31: =OFFSET(分配表!C351,0,mth-1,1,1) -> 0 | G31: =E31*F$3 -> 0 | I31: 3、水 | J31: 吨 | K31: ='F55'!K29 -> 5.8950402 | L31: =IF($N$3=0,0,N31/$N$3) -> 1.7945646 | M31: =K31*L31 -> 10.579031 | N31: =分配表!O351 -> 69987 | O31: =M31*N$3 -> 412576.18
A32: 4、天然气 | B32: M3 | C32: ='F55'!C30 -> 0 | D32: =IF(VALUE($F$3)=0,0,F32/$F$3) -> 0 | E32: =C32*D32 -> 0 | F32: =OFFSET(分配表!C367,0,mth-1,1,1) -> 0 | G32: =E32*F$3 -> 0 | I32: 4、天然气 | J32: M3 | K32: ='F55'!K30 -> 0 | L32: =IF($N$3=0,0,N32/$N$3) -> 0 | M32: =K32*L32 -> 0 | N32: =分配表!O367 -> 0 | O32: =M32*N$3 -> 0
A33: (四)污水 | E33: =IF(VALUE($F$3)=0,0,G33/$F$3) -> 0 | G33: =OFFSET(分配表!C379,0,mth-1,1,1) -> #DIV/0! | I33: (四)污水 | M33: =IF($N$3=0,,O33/$N$3) -> #DIV/0! | O33: =分配表!O379 -> #DIV/0!
A34: 1.污水处理 | E34: =E33 -> 0 | G34: =G33 -> #DIV/0! | I34: 1.污水处理 | M34: =M33 -> #DIV/0! | O34: =O33 -> #DIV/0!
A35: 2.污水固定成本 | I35: 2.污水固定成本
A36: (五)增值税 | I36: (五)增值税
A37: 三、边际贡献 | E37: =E5-E10 -> #DIV/0! | G37: =G5-G10 -> #DIV/0! | I37: 三、边际贡献 | M37: =M5-M10 -> #DIV/0! | O37: =O5-O10 -> #DIV/0!
A38: 四、固定成本 | E38: =SUM(E39:E45) -> 0 | G38: =SUM(G39:G45) -> #DIV/0! | I38: 四、固定成本 | M38: =IF(N$3=0,0,O38/N$3) -> #DIV/0! | O38: =SUM(O39:O45) -> #DIV/0!
A39: （一）折旧与摊销 | E39: =IF(VALUE($F$3)=0,0,G39/$F$3) -> 0 | G39: =OFFSET(分配表!C412,0,mth-1,1,1) -> #DIV/0! | I39: （一）折旧与摊销 | M39: =IF($N$3=0,0,O39/$N$3) -> #DIV/0! | O39: =分配表!O412 -> #DIV/0!
A40: （二）工资 | E40: =IF(VALUE($F$3)=0,0,G40/$F$3) -> 0 | G40: =OFFSET(分配表!C432,0,mth-1,1,1) -> #DIV/0! | I40: （二）工资 | M40: =IF($N$3=0,0,O40/$N$3) -> #DIV/0! | O40: =分配表!O432 -> #DIV/0!
A41: （三）制造费用 | E41: =IF(VALUE($F$3)=0,0,G41/$F$3) -> 0 | G41: =OFFSET(分配表!C452,0,mth-1,1,1) -> #DIV/0! | I41: （三）制造费用 | M41: =IF($N$3=0,0,O41/$N$3) -> #DIV/0! | O41: =分配表!O452 -> #DIV/0!
...

Sheet F90
A1: =CONCATENATE("果葡糖浆F90综合成本利润表_不含税(2025年"&mth&"月)") -> 果葡糖浆F90综合成本利润表_不含税(2025年8月) | I1: =CONCATENATE("果葡糖浆F90综合成本利润表_不含税(2025年1-"&mth&"月)") -> 果葡糖浆F90综合成本利润表_不含税(2025年1-8月)
A3: 自产部分 | E3: 自产产量 | F3: =OFFSET(基础表!C11,0,mth-1,1,1) -> 0 | M3: 自产产量 | N3: =基础表!O11 -> 36.72 | O3: 吨
B4: 单位 | C4: 单价 | D4: 单耗 | E4: 单位成本 | F4: 总耗量 | G4: 总成本 | J4: 单位 | K4: 单价 | L4: 单耗 | M4: 单位成本 | N4: 总耗量 | O4: 总成本
A5: 一、收入 | E5: =E6-E7 -> 0 | G5: =G6-G7 -> 0 | I5: 一、收入 | M5: =M6-M7 -> 3626.0359 | O5: =O6-O7 -> 133148.04
A6: （一）销售价格 | E6: =OFFSET(销售收入及运费!C77,0,mth-1,1,1) -> 0 | G6: =E6*$F$3 -> 0 | I6: （一）销售价格 | M6: =销售收入及运费!O77 -> 3679.725 | O6: =M6*$N$3 -> 135119.5
A7: （二）物流费 | E7: =SUM(E8:E9) -> 0 | G7: =E7*$F$3 -> 0 | I7: （二）物流费 | M7: =SUM(M8:M9) -> 53.689075 | O7: =M7*$N$3 -> 1971.4628
A8: 1、运费 | E8: =IFERROR(OFFSET(销售收入及运费!C134,0,mth-1,1,1)/1.09/OFFSET(销售收入及运费!C17,0,mth-1,1,1),"0") -> 0 | G8: =E8*$F$3 -> 0 | I8: 1、运费 | M8: =IFERROR(销售收入及运费!O134/1.09/销售收入及运费!O17,"0") -> 53.689075 | O8: =M8*$N$3 -> 1971.4628
A9: 2、包装费、租赁费等 | E9: =IFERROR((OFFSET(销售收入及运费!C154,0,mth-1,1,1)/1.13+OFFSET(销售收入及运费!C174,0,mth-1,1,1)/1.13)/OFFSET(销售收入及运费!C17,0,mth-1,1,1),"0") -> 0 | G9: =E9*$F$3 -> 0 | I9: 2、包装费、租赁费等 | M9: =IFERROR((销售收入及运费!O154+销售收入及运费!O174)/1.13/销售收入及运费!O17,"0") -> 0 | O9: =M9*$N$3 -> 0
A10: 二、变动成本 | E10: =E11+E13+E26+E31+E34+E25 -> 0 | G10: =G11+G13+G26+G31+G25 -> #DIV/0! | I10: 二、变动成本 | M10: =M11+M13+M26+M31+M34+M25 -> #DIV/0! | O10: =O11+O13+O26+O31+O25 -> #DIV/0!
A11: (一)淀粉 | B11: 吨 | C11: =C12 -> 0 | D11: =IF(C11=0,0,E11/C11) -> 0 | E11: =E12 -> 0 | F11: =F12 -> 0 | G11: =G12 -> 0 | I11: (一)淀粉 | J11: 吨 | K11: =IF(N11=0,0,O11/N11) -> 2453.7157 | L11: =IF(K11=0,0,M11/K11) -> 0.81284707 | M11: =M12 -> 1994.4956 | N11: =N12 -> 29.847744 | O11: =O12 -> 73237.879
A12: 1、淀粉(14%) | B12: 吨 | C12: =OFFSET(分配表!C69,0,mth-1,1,1) -> 0 | D12: =IF(VALUE($F$3)=0,0,F12/$F$3) -> 0 | E12: =C12*D12 -> 0 | F12: =OFFSET(分配表!C83,0,mth-1,1,1) -> 0 | G12: =E12*F3 -> 0 | I12: 1、淀粉(14%) | J12: 吨 | K12: =分配表!O69 -> 2453.7157 | L12: =IF($N$3=0,,N12/$N$3) -> 0.81284707 | M12: =K12*L12 -> 1994.4956 | N12: =分配表!O83 -> 29.847744 | O12: =K12*N12 -> 73237.879
A13: (二）辅料 | E13: =SUM(E14:E24) -> 0 | G13: =SUM(G14:G24) -> #DIV/0! | I13: (二）辅料 | M13: =SUM(M14:M24) -> #DIV/0! | O13: =SUM(O14:O24) -> #DIV/0!
A14: 盐酸(折百) | C14: =OFFSET(分配表!C179,0,mth-1,1,1) -> 0 | D14: =IF(VALUE($F$3)=0,0,F14/$F$3) -> 0 | E14: =C14*D14 -> 0 | F14: =OFFSET(分配表!C166,0,mth-1) -> 0 | G14: =E14*$F$3 -> 0 | I14: 盐酸(折百) | K14: =分配表!O179 -> 1.0336348 | L14: =IF($N$3=0,,N14/$N$3) -> 4.3055556 | M14: =K14*L14 -> 4.4503719 | N14: =分配表!O166 -> 158.1 | O14: =M14*$N$3 -> 163.41766
A15: 氢氧化钠(折百) | C15: =OFFSET(分配表!C180,0,mth-1,1,1) -> 0 | D15: =IF(VALUE($F$3)=0,0,F15/$F$3) -> 0 | E15: =C15*D15 -> 0 | F15: =OFFSET(分配表!C167,0,mth-1) -> 0 | G15: =E15*$F$3 -> 0 | I15: 氢氧化钠(折百) | K15: =分配表!O180 -> 3.1653036 | L15: =IF($N$3=0,,N15/$N$3) -> 4.9673203 | M15: =K15*L15 -> 15.723077 | N15: =分配表!O167 -> 182.4 | O15: =M15*$N$3 -> 577.35138
A16: 硅藻土 | C16: =OFFSET(分配表!C181,0,mth-1,1,1) -> 0 | D16: =IF(VALUE($F$3)=0,0,F16/$F$3) -> 0 | E16: =C16*D16 -> 0 | F16: =OFFSET(分配表!C168,0,mth-1) -> 0 | G16: =E16*$F$3 -> 0 | I16: 硅藻土 | K16: =分配表!O181 -> 2.60487 | L16: =IF($N$3=0,,N16/$N$3) -> 0.84422658 | M16: =K16*L16 -> 2.1991005 | N16: =分配表!O168 -> 31 | O16: =M16*$N$3 -> 80.750971
A17: 活性炭 | C17: =OFFSET(分配表!C183,0,mth-1,1,1) -> 0 | D17: =IF(VALUE($F$3)=0,0,F17/$F$3) -> 0 | E17: =C17*D17 -> 0 | F17: =OFFSET(分配表!C170,0,mth-1) -> 0 | G17: =E17*$F$3 -> 0 | I17: 活性炭 | K17: =分配表!O183 -> 7.0797015 | L17: =IF($N$3=0,,N17/$N$3) -> 1.7701525 | M17: =K17*L17 -> 12.532151 | N17: =分配表!O170 -> 65 | O17: =M17*$N$3 -> 460.1806
